File: 10silicone10.csv
Tenacity at Break (Standard),"0.19481",N/tex
Tensile extension at Break (Standard),"76.52746",mm
Tenacity at Yield ,,N/tex

Time,Extension,Load,Tensile strain (Extension),Tensile stress,Tenacity,Tensile extension
(s),(mm),(N),(mm/mm),(MPa),(N/tex),(mm)
"0.00000","0.00000","0.01235","0.00000","0.00206","0.01235","0.00000"
"0.20000","0.17902","0.04142","0.00559","0.00690","0.04142","0.17902"
"0.40000","0.37963","0.03156","0.01186","0.00526","0.03156","0.37963"
"0.60000","0.57951","0.06310","0.01811","0.01052","0.06310","0.57951"
"0.80000","0.77967","-0.00487","0.02436","-0.00081","-0.00487","0.77967"
"1.00000","0.97948","0.02790","0.03061","0.00465","0.02790","0.97948"
"1.20000","1.17959","0.07584","0.03686","0.01264","0.07584","1.17959"
"1.40000","1.37948","0.09601","0.04311","0.01600","0.09601","1.37948"
"1.60000","1.57967","0.07368","0.04936","0.01228","0.07368","1.57967"
"1.80000","1.77945","0.10016","0.05561","0.01669","0.10016","1.77945"
"2.00000","1.97966","0.13857","0.06186","0.02310","0.13857","1.97966"
"2.20000","2.17949","0.08049","0.06811","0.01341","0.08049","2.17949"
"2.40000","2.37965","0.11838","0.07436","0.01973","0.11838","2.37965"
"2.60000","2.57950","0.09476","0.08061","0.01579","0.09476","2.57950"
"2.80000","2.77964","0.16879","0.08686","0.02813","0.16879","2.77964"
"3.00000","2.97950","0.14742","0.09311","0.02457","0.14742","2.97950"
"3.20000","3.17964","0.19249","0.09936","0.03208","0.19249","3.17964"
"3.40000","3.37953","0.22331","0.10561","0.03722","0.22331","3.37953"
"3.60000","3.57964","0.27284","0.11186","0.04547","0.27284","3.57964"
"3.80000","3.77948","0.23633","0.11811","0.03939","0.23633","3.77948"
"4.00000","3.97968","0.18499","0.12436","0.03083","0.18499","3.97968"
"4.20000","4.17946","0.26659","0.13061","0.04443","0.26659","4.17946"
"4.40000","4.37966","0.26165","0.13686","0.04361","0.26165","4.37966"
"4.60000","4.57947","0.31196","0.14311","0.05199","0.31196","4.57947"
"4.80000","4.77959","0.23471","0.14936","0.03912","0.23471","4.77959"
"5.00000","4.97948","0.31354","0.15561","0.05226","0.31354","4.97948"
"5.20000","5.17964","0.27506","0.16186","0.04584","0.27506","5.17964"
"5.40000","5.37950","0.28249","0.16811","0.04708","0.28249","5.37950"
"5.60000","5.57960","0.25016","0.17436","0.04169","0.25016","5.57960"
"5.80000","5.77949","0.34667","0.18061","0.05778","0.34667","5.77949"
"6.00000","5.97963","0.40243","0.18686","0.06707","0.40243","5.97963"
"6.20000","6.17947","0.37003","0.19311","0.06167","0.37003","6.17947"
"6.40000","6.37966","0.32842","0.19936","0.05474","0.32842","6.37966"
"6.60000","6.57944","0.40648","0.20561","0.06775","0.40648","6.57944"
"6.80000","6.77964","0.34990","0.21186","0.05832","0.34990","6.77964"
"7.00000","6.97947","0.43527","0.21811","0.07255","0.43527","6.97947"
"7.20000","7.17954","0.43757","0.22436","0.07293","0.43757","7.17954"
"7.40000","7.37946","0.42445","0.23061","0.07074","0.42445","7.37946"
"7.60000","7.57964","0.40278","0.23686","0.06713","0.40278","7.57964"
"7.80000","7.77945","0.50955","0.24311","0.08492","0.50955","7.77945"
"8.00000","7.97958","0.52097","0.24936","0.08683","0.52097","7.97958"
"8.20000","8.17944","0.55036","0.25561","0.09173","0.55036","8.17944"
"8.40000","8.37965","0.48732","0.26186","0.08122","0.48732","8.37965"
"8.60000","8.57937","0.51680","0.26811","0.08613","0.51680","8.57937"
"8.80000","8.77962","0.50719","0.27436","0.08453","0.50719","8.77962"
"9.00000","8.97940","0.48056","0.28061","0.08009","0.48056","8.97940"
"9.20000","9.17958","0.46949","0.28686","0.07825","0.46949","9.17958"
"9.40000","9.37945","0.52865","0.29311","0.08811","0.52865","9.37945"
"9.60000","9.57951","0.56104","0.29936","0.09351","0.56104","9.57951"
"9.80000","9.77946","0.49748","0.30561","0.08291","0.49748","9.77946"
"10.00000","9.97958","0.53322","0.31186","0.08887","0.53322","9.97958"
"10.20000","10.17944","0.54203","0.31811","0.09034","0.54203","10.17944"
"10.40000","10.37959","0.60938","0.32436","0.10156","0.60938","10.37959"
"10.60000","10.57940","0.58600","0.33061","0.09767","0.58600","10.57940"
"10.80000","10.77953","0.65181","0.33686","0.10864","0.65181","10.77953"
"11.00000","10.97936","0.66874","0.34311","0.11146","0.66874","10.97936"
"11.20000","11.17955","0.57527","0.34936","0.09588","0.57527","11.17955"
"11.40000","11.37940","0.64671","0.35561","0.10778","0.64671","11.37940"
"11.60000","11.57948","0.66339","0.36186","0.11056","0.66339","11.57948"
"11.80000","11.77940","0.66738","0.36811","0.11123","0.66738","11.77940"
"12.00000","11.97949","0.71109","0.37436","0.11852","0.71109","11.97949"
"12.20000","12.17944","0.69388","0.38061","0.11565","0.69388","12.17944"
"12.40000","12.37953","0.73998","0.38686","0.12333","0.73998","12.37953"
"12.60000","12.57941","0.67391","0.39311","0.11232","0.67391","12.57941"
"12.80000","12.77955","0.65831","0.39936","0.10972","0.65831","12.77955"
"13.00000","12.97936","0.70425","0.40560","0.11738","0.70425","12.97936"
"13.20000","13.17952","0.75405","0.41186","0.12568","0.75405","13.17952"
"13.40000","13.37938","0.73411","0.41811","0.12235","0.73411","13.37938"
"13.60000","13.57950","0.70542","0.42436","0.11757","0.70542","13.57950"
"13.80000","13.77935","0.75210","0.43060","0.12535","0.75210","13.77935"
"14.00000","13.97949","0.80720","0.43686","0.13453","0.80720","13.97949"
"14.20000","14.17940","0.79357","0.44311","0.13226","0.79357","14.17940"
"14.40000","14.37944","0.81390","0.44936","0.13565","0.81390","14.37944"
"14.60000","14.57942","0.77940","0.45561","0.12990","0.77940","14.57942"
"14.80000","14.77951","0.76225","0.46186","0.12704","0.76225","14.77951"
"15.00000","14.97939","0.80511","0.46811","0.13419","0.80511","14.97939"
"15.20000","15.17951","0.82674","0.47436","0.13779","0.82674","15.17951"
"15.40000","15.37939","0.84520","0.48061","0.14087","0.84520","15.37939"
"15.60000","15.57948","0.90763","0.48686","0.15127","0.90763","15.57948"
"15.80000","15.77939","0.84007","0.49311","0.14001","0.84007","15.77939"
"16.00000","15.97948","0.85266","0.49936","0.14211","0.85266","15.97948"
"16.20000","16.17939","0.86143","0.50561","0.14357","0.86143","16.17939"
"16.40000","16.37947","0.92503","0.51186","0.15417","0.92503","16.37947"
"16.60000","16.57940","0.93266","0.51811","0.15544","0.93266","16.57940"
"16.80000","16.77946","0.95893","0.52436","0.15982","0.95893","16.77946"
"17.00000","16.97938","0.82536","0.53061","0.13756","0.82536","16.97938"
"17.20000","17.17950","0.93081","0.53686","0.15513","0.93081","17.17950"
"17.40000","17.37932","0.92407","0.54310","0.15401","0.92407","17.37932"
"17.60000","17.57953","0.89764","0.54936","0.14961","0.89764","17.57953"
"17.80000","17.77941","0.94220","0.55561","0.15703","0.94220","17.77941"
"18.00000","17.97950","0.99576","0.56186","0.16596","0.99576","17.97950"
"18.20000","18.17941","1.07393","0.56811","0.17899","1.07393","18.17941"
"18.40000","18.37954","0.98935","0.57436","0.16489","0.98935","18.37954"
"18.60000","18.57948","1.01916","0.58061","0.16986","1.01916","18.57948"
"18.80000","18.77951","1.05206","0.58686","0.17534","1.05206","18.77951"
"19.00000","18.97944","1.04305","0.59311","0.17384","1.04305","18.97944"
"19.20000","19.17947","1.04342","0.59936","0.17390","1.04342","19.17947"
"19.40000","19.37942","1.01061","0.60561","0.16843","1.01061","19.37942"
"19.60000","19.57952","1.06371","0.61186","0.17728","1.06371","19.57952"
"19.80000","19.77945","1.06966","0.61811","0.17828","1.06966","19.77945"
"20.00000","19.97956","1.00390","0.62436","0.16732","1.00390","19.97956"
"20.20000","20.17943","1.10632","0.63061","0.18439","1.10632","20.17943"
"20.40000","20.37958","1.06801","0.63686","0.17800","1.06801","20.37958"
"20.60000","20.57946","1.13101","0.64311","0.18850","1.13101","20.57946"
"20.80000","20.77953","1.17692","0.64936","0.19615","1.17692","20.77953"
"21.00000","20.97948","1.20041","0.65561","0.20007","1.20041","20.97948"
"21.20000","21.17956","1.14466","0.66186","0.19078","1.14466","21.17956"
"21.40000","21.37953","1.19851","0.66811","0.19975","1.19851","21.37953"
"21.60000","21.57950","1.20757","0.67436","0.20126","1.20757","21.57950"
"21.80000","21.77952","1.13019","0.68061","0.18837","1.13019","21.77952"
"22.00000","21.97954","1.23523","0.68686","0.20587","1.23523","21.97954"
"22.20000","22.17951","1.24820","0.69311","0.20803","1.24820","22.17951"
"22.40000","22.37957","1.30297","0.69936","0.21716","1.30297","22.37957"
"22.60000","22.57947","1.24573","0.70561","0.20762","1.24573","22.57947"
"22.80000","22.77961","1.31836","0.71186","0.21973","1.31836","22.77961"
"23.00000","22.97951","1.32678","0.71811","0.22113","1.32678","22.97951"
"23.20000","23.17953","1.33060","0.72436","0.22177","1.33060","23.17953"
"23.40000","23.37959","1.29829","0.73061","0.21638","1.29829","23.37959"
"23.60000","23.57956","1.37537","0.73686","0.22923","1.37537","23.57956"
"23.80000","23.77953","1.38064","0.74311","0.23011","1.38064","23.77953"
"24.00000","23.97954","1.38494","0.74936","0.23082","1.38494","23.97954"
"24.20000","24.17955","1.34766","0.75561","0.22461","1.34766","24.17955"
"24.40000","24.37955","1.38236","0.76186","0.23039","1.38236","24.37955"
"24.60000","24.57956","1.34554","0.76811","0.22426","1.34554","24.57956"
"24.80000","24.77961","1.31222","0.77436","0.21870","1.31222","24.77961"
"25.00000","24.97945","1.43392","0.78061","0.23899","1.43392","24.97945"
"25.20000","25.17961","1.40909","0.78686","0.23485","1.40909","25.17961"
"25.40000","25.37955","1.40148","0.79311","0.23358","1.40148","25.37955"
"25.60000","25.57949","1.37192","0.79936","0.22865","1.37192","25.57949"
"25.80000","25.77960","1.47729","0.80561","0.24622","1.47729","25.77960"
"26.00000","25.97954","1.36754","0.81186","0.22792","1.36754","25.97954"
"26.20000","26.17957","1.42496","0.81811","0.23749","1.42496","26.17957"
"26.40000","26.37953","1.50182","0.82436","0.25030","1.50182","26.37953"
"26.60000","26.57957","1.48873","0.83061","0.24812","1.48873","26.57957"
"26.80000","26.77957","1.48676","0.83686","0.24779","1.48676","26.77957"
"27.00000","26.97955","1.52047","0.84311","0.25341","1.52047","26.97955"
"27.20000","27.17956","1.56989","0.84936","0.26165","1.56989","27.17956"
"27.40000","27.37955","1.50005","0.85561","0.25001","1.50005","27.37955"
"27.60000","27.57959","1.51833","0.86186","0.25305","1.51833","27.57959"
"27.80000","27.77957","1.57270","0.86811","0.26212","1.57270","27.77957"
"28.00000","27.97947","1.56752","0.87436","0.26125","1.56752","27.97947"
"28.20000","28.17957","1.53341","0.88061","0.25557","1.53341","28.17957"
"28.40000","28.37955","1.56598","0.88686","0.26100","1.56598","28.37955"
"28.60000","28.57953","1.69615","0.89311","0.28269","1.69615","28.57953"
"28.80000","28.77948","1.60603","0.89936","0.26767","1.60603","28.77948"
"29.00000","28.97955","1.62138","0.90561","0.27023","1.62138","28.97955"
"29.20000","29.17953","1.63567","0.91186","0.27261","1.63567","29.17953"
"29.40000","29.37952","1.62903","0.91811","0.27151","1.62903","29.37952"
"29.60000","29.57951","1.68065","0.92436","0.28011","1.68065","29.57951"
"29.80000","29.77953","1.68925","0.93061","0.28154","1.68925","29.77953"
"30.00000","29.97953","1.69542","0.93686","0.28257","1.69542","29.97953"
"30.20000","30.17957","1.69962","0.94311","0.28327","1.69962","30.17957"
"30.40000","30.37946","1.71779","0.94936","0.28630","1.71779","30.37946"
"30.60000","30.57958","1.75933","0.95561","0.29322","1.75933","30.57958"
"30.80000","30.77948","1.72408","0.96186","0.28735","1.72408","30.77948"
"31.00000","30.97946","1.74064","0.96811","0.29011","1.74064","30.97946"
"31.20000","31.17947","1.79804","0.97436","0.29967","1.79804","31.17947"
"31.40000","31.37954","1.83469","0.98061","0.30578","1.83469","31.37954"
"31.60000","31.57947","1.73811","0.98686","0.28969","1.73811","31.57947"
"31.80000","31.77948","1.83660","0.99311","0.30610","1.83660","31.77948"
"32.00000","31.97947","1.81249","0.99936","0.30208","1.81249","31.97947"
"32.20000","32.17952","1.80377","1.00561","0.30063","1.80377","32.17952"
"32.40000","32.37944","1.89667","1.01186","0.31611","1.89667","32.37944"
"32.60000","32.57954","1.87952","1.01811","0.31325","1.87952","32.57954"
"32.80000","32.77941","1.91103","1.02436","0.31850","1.91103","32.77941"
"33.00000","32.97955","1.85919","1.03061","0.30987","1.85919","32.97955"
"33.20000","33.17941","1.90594","1.03686","0.31766","1.90594","33.17941"
"33.40000","33.37949","1.90638","1.04311","0.31773","1.90638","33.37949"
"33.60000","33.57947","1.93086","1.04936","0.32181","1.93086","33.57947"
"33.80000","33.77952","1.90189","1.05561","0.31698","1.90189","33.77952"
"34.00000","33.97945","1.93598","1.06186","0.32266","1.93598","33.97945"
"34.20000","34.17951","1.94199","1.06811","0.32367","1.94199","34.17951"
"34.40000","34.37936","2.01769","1.07435","0.33628","2.01769","34.37936"
"34.60000","34.57952","1.96317","1.08061","0.32720","1.96317","34.57952"
"34.80000","34.77944","1.95294","1.08686","0.32549","1.95294","34.77944"
"35.00000","34.97951","2.04706","1.09311","0.34118","2.04706","34.97951"
"35.20000","35.17937","2.06450","1.09936","0.34408","2.06450","35.17937"
"35.40000","35.37953","2.07000","1.10561","0.34500","2.07000","35.37953"
"35.60000","35.57940","2.03009","1.11186","0.33835","2.03009","35.57940"
"35.80000","35.77949","2.10358","1.11811","0.35060","2.10358","35.77949"
"36.00000","35.97940","2.11006","1.12436","0.35168","2.11006","35.97940"
"36.20000","36.17950","2.10021","1.13061","0.35004","2.10021","36.17950"
"36.40000","36.37939","2.14037","1.13686","0.35673","2.14037","36.37939"
"36.60000","36.57953","2.19122","1.14311","0.36520","2.19122","36.57953"
"36.80000","36.77938","2.10557","1.14936","0.35093","2.10557","36.77938"
"37.00000","36.97949","2.16943","1.15561","0.36157","2.16943","36.97949"
"37.20000","37.17937","2.20870","1.16186","0.36812","2.20870","37.17937"
"37.40000","37.37948","2.24762","1.16811","0.37460","2.24762","37.37948"
"37.60000","37.57937","2.17556","1.17436","0.36259","2.17556","37.57937"
"37.80000","37.77949","2.22163","1.18061","0.37027","2.22163","37.77949"
"38.00000","37.97938","2.24713","1.18686","0.37452","2.24713","37.97938"
"38.20000","38.17949","2.19133","1.19311","0.36522","2.19133","38.17949"
"38.40000","38.37942","2.22819","1.19936","0.37136","2.22819","38.37942"
"38.60000","38.57950","2.27022","1.20561","0.37837","2.27022","38.57950"
"38.80000","38.77942","2.31301","1.21186","0.38550","2.31301","38.77942"
"39.00000","38.97955","2.32543","1.21811","0.38757","2.32543","38.97955"
"39.20000","39.17935","2.29586","1.22435","0.38264","2.29586","39.17935"
"39.40000","39.37949","2.31778","1.23061","0.38630","2.31778","39.37949"
"39.60000","39.57935","2.27278","1.23685","0.37880","2.27278","39.57935"
"39.80000","39.77952","2.34780","1.24311","0.39130","2.34780","39.77952"
"40.00000","39.97938","2.32499","1.24936","0.38750","2.32499","39.97938"
"40.20000","40.17953","2.39590","1.25561","0.39932","2.39590","40.17953"
"40.40000","40.37943","2.34551","1.26186","0.39092","2.34551","40.37943"
"40.60000","40.57950","2.42073","1.26811","0.40346","2.42073","40.57950"
"40.80000","40.77944","2.47125","1.27436","0.41188","2.47125","40.77944"
"41.00000","40.97955","2.43130","1.28061","0.40522","2.43130","40.97955"
"41.20000","41.17942","2.53098","1.28686","0.42183","2.53098","41.17942"
"41.40000","41.37955","2.43485","1.29311","0.40581","2.43485","41.37955"
"41.60000","41.57941","2.46036","1.29936","0.41006","2.46036","41.57941"
"41.80000","41.77959","2.57516","1.30561","0.42919","2.57516","41.77959"
"42.00000","41.97939","2.56376","1.31186","0.42729","2.56376","41.97939"
"42.20000","42.17960","2.55072","1.31811","0.42512","2.55072","42.17960"
"42.40000","42.37946","2.65102","1.32436","0.44184","2.65102","42.37946"
"42.60000","42.57960","2.58062","1.33061","0.43010","2.58062","42.57960"
"42.80000","42.77938","2.57409","1.33686","0.42902","2.57409","42.77938"
"43.00000","42.97955","2.58410","1.34311","0.43068","2.58410","42.97955"
"43.20000","43.17945","2.62657","1.34936","0.43776","2.62657","43.17945"
"43.40000","43.37961","2.67336","1.35561","0.44556","2.67336","43.37961"
"43.60000","43.57946","2.64434","1.36186","0.44072","2.64434","43.57946"
"43.80000","43.77959","2.69925","1.36811","0.44988","2.69925","43.77959"
"44.00000","43.97942","2.65823","1.37436","0.44304","2.65823","43.97942"
"44.20000","44.17962","2.68954","1.38061","0.44826","2.68954","44.17962"
"44.40000","44.37943","2.77512","1.38686","0.46252","2.77512","44.37943"
"44.60000","44.57962","2.82400","1.39311","0.47067","2.82400","44.57962"
"44.80000","44.77951","2.75017","1.39936","0.45836","2.75017","44.77951"
"45.00000","44.97964","2.80253","1.40561","0.46709","2.80253","44.97964"
"45.20000","45.17950","2.76698","1.41186","0.46116","2.76698","45.17950"
"45.40000","45.37962","2.80575","1.41811","0.46763","2.80575","45.37962"
"45.60000","45.57948","2.78528","1.42436","0.46421","2.78528","45.57948"
"45.80000","45.77962","2.90446","1.43061","0.48408","2.90446","45.77962"
"46.00000","45.97950","2.85226","1.43686","0.47538","2.85226","45.97950"
"46.20000","46.17967","2.90858","1.44311","0.48476","2.90858","46.17967"
"46.40000","46.37945","2.90922","1.44936","0.48487","2.90922","46.37945"
"46.60000","46.57967","2.96285","1.45561","0.49381","2.96285","46.57967"
"46.80000","46.77946","2.89257","1.46186","0.48209","2.89257","46.77946"
"47.00000","46.97963","2.93116","1.46811","0.48853","2.93116","46.97963"
"47.20000","47.17953","2.99171","1.47436","0.49862","2.99171","47.17953"
"47.40000","47.37965","3.01372","1.48061","0.50229","3.01372","47.37965"
"47.60000","47.57948","3.00486","1.48686","0.50081","3.00486","47.57948"
"47.80000","47.77962","3.02764","1.49311","0.50461","3.02764","47.77962"
"48.00000","47.97951","3.08043","1.49936","0.51341","3.08043","47.97951"
"48.20000","48.17965","3.03066","1.50561","0.50511","3.03066","48.17965"
"48.40000","48.37949","3.08922","1.51186","0.51487","3.08922","48.37949"
"48.60000","48.57968","3.17110","1.51811","0.52852","3.17110","48.57968"
"48.80000","48.77946","3.14824","1.52436","0.52471","3.14824","48.77946"
"49.00000","48.97968","3.16191","1.53061","0.52698","3.16191","48.97968"
"49.20000","49.17946","3.22372","1.53686","0.53729","3.22372","49.17946"
"49.40000","49.37961","3.19380","1.54311","0.53230","3.19380","49.37961"
"49.60000","49.57949","3.17977","1.54936","0.52996","3.17977","49.57949"
"49.80000","49.77965","3.24215","1.55561","0.54036","3.24215","49.77965"
"50.00000","49.97949","3.22522","1.56186","0.53754","3.22522","49.97949"
"50.20000","50.17962","3.22269","1.56811","0.53712","3.22269","50.17962"
"50.40000","50.37947","3.26788","1.57436","0.54465","3.26788","50.37947"
"50.60000","50.57967","3.30504","1.58061","0.55084","3.30504","50.57967"
"50.80000","50.77949","3.28075","1.58686","0.54679","3.28075","50.77949"
"51.00000","50.97964","3.28149","1.59311","0.54691","3.28149","50.97964"
"51.20000","51.17942","3.38236","1.59936","0.56373","3.38236","51.17942"
"51.40000","51.37961","3.35307","1.60561","0.55884","3.35307","51.37961"
"51.60000","51.57948","3.40792","1.61186","0.56799","3.40792","51.57948"
"51.80000","51.77957","3.40283","1.61811","0.56714","3.40283","51.77957"
"52.00000","51.97947","3.44249","1.62436","0.57375","3.44249","51.97947"
"52.20000","52.17963","3.43878","1.63061","0.57313","3.43878","52.17963"
"52.40000","52.37944","3.43723","1.63686","0.57287","3.43723","52.37944"
"52.60000","52.57960","3.51460","1.64311","0.58577","3.51460","52.57960"
"52.80000","52.77945","3.46477","1.64936","0.57746","3.46477","52.77945"
"53.00000","52.97962","3.54723","1.65561","0.59120","3.54723","52.97962"
"53.20000","53.17940","3.56648","1.66186","0.59441","3.56648","53.17940"
"53.40000","53.37963","3.49877","1.66811","0.58313","3.49877","53.37963"
"53.60000","53.57941","3.63724","1.67436","0.60621","3.63724","53.57941"
"53.80000","53.77960","3.66952","1.68061","0.61159","3.66952","53.77960"
"54.00000","53.97945","3.64608","1.68686","0.60768","3.64608","53.97945"
"54.20000","54.17955","3.64549","1.69311","0.60758","3.64549","54.17955"
"54.40000","54.37944","3.72968","1.69936","0.62161","3.72968","54.37944"
"54.60000","54.57958","3.66711","1.70561","0.61118","3.66711","54.57958"
"54.80000","54.77937","3.74293","1.71186","0.62382","3.74293","54.77937"
"55.00000","54.97955","3.74721","1.71811","0.62454","3.74721","54.97955"
"55.20000","55.17943","3.78094","1.72436","0.63016","3.78094","55.17943"
"55.40000","55.37957","3.81753","1.73061","0.63626","3.81753","55.37957"
"55.60000","55.57938","3.78318","1.73686","0.63053","3.78318","55.57938"
"55.80000","55.77958","3.87988","1.74311","0.64665","3.87988","55.77958"
"56.00000","55.97938","3.79353","1.74936","0.63226","3.79353","55.97938"
"56.20000","56.17951","3.80924","1.75561","0.63487","3.80924","56.17951"
"56.40000","56.37940","3.91596","1.76186","0.65266","3.91596","56.37940"
"56.60000","56.57950","3.90437","1.76811","0.65073","3.90437","56.57950"
"56.80000","56.77940","3.91154","1.77436","0.65192","3.91154","56.77940"
"57.00000","56.97953","3.92311","1.78061","0.65385","3.92311","56.97953"
"57.20000","57.17935","3.98331","1.78685","0.66388","3.98331","57.17935"
"57.40000","57.37953","3.94074","1.79311","0.65679","3.94074","57.37953"
"57.60000","57.57940","3.92994","1.79936","0.65499","3.92994","57.57940"
"57.80000","57.77954","4.00425","1.80561","0.66738","4.00425","57.77954"
"58.00000","57.97936","4.02317","1.81185","0.67053","4.02317","57.97936"
"58.20000","58.17950","4.09982","1.81811","0.68330","4.09982","58.17950"
"58.40000","58.37939","4.06367","1.82436","0.67728","4.06367","58.37939"
"58.60000","58.57948","4.09770","1.83061","0.68295","4.09770","58.57948"
"58.80000","58.77938","4.08218","1.83686","0.68036","4.08218","58.77938"
"59.00000","58.97948","4.18751","1.84311","0.69792","4.18751","58.97948"
"59.20000","59.17938","4.08814","1.84936","0.68136","4.08814","59.17938"
"59.40000","59.37952","4.15920","1.85561","0.69320","4.15920","59.37952"
"59.60000","59.57936","4.21599","1.86185","0.70267","4.21599","59.57936"
"59.80000","59.77943","4.22280","1.86811","0.70380","4.22280","59.77943"
"60.00000","59.97939","4.24186","1.87436","0.70698","4.24186","59.97939"
"60.20000","60.17955","4.28711","1.88061","0.71452","4.28711","60.17955"
"60.40000","60.37939","4.33103","1.88686","0.72184","4.33103","60.37939"
"60.60000","60.57949","4.26728","1.89311","0.71121","4.26728","60.57949"
"60.80000","60.77938","4.30468","1.89936","0.71745","4.30468","60.77938"
"61.00000","60.97945","4.32859","1.90561","0.72143","4.32859","60.97945"
"61.20000","61.17939","4.35820","1.91186","0.72637","4.35820","61.17939"
"61.40000","61.37948","4.40201","1.91811","0.73367","4.40201","61.37948"
"61.60000","61.57940","4.43166","1.92436","0.73861","4.43166","61.57940"
"61.80000","61.77948","4.45546","1.93061","0.74258","4.45546","61.77948"
"62.00000","61.97940","4.43758","1.93686","0.73960","4.43758","61.97940"
"62.20000","62.17953","4.49798","1.94311","0.74966","4.49798","62.17953"
"62.40000","62.37940","4.52599","1.94936","0.75433","4.52599","62.37940"
"62.60000","62.57952","4.47831","1.95561","0.74639","4.47831","62.57952"
"62.80000","62.77943","4.59808","1.96186","0.76635","4.59808","62.77943"
"63.00000","62.97950","4.57848","1.96811","0.76308","4.57848","62.97950"
"63.20000","63.17942","4.52918","1.97436","0.75486","4.52918","63.17942"
"63.40000","63.37948","4.63980","1.98061","0.77330","4.63980","63.37948"
"63.60000","63.57946","4.59951","1.98686","0.76658","4.59951","63.57946"
"63.80000","63.77950","4.67896","1.99311","0.77983","4.67896","63.77950"
"64.00000","63.97944","4.75481","1.99936","0.79247","4.75481","63.97944"
"64.20000","64.17953","4.69537","2.00561","0.78256","4.69537","64.17953"
"64.40000","64.37939","4.70623","2.01186","0.78437","4.70623","64.37939"
"64.60000","64.57951","4.72930","2.01811","0.78822","4.72930","64.57951"
"64.80000","64.77946","4.74669","2.02436","0.79111","4.74669","64.77946"
"65.00000","64.97956","4.81019","2.03061","0.80170","4.81019","64.97956"
"65.20000","65.17948","4.80322","2.03686","0.80054","4.80322","65.17948"
"65.40000","65.37953","4.85688","2.04311","0.80948","4.85688","65.37953"
"65.60000","65.57948","4.80287","2.04936","0.80048","4.80287","65.57948"
"65.80000","65.77956","4.85866","2.05561","0.80978","4.85866","65.77956"
"66.00000","65.97948","4.86993","2.06186","0.81166","4.86993","65.97948"
"66.20000","66.17953","4.85929","2.06811","0.80988","4.85929","66.17953"
"66.40000","66.37950","4.86693","2.07436","0.81115","4.86693","66.37950"
"66.60000","66.57955","4.93988","2.08061","0.82331","4.93988","66.57955"
"66.80000","66.77946","4.93707","2.08686","0.82285","4.93707","66.77946"
"67.00000","66.97956","5.02375","2.09311","0.83729","5.02375","66.97956"
"67.20000","67.17952","5.01425","2.09936","0.83571","5.01425","67.17952"
"67.40000","67.37956","5.00355","2.10561","0.83392","5.00355","67.37956"
"67.60000","67.57954","5.07255","2.11186","0.84542","5.07255","67.57954"
"67.80000","67.77954","5.03100","2.11811","0.83850","5.03100","67.77954"
"68.00000","67.97954","5.08268","2.12436","0.84711","5.08268","67.97954"
"68.20000","68.17953","5.14944","2.13061","0.85824","5.14944","68.17953"
"68.40000","68.37953","5.11530","2.13686","0.85255","5.11530","68.37953"
"68.60000","68.57961","5.22045","2.14311","0.87008","5.22045","68.57961"
"68.80000","68.77953","5.26365","2.14936","0.87727","5.26365","68.77953"
"69.00000","68.97958","5.14979","2.15561","0.85830","5.14979","68.97958"
"69.20000","69.17951","5.21573","2.16186","0.86929","5.21573","69.17951"
"69.40000","69.37955","5.20711","2.16811","0.86785","5.20711","69.37955"
"69.60000","69.57955","5.27643","2.17436","0.87940","5.27643","69.57955"
"69.80000","69.77956","5.27631","2.18061","0.87939","5.27631","69.77956"
"70.00000","69.97958","5.27996","2.18686","0.87999","5.27996","69.97958"
"70.20000","70.17955","5.29994","2.19311","0.88332","5.29994","70.17955"
"70.40000","70.37959","5.28978","2.19936","0.88163","5.28978","70.37959"
"70.60000","70.57954","5.31394","2.20561","0.88566","5.31394","70.57954"
"70.80000","70.77953","5.43082","2.21186","0.90514","5.43082","70.77953"
"71.00000","70.97959","5.39608","2.21811","0.89935","5.39608","70.97959"
"71.20000","71.17957","5.47823","2.22436","0.91304","5.47823","71.17957"
"71.40000","71.37957","5.52297","2.23061","0.92049","5.52297","71.37957"
"71.60000","71.57952","5.46807","2.23686","0.91134","5.46807","71.57952"
"71.80000","71.77955","5.47768","2.24311","0.91295","5.47768","71.77955"
"72.00000","71.97957","5.54875","2.24936","0.92479","5.54875","71.97957"
"72.20000","72.17956","5.50243","2.25561","0.91707","5.50243","72.17956"
"72.40000","72.37955","5.55561","2.26186","0.92594","5.55561","72.37955"
"72.60000","72.57950","5.55736","2.26811","0.92623","5.55736","72.57950"
"72.80000","72.77962","5.64318","2.27436","0.94053","5.64318","72.77962"
"73.00000","72.97951","5.59281","2.28061","0.93214","5.59281","72.97951"
"73.20000","73.17949","5.59891","2.28686","0.93315","5.59891","73.17949"
"73.40000","73.37955","5.70996","2.29311","0.95166","5.70996","73.37955"
"73.60000","73.57960","5.71275","2.29936","0.95212","5.71275","73.57960"
"73.80000","73.77955","5.65129","2.30561","0.94188","5.65129","73.77955"
"74.00000","73.97954","5.71155","2.31186","0.95193","5.71155","73.97954"
"74.20000","74.17954","5.77283","2.31811","0.96214","5.77283","74.17954"
"74.40000","74.37955","5.74916","2.32436","0.95819","5.74916","74.37955"
"74.60000","74.57948","5.81565","2.33061","0.96927","5.81565","74.57948"
"74.80000","74.77957","5.81721","2.33686","0.96954","5.81721","74.77957"
"75.00000","74.97946","5.79485","2.34311","0.96581","5.79485","74.97946"
"75.20000","75.17958","5.90402","2.34936","0.98400","5.90402","75.17958"
"75.40000","75.37949","5.89735","2.35561","0.98289","5.89735","75.37949"
"75.60000","75.57948","5.85150","2.36186","0.97525","5.85150","75.57948"
"75.80000","75.77948","0.74914","2.36811","0.12486","0.74914","75.77948"
"76.00000","75.97955","0.25907","2.37436","0.04318","0.25907","75.97955"
"76.20000","76.17946","0.20370","2.38061","0.03395","0.20370","76.17946"
"76.40000","76.37952","0.21575","2.38686","0.03596","0.21575","76.37952"
"76.54800","76.52746","0.19481","2.39148","0.03247","0.19481","76.52746"