File: 10silicone5.csv
Tenacity at Break (Standard),"0.22849",N/tex
Tensile extension at Break (Standard),"64.67944",mm
Tenacity at Yield ,,N/tex

Time,Extension,Load,Tensile strain (Extension),Tensile stress,Tenacity,Tensile extension
(s),(mm),(N),(mm/mm),(MPa),(N/tex),(mm)
"0.00000","0.00000","0.00162","0.00000","0.00027","0.00162","0.00000"
"0.10000","0.06794","-0.09630","0.00212","-0.01605","-0.09630","0.06794"
"0.20000","0.17917","-0.00907","0.00560","-0.00151","-0.00907","0.17917"
"0.30000","0.27948","0.07030","0.00873","0.01172","0.07030","0.27948"
"0.40000","0.37951","-0.01982","0.01186","-0.00330","-0.01982","0.37951"
"0.50000","0.47960","0.12602","0.01499","0.02100","0.12602","0.47960"
"0.60000","0.57964","0.04780","0.01811","0.00797","0.04780","0.57964"
"0.70000","0.67952","0.08086","0.02123","0.01348","0.08086","0.67952"
"0.80000","0.77947","0.05163","0.02436","0.00860","0.05163","0.77947"
"0.90000","0.87960","0.08220","0.02749","0.01370","0.08220","0.87960"
"1.00000","0.97962","0.11155","0.03061","0.01859","0.11155","0.97962"
"1.10000","1.07950","0.01993","0.03373","0.00332","0.01993","1.07950"
"1.20000","1.17948","0.07131","0.03686","0.01189","0.07131","1.17948"
"1.30000","1.27956","0.04676","0.03999","0.00779","0.04676","1.27956"
"1.40000","1.37955","0.11273","0.04311","0.01879","0.11273","1.37955"
"1.50000","1.47956","0.15068","0.04624","0.02511","0.15068","1.47956"
"1.60000","1.57951","0.15375","0.04936","0.02563","0.15375","1.57951"
"1.70000","1.67953","0.14428","0.05249","0.02405","0.14428","1.67953"
"1.80000","1.77970","0.19665","0.05562","0.03278","0.19665","1.77970"
"1.90000","1.87956","0.11763","0.05874","0.01960","0.11763","1.87956"
"2.00000","1.97948","0.11242","0.06186","0.01874","0.11242","1.97948"
"2.10000","2.07958","0.19646","0.06499","0.03274","0.19646","2.07958"
"2.20000","2.17964","0.12383","0.06811","0.02064","0.12383","2.17964"
"2.30000","2.27955","0.17653","0.07124","0.02942","0.17653","2.27955"
"2.40000","2.37946","0.21784","0.07436","0.03631","0.21784","2.37946"
"2.50000","2.47957","0.13368","0.07749","0.02228","0.13368","2.47957"
"2.60000","2.57967","0.18673","0.08061","0.03112","0.18673","2.57967"
"2.70000","2.67956","0.18689","0.08374","0.03115","0.18689","2.67956"
"2.80000","2.77950","0.23194","0.08686","0.03866","0.23194","2.77950"
"2.90000","2.87957","0.19808","0.08999","0.03301","0.19808","2.87957"
"3.00000","2.97965","0.19819","0.09311","0.03303","0.19819","2.97965"
"3.10000","3.07954","0.24982","0.09624","0.04164","0.24982","3.07954"
"3.20000","3.17951","0.20523","0.09936","0.03421","0.20523","3.17951"
"3.30000","3.27957","0.21357","0.10249","0.03559","0.21357","3.27957"
"3.40000","3.37961","0.28475","0.10561","0.04746","0.28475","3.37961"
"3.50000","3.47956","0.25702","0.10874","0.04284","0.25702","3.47956"
"3.60000","3.57953","0.31136","0.11186","0.05189","0.31136","3.57953"
"3.70000","3.67954","0.29101","0.11499","0.04850","0.29101","3.67954"
"3.80000","3.77961","0.23339","0.11811","0.03890","0.23339","3.77961"
"3.90000","3.87954","0.29317","0.12124","0.04886","0.29317","3.87954"
"4.00000","3.97947","0.27906","0.12436","0.04651","0.27906","3.97947"
"4.10000","4.07950","0.30429","0.12748","0.05072","0.30429","4.07950"
"4.20000","4.17968","0.27823","0.13062","0.04637","0.27823","4.17968"
"4.30000","4.27959","0.23568","0.13374","0.03928","0.23568","4.27959"
"4.40000","4.37949","0.30106","0.13686","0.05018","0.30106","4.37949"
"4.50000","4.47958","0.26866","0.13999","0.04478","0.26866","4.47958"
"4.60000","4.57963","0.33347","0.14311","0.05558","0.33347","4.57963"
"4.70000","4.67959","0.30648","0.14624","0.05108","0.30648","4.67959"
"4.80000","4.77943","0.30444","0.14936","0.05074","0.30444","4.77943"
"4.90000","4.87958","0.32132","0.15249","0.05355","0.32132","4.87958"
"5.00000","4.97965","0.41340","0.15561","0.06890","0.41340","4.97965"
"5.10000","5.07952","0.30349","0.15874","0.05058","0.30349","5.07952"
"5.20000","5.17950","0.27605","0.16186","0.04601","0.27605","5.17950"
"5.30000","5.27957","0.36467","0.16499","0.06078","0.36467","5.27957"
"5.40000","5.37971","0.32094","0.16812","0.05349","0.32094","5.37971"
"5.50000","5.47959","0.41501","0.17124","0.06917","0.41501","5.47959"
"5.60000","5.57949","0.32988","0.17436","0.05498","0.32988","5.57949"
"5.70000","5.67950","0.35779","0.17748","0.05963","0.35779","5.67950"
"5.80000","5.77957","0.32803","0.18061","0.05467","0.32803","5.77957"
"5.90000","5.87957","0.36635","0.18374","0.06106","0.36635","5.87957"
"6.00000","5.97951","0.42269","0.18686","0.07045","0.42269","5.97951"
"6.10000","6.07954","0.36464","0.18999","0.06077","0.36464","6.07954"
"6.20000","6.17962","0.39261","0.19311","0.06543","0.39261","6.17962"
"6.30000","6.27957","0.44402","0.19624","0.07400","0.44402","6.27957"
"6.40000","6.37943","0.39367","0.19936","0.06561","0.39367","6.37943"
"6.50000","6.47952","0.44134","0.20249","0.07356","0.44134","6.47952"
"6.60000","6.57964","0.41877","0.20561","0.06980","0.41877","6.57964"
"6.70000","6.67956","0.40193","0.20874","0.06699","0.40193","6.67956"
"6.80000","6.77948","0.52043","0.21186","0.08674","0.52043","6.77948"
"6.90000","6.87952","0.40194","0.21499","0.06699","0.40194","6.87952"
"7.00000","6.97966","0.39306","0.21811","0.06551","0.39306","6.97966"
"7.10000","7.07952","0.48183","0.22123","0.08031","0.48183","7.07952"
"7.20000","7.17942","0.42140","0.22436","0.07023","0.42140","7.17942"
"7.30000","7.27955","0.47547","0.22749","0.07925","0.47547","7.27955"
"7.40000","7.37963","0.41618","0.23061","0.06936","0.41618","7.37963"
"7.50000","7.47957","0.47303","0.23374","0.07884","0.47303","7.47957"
"7.60000","7.57949","0.52017","0.23686","0.08670","0.52017","7.57949"
"7.70000","7.67955","0.51622","0.23999","0.08604","0.51622","7.67955"
"7.80000","7.77961","0.48870","0.24311","0.08145","0.48870","7.77961"
"7.90000","7.87956","0.55458","0.24624","0.09243","0.55458","7.87956"
"8.00000","7.97948","0.48456","0.24936","0.08076","0.48456","7.97948"
"8.10000","8.07949","0.52960","0.25248","0.08827","0.52960","8.07949"
"8.20000","8.17962","0.53876","0.25561","0.08979","0.53876","8.17962"
"8.30000","8.27956","0.48037","0.25874","0.08006","0.48037","8.27956"
"8.40000","8.37944","0.53776","0.26186","0.08963","0.53776","8.37944"
"8.50000","8.47946","0.49162","0.26498","0.08194","0.49162","8.47946"
"8.60000","8.57959","0.48353","0.26811","0.08059","0.48353","8.57959"
"8.70000","8.67953","0.54465","0.27124","0.09078","0.54465","8.67953"
"8.80000","8.77941","0.51221","0.27436","0.08537","0.51221","8.77941"
"8.90000","8.87948","0.51771","0.27748","0.08628","0.51771","8.87948"
"9.00000","8.97961","0.55164","0.28061","0.09194","0.55164","8.97961"
"9.10000","9.07952","0.55303","0.28373","0.09217","0.55303","9.07952"
"9.20000","9.17941","0.53260","0.28686","0.08877","0.53260","9.17941"
"9.30000","9.27946","0.53522","0.28998","0.08920","0.53522","9.27946"
"9.40000","9.37955","0.56334","0.29311","0.09389","0.56334","9.37955"
"9.50000","9.47952","0.51334","0.29624","0.08556","0.51334","9.47952"
"9.60000","9.57938","0.60123","0.29936","0.10021","0.60123","9.57938"
"9.70000","9.67949","0.57911","0.30248","0.09652","0.57911","9.67949"
"9.80000","9.77959","0.55074","0.30561","0.09179","0.55074","9.77959"
"9.90000","9.87951","0.60447","0.30873","0.10075","0.60447","9.87951"
"10.00000","9.97943","0.59068","0.31186","0.09845","0.59068","9.97943"
"10.10000","10.07948","0.53362","0.31498","0.08894","0.53362","10.07948"
"10.20000","10.17953","0.60486","0.31811","0.10081","0.60486","10.17953"
"10.30000","10.27955","0.64814","0.32124","0.10802","0.64814","10.27955"
"10.40000","10.37943","0.63693","0.32436","0.10616","0.63693","10.37943"
"10.50000","10.47943","0.60855","0.32748","0.10143","0.60855","10.47943"
"10.60000","10.57953","0.65264","0.33061","0.10877","0.65264","10.57953"
"10.70000","10.67951","0.61112","0.33373","0.10185","0.61112","10.67951"
"10.80000","10.77941","0.58025","0.33686","0.09671","0.58025","10.77941"
"10.90000","10.87940","0.61619","0.33998","0.10270","0.61619","10.87940"
"11.00000","10.97957","0.64177","0.34311","0.10696","0.64177","10.97957"
"11.10000","11.07954","0.64891","0.34624","0.10815","0.64891","11.07954"
"11.20000","11.17934","0.61224","0.34935","0.10204","0.61224","11.17934"
"11.30000","11.27943","0.63913","0.35248","0.10652","0.63913","11.27943"
"11.40000","11.37955","0.66261","0.35561","0.11044","0.66261","11.37955"
"11.50000","11.47953","0.68043","0.35874","0.11341","0.68043","11.47953"
"11.60000","11.57943","0.65582","0.36186","0.10930","0.65582","11.57943"
"11.70000","11.67942","0.60621","0.36498","0.10104","0.60621","11.67942"
"11.80000","11.77949","0.67041","0.36811","0.11173","0.67041","11.77949"
"11.90000","11.87948","0.67385","0.37123","0.11231","0.67385","11.87948"
"12.00000","11.97936","0.60144","0.37436","0.10024","0.60144","11.97936"
"12.10000","12.07940","0.71958","0.37748","0.11993","0.71958","12.07940"
"12.20000","12.17954","0.65009","0.38061","0.10835","0.65009","12.17954"
"12.30000","12.27952","0.74417","0.38373","0.12403","0.74417","12.27952"
"12.40000","12.37939","0.76677","0.38686","0.12780","0.76677","12.37939"
"12.50000","12.47943","0.71294","0.38998","0.11882","0.71294","12.47943"
"12.60000","12.57947","0.83333","0.39311","0.13889","0.83333","12.57947"
"12.70000","12.67951","0.73409","0.39623","0.12235","0.73409","12.67951"
"12.80000","12.77940","0.72759","0.39936","0.12127","0.72759","12.77940"
"12.90000","12.87938","0.74507","0.40248","0.12418","0.74507","12.87938"
"13.00000","12.97955","0.72309","0.40561","0.12051","0.72309","12.97955"
"13.10000","13.07954","0.77780","0.40874","0.12963","0.77780","13.07954"
"13.20000","13.17937","0.73472","0.41186","0.12245","0.73472","13.17937"
"13.30000","13.27939","0.77337","0.41498","0.12889","0.77337","13.27939"
"13.40000","13.37951","0.82707","0.41811","0.13784","0.82707","13.37951"
"13.50000","13.47948","0.76668","0.42123","0.12778","0.76668","13.47948"
"13.60000","13.57932","0.77269","0.42435","0.12878","0.77269","13.57932"
"13.70000","13.67942","0.80720","0.42748","0.13453","0.80720","13.67942"
"13.80000","13.77953","0.77709","0.43061","0.12951","0.77709","13.77953"
"13.90000","13.87953","0.77592","0.43374","0.12932","0.77592","13.87953"
"14.00000","13.97938","0.77023","0.43686","0.12837","0.77023","13.97938"
"14.10000","14.07936","0.76826","0.43998","0.12804","0.76826","14.07936"
"14.20000","14.17947","0.85968","0.44311","0.14328","0.85968","14.17947"
"14.30000","14.27945","0.80506","0.44623","0.13418","0.80506","14.27945"
"14.40000","14.37935","0.82092","0.44935","0.13682","0.82092","14.37935"
"14.50000","14.47940","0.87936","0.45248","0.14656","0.87936","14.47940"
"14.60000","14.57949","0.82407","0.45561","0.13734","0.82407","14.57949"
"14.70000","14.67950","0.89453","0.45873","0.14909","0.89453","14.67950"
"14.80000","14.77937","0.85522","0.46186","0.14254","0.85522","14.77937"
"14.90000","14.87944","0.87735","0.46498","0.14623","0.87735","14.87944"
"15.00000","14.97951","0.91785","0.46811","0.15297","0.91785","14.97951"
"15.10000","15.07952","0.91331","0.47123","0.15222","0.91331","15.07952"
"15.20000","15.17939","0.84714","0.47436","0.14119","0.84714","15.17939"
"15.30000","15.27933","0.87964","0.47748","0.14661","0.87964","15.27933"
"15.40000","15.37949","0.85486","0.48061","0.14248","0.85486","15.37949"
"15.50000","15.47952","0.89604","0.48373","0.14934","0.89604","15.47952"
"15.60000","15.57934","0.89298","0.48685","0.14883","0.89298","15.57934"
"15.70000","15.67934","0.95853","0.48998","0.15976","0.95853","15.67934"
"15.80000","15.77950","0.94816","0.49311","0.15803","0.94816","15.77950"
"15.90000","15.87950","0.95527","0.49623","0.15921","0.95527","15.87950"
"16.00000","15.97939","0.88221","0.49936","0.14704","0.88221","15.97939"
"16.10000","16.07943","0.93857","0.50248","0.15643","0.93857","16.07943"
"16.20000","16.17949","0.92126","0.50561","0.15354","0.92126","16.17949"
"16.30000","16.27952","0.98997","0.50873","0.16499","0.98997","16.27952"
"16.40000","16.37940","0.91998","0.51186","0.15333","0.91998","16.37940"
"16.50000","16.47937","0.98168","0.51498","0.16361","0.98168","16.47937"
"16.60000","16.57951","0.93949","0.51811","0.15658","0.93949","16.57951"
"16.70000","16.67950","0.85340","0.52123","0.14223","0.85340","16.67950"
"16.80000","16.77945","0.96937","0.52436","0.16156","0.96937","16.77945"
"16.90000","16.87939","0.99303","0.52748","0.16550","0.99303","16.87939"
"17.00000","16.97947","1.01398","0.53061","0.16900","1.01398","16.97947"
"17.10000","17.07951","0.97480","0.53373","0.16247","0.97480","17.07951"
"17.20000","17.17942","1.01449","0.53686","0.16908","1.01449","17.17942"
"17.30000","17.27938","1.00475","0.53998","0.16746","1.00475","17.27938"
"17.40000","17.37954","1.01968","0.54311","0.16995","1.01968","17.37954"
"17.50000","17.47956","0.99010","0.54624","0.16502","0.99010","17.47956"
"17.60000","17.57938","0.97347","0.54936","0.16224","0.97347","17.57938"
"17.70000","17.67936","1.02891","0.55248","0.17148","1.02891","17.67936"
"17.80000","17.77951","1.00886","0.55561","0.16814","1.00886","17.77951"
"17.90000","17.87958","1.00334","0.55874","0.16722","1.00334","17.87958"
"18.00000","17.97939","1.02374","0.56186","0.17062","1.02374","17.97939"
"18.10000","18.07936","1.05941","0.56498","0.17657","1.05941","18.07936"
"18.20000","18.17951","1.10752","0.56811","0.18459","1.10752","18.17951"
"18.30000","18.27949","1.07193","0.57123","0.17865","1.07193","18.27949"
"18.40000","18.37937","1.02125","0.57436","0.17021","1.02125","18.37937"
"18.50000","18.47944","1.07774","0.57748","0.17962","1.07774","18.47944"
"18.60000","18.57953","1.04456","0.58061","0.17409","1.04456","18.57953"
"18.70000","18.67957","1.07926","0.58374","0.17988","1.07926","18.67957"
"18.80000","18.77942","1.01010","0.58686","0.16835","1.01010","18.77942"
"18.90000","18.87940","1.10158","0.58998","0.18360","1.10158","18.87940"
"19.00000","18.97947","1.10536","0.59311","0.18423","1.10536","18.97947"
"19.10000","19.07948","1.09573","0.59623","0.18262","1.09573","19.07948"
"19.20000","19.17947","1.10831","0.59936","0.18472","1.10831","19.17947"
"19.30000","19.27941","1.02210","0.60248","0.17035","1.02210","19.27941"
"19.40000","19.37951","1.05557","0.60561","0.17593","1.05557","19.37951"
"19.50000","19.47960","1.18898","0.60874","0.19816","1.18898","19.47960"
"19.60000","19.57947","1.08239","0.61186","0.18040","1.08239","19.57947"
"19.70000","19.67943","1.14226","0.61498","0.19038","1.14226","19.67943"
"19.80000","19.77955","1.19539","0.61811","0.19923","1.19539","19.77955"
"19.90000","19.87958","1.10074","0.62124","0.18346","1.10074","19.87958"
"20.00000","19.97943","1.10869","0.62436","0.18478","1.10869","19.97943"
"20.10000","20.07940","1.13469","0.62748","0.18911","1.13469","20.07940"
"20.20000","20.17953","1.10522","0.63061","0.18420","1.10522","20.17953"
"20.30000","20.27958","1.14719","0.63374","0.19120","1.14719","20.27958"
"20.40000","20.37946","1.18305","0.63686","0.19717","1.18305","20.37946"
"20.50000","20.47943","1.17440","0.63998","0.19573","1.17440","20.47943"
"20.60000","20.57954","1.21408","0.64311","0.20235","1.21408","20.57954"
"20.70000","20.67953","1.14604","0.64624","0.19101","1.14604","20.67953"
"20.80000","20.77945","1.14682","0.64936","0.19114","1.14682","20.77945"
"20.90000","20.87946","1.20159","0.65248","0.20026","1.20159","20.87946"
"21.00000","20.97954","1.15635","0.65561","0.19273","1.15635","20.97954"
"21.10000","21.07957","1.24655","0.65874","0.20776","1.24655","21.07957"
"21.20000","21.17946","1.26000","0.66186","0.21000","1.26000","21.17946"
"21.30000","21.27946","1.18785","0.66498","0.19798","1.18785","21.27946"
"21.40000","21.37954","1.23594","0.66811","0.20599","1.23594","21.37954"
"21.50000","21.47956","1.14651","0.67124","0.19108","1.14651","21.47956"
"21.60000","21.57950","1.22634","0.67436","0.20439","1.22634","21.57950"
"21.70000","21.67948","1.27673","0.67748","0.21279","1.27673","21.67948"
"21.80000","21.77954","1.25109","0.68061","0.20852","1.25109","21.77954"
"21.90000","21.87961","1.26592","0.68374","0.21099","1.26592","21.87961"
"22.00000","21.97944","1.27790","0.68686","0.21298","1.27790","21.97944"
"22.10000","22.07943","1.22035","0.68998","0.20339","1.22035","22.07943"
"22.20000","22.17960","1.29077","0.69311","0.21513","1.29077","22.17960"
"22.30000","22.27965","1.29200","0.69624","0.21533","1.29200","22.27965"
"22.40000","22.37952","1.25837","0.69936","0.20973","1.25837","22.37952"
"22.50000","22.47942","1.29591","0.70248","0.21599","1.29591","22.47942"
"22.60000","22.57954","1.34292","0.70561","0.22382","1.34292","22.57954"
"22.70000","22.67960","1.24715","0.70874","0.20786","1.24715","22.67960"
"22.80000","22.77949","1.31747","0.71186","0.21958","1.31747","22.77949"
"22.90000","22.87948","1.25938","0.71498","0.20990","1.25938","22.87948"
"23.00000","22.97960","1.33470","0.71811","0.22245","1.33470","22.97960"
"23.10000","23.07961","1.32715","0.72124","0.22119","1.32715","23.07961"
"23.20000","23.17954","1.31692","0.72436","0.21949","1.31692","23.17954"
"23.30000","23.27950","1.36849","0.72748","0.22808","1.36849","23.27950"
"23.40000","23.37955","1.36460","0.73061","0.22743","1.36460","23.37955"
"23.50000","23.47963","1.33623","0.73374","0.22270","1.33623","23.47963"
"23.60000","23.57953","1.36672","0.73686","0.22779","1.36672","23.57953"
"23.70000","23.67944","1.40110","0.73998","0.23352","1.40110","23.67944"
"23.80000","23.77952","1.42304","0.74311","0.23717","1.42304","23.77952"
"23.90000","23.87959","1.40018","0.74624","0.23336","1.40018","23.87959"
"24.00000","23.97954","1.31233","0.74936","0.21872","1.31233","23.97954"
"24.10000","24.07945","1.36809","0.75248","0.22801","1.36809","24.07945"
"24.20000","24.17955","1.41018","0.75561","0.23503","1.41018","24.17955"
"24.30000","24.27964","1.39511","0.75874","0.23252","1.39511","24.27964"
"24.40000","24.37954","1.40027","0.76186","0.23338","1.40027","24.37954"
"24.50000","24.47946","1.39186","0.76498","0.23198","1.39186","24.47946"
"24.60000","24.57957","1.40007","0.76811","0.23334","1.40007","24.57957"
"24.70000","24.67967","1.44647","0.77124","0.24108","1.44647","24.67967"
"24.80000","24.77954","1.44838","0.77436","0.24140","1.44838","24.77954"
"24.90000","24.87950","1.40476","0.77748","0.23413","1.40476","24.87950"
"25.00000","24.97961","1.48098","0.78061","0.24683","1.48098","24.97961"
"25.10000","25.07966","1.42543","0.78374","0.23757","1.42543","25.07966"
"25.20000","25.17954","1.50140","0.78686","0.25023","1.50140","25.17954"
"25.30000","25.27950","1.46642","0.78998","0.24440","1.46642","25.27950"
"25.40000","25.37958","1.46848","0.79311","0.24475","1.46848","25.37958"
"25.50000","25.47957","1.51615","0.79624","0.25269","1.51615","25.47957"
"25.60000","25.57957","1.53368","0.79936","0.25561","1.53368","25.57957"
"25.70000","25.67952","1.42283","0.80248","0.23714","1.42283","25.67952"
"25.80000","25.77958","1.53410","0.80561","0.25568","1.53410","25.77958"
"25.90000","25.87966","1.46227","0.80874","0.24371","1.46227","25.87966"
"26.00000","25.97957","1.52855","0.81186","0.25476","1.52855","25.97957"
"26.10000","26.07944","1.56339","0.81498","0.26056","1.56339","26.07944"
"26.20000","26.17952","1.54783","0.81811","0.25797","1.54783","26.17952"
"26.30000","26.27963","1.51301","0.82124","0.25217","1.51301","26.27963"
"26.40000","26.37959","1.54418","0.82436","0.25736","1.54418","26.37959"
"26.50000","26.47952","1.52709","0.82749","0.25452","1.52709","26.47952"
"26.60000","26.57955","1.61243","0.83061","0.26874","1.61243","26.57955"
"26.70000","26.67967","1.54050","0.83374","0.25675","1.54050","26.67967"
"26.80000","26.77957","1.62817","0.83686","0.27136","1.62817","26.77957"
"26.90000","26.87946","1.55029","0.83998","0.25838","1.55029","26.87946"
"27.00000","26.97955","1.53605","0.84311","0.25601","1.53605","26.97955"
"27.10000","27.07963","1.54011","0.84624","0.25668","1.54011","27.07963"
"27.20000","27.17955","1.60140","0.84936","0.26690","1.60140","27.17955"
"27.30000","27.27951","1.59039","0.85248","0.26506","1.59039","27.27951"
"27.40000","27.37960","1.61053","0.85561","0.26842","1.61053","27.37960"
"27.50000","27.47958","1.70002","0.85874","0.28334","1.70002","27.47958"
"27.60000","27.57951","1.54300","0.86186","0.25717","1.54300","27.57951"
"27.70000","27.67950","1.66015","0.86498","0.27669","1.66015","27.67950"
"27.80000","27.77957","1.62703","0.86811","0.27117","1.62703","27.77957"
"27.90000","27.87962","1.68094","0.87124","0.28016","1.68094","27.87962"
"28.00000","27.97963","1.61811","0.87436","0.26969","1.61811","27.97963"
"28.10000","28.07950","1.64674","0.87748","0.27446","1.64674","28.07950"
"28.20000","28.17957","1.67608","0.88061","0.27935","1.67608","28.17957"
"28.30000","28.27964","1.68956","0.88374","0.28159","1.68956","28.27964"
"28.40000","28.37955","1.63684","0.88686","0.27281","1.63684","28.37955"
"28.50000","28.47946","1.69668","0.88998","0.28278","1.69668","28.47946"
"28.60000","28.57952","1.71053","0.89311","0.28509","1.71053","28.57952"
"28.70000","28.67965","1.63278","0.89624","0.27213","1.63278","28.67965"
"28.80000","28.77955","1.71317","0.89936","0.28553","1.71317","28.77955"
"28.90000","28.87945","1.68108","0.90248","0.28018","1.68108","28.87945"
"29.00000","28.97953","1.69388","0.90561","0.28231","1.69388","28.97953"
"29.10000","29.07966","1.71215","0.90874","0.28536","1.71215","29.07966"
"29.20000","29.17956","1.78426","0.91186","0.29738","1.78426","29.17956"
"29.30000","29.27942","1.73486","0.91498","0.28914","1.73486","29.27942"
"29.40000","29.37959","1.76900","0.91811","0.29483","1.76900","29.37959"
"29.50000","29.47962","1.74972","0.92124","0.29162","1.74972","29.47962"
"29.60000","29.57950","1.73951","0.92436","0.28992","1.73951","29.57950"
"29.70000","29.67945","1.72655","0.92748","0.28776","1.72655","29.67945"
"29.80000","29.77954","1.75747","0.93061","0.29291","1.75747","29.77954"
"29.90000","29.87958","1.77400","0.93374","0.29567","1.77400","29.87958"
"30.00000","29.97954","1.78371","0.93686","0.29728","1.78371","29.97954"
"30.10000","30.07948","1.80469","0.93998","0.30078","1.80469","30.07948"
"30.20000","30.17947","1.79790","0.94311","0.29965","1.79790","30.17947"
"30.30000","30.27961","1.81715","0.94624","0.30286","1.81715","30.27961"
"30.40000","30.37958","1.84580","0.94936","0.30763","1.84580","30.37958"
"30.50000","30.47936","1.79176","0.95248","0.29863","1.79176","30.47936"
"30.60000","30.57948","1.82795","0.95561","0.30466","1.82795","30.57948"
"30.70000","30.67961","1.83440","0.95874","0.30573","1.83440","30.67961"
"30.80000","30.77956","1.82178","0.96186","0.30363","1.82178","30.77956"
"30.90000","30.87942","1.83684","0.96498","0.30614","1.83684","30.87942"
"31.00000","30.97946","1.88583","0.96811","0.31431","1.88583","30.97946"
"31.10000","31.07961","1.82562","0.97124","0.30427","1.82562","31.07961"
"31.20000","31.17955","1.85138","0.97436","0.30856","1.85138","31.17955"
"31.30000","31.27942","1.90248","0.97748","0.31708","1.90248","31.27942"
"31.40000","31.37951","1.82631","0.98061","0.30439","1.82631","31.37951"
"31.50000","31.47961","1.91749","0.98374","0.31958","1.91749","31.47961"
"31.60000","31.57953","1.85800","0.98686","0.30967","1.85800","31.57953"
"31.70000","31.67945","1.90191","0.98998","0.31699","1.90191","31.67945"
"31.80000","31.77950","1.96870","0.99311","0.32812","1.96870","31.77950"
"31.90000","31.87956","1.84757","0.99624","0.30793","1.84757","31.87956"
"32.00000","31.97951","1.89586","0.99936","0.31598","1.89586","31.97951"
"32.10000","32.07941","1.97364","1.00248","0.32894","1.97364","32.07941"
"32.20000","32.17950","1.92826","1.00561","0.32138","1.92826","32.17950"
"32.30000","32.27953","1.89308","1.00874","0.31551","1.89308","32.27953"
"32.40000","32.37952","1.91816","1.01186","0.31969","1.91816","32.37952"
"32.50000","32.47940","1.92592","1.01498","0.32099","1.92592","32.47940"
"32.60000","32.57938","2.00606","1.01811","0.33434","2.00606","32.57938"
"32.70000","32.67957","1.99193","1.02124","0.33199","1.99193","32.67957"
"32.80000","32.77953","2.00315","1.02436","0.33386","2.00315","32.77953"
"32.90000","32.87942","1.98815","1.02748","0.33136","1.98815","32.87942"
"33.00000","32.97946","1.95516","1.03061","0.32586","1.95516","32.97946"
"33.10000","33.07956","1.92728","1.03374","0.32121","1.92728","33.07956"
"33.20000","33.17952","1.98454","1.03686","0.33076","1.98454","33.17952"
"33.30000","33.27940","2.04509","1.03998","0.34085","2.04509","33.27940"
"33.40000","33.37938","2.03192","1.04311","0.33865","2.03192","33.37938"
"33.50000","33.47959","2.02146","1.04624","0.33691","2.02146","33.47959"
"33.60000","33.57952","2.02988","1.04936","0.33831","2.02988","33.57952"
"33.70000","33.67943","2.03003","1.05248","0.33834","2.03003","33.67943"
"33.80000","33.77945","2.04005","1.05561","0.34001","2.04005","33.77945"
"33.90000","33.87955","2.04997","1.05874","0.34166","2.04997","33.87955"
"34.00000","33.97946","2.07792","1.06186","0.34632","2.07792","33.97946"
"34.10000","34.07936","2.07554","1.06498","0.34592","2.07554","34.07936"
"34.20000","34.17941","2.07027","1.06811","0.34504","2.07027","34.17941"
"34.30000","34.27953","2.12978","1.07124","0.35496","2.12978","34.27953"
"34.40000","34.37947","2.01853","1.07436","0.33642","2.01853","34.37947"
"34.50000","34.47940","2.06772","1.07748","0.34462","2.06772","34.47940"
"34.60000","34.57945","2.08069","1.08061","0.34678","2.08069","34.57945"
"34.70000","34.67949","2.10863","1.08373","0.35144","2.10863","34.67949"
"34.80000","34.77952","2.18669","1.08686","0.36445","2.18669","34.77952"
"34.90000","34.87942","2.11402","1.08998","0.35234","2.11402","34.87942"
"35.00000","34.97939","2.17749","1.09311","0.36292","2.17749","34.97939"
"35.10000","35.07951","2.15282","1.09623","0.35880","2.15282","35.07951"
"35.20000","35.17953","2.12610","1.09936","0.35435","2.12610","35.17953"
"35.30000","35.27936","2.14244","1.10248","0.35707","2.14244","35.27936"
"35.40000","35.37939","2.20060","1.10561","0.36677","2.20060","35.37939"
"35.50000","35.47955","2.10742","1.10874","0.35124","2.10742","35.47955"
"35.60000","35.57946","2.15490","1.11186","0.35915","2.15490","35.57946"
"35.70000","35.67936","2.19906","1.11498","0.36651","2.19906","35.67936"
"35.80000","35.77935","2.17468","1.11810","0.36245","2.17468","35.77935"
"35.90000","35.87950","2.22503","1.12123","0.37084","2.22503","35.87950"
"36.00000","35.97948","2.24471","1.12436","0.37412","2.24471","35.97948"
"36.10000","36.07935","2.20605","1.12748","0.36767","2.20605","36.07935"
"36.20000","36.17939","2.24888","1.13061","0.37481","2.24888","36.17939"
"36.30000","36.27953","2.29843","1.13374","0.38307","2.29843","36.27953"
"36.40000","36.37949","2.21282","1.13686","0.36880","2.21282","36.37949"
"36.50000","36.47941","2.35075","1.13998","0.39179","2.35075","36.47941"
"36.60000","36.57939","2.26357","1.14311","0.37726","2.26357","36.57939"
"36.70000","36.67952","2.22464","1.14623","0.37077","2.22464","36.67952"
"36.80000","36.77948","2.29384","1.14936","0.38231","2.29384","36.77948"
"36.90000","36.87939","2.20784","1.15248","0.36797","2.20784","36.87939"
"37.00000","36.97938","2.32927","1.15561","0.38821","2.32927","36.97938"
"37.10000","37.07946","2.27715","1.15873","0.37953","2.27715","37.07946"
"37.20000","37.17952","2.29792","1.16186","0.38299","2.29792","37.17952"
"37.30000","37.27939","2.32713","1.16498","0.38785","2.32713","37.27939"
"37.40000","37.37932","2.34874","1.16810","0.39146","2.34874","37.37932"
"37.50000","37.47952","2.34481","1.17124","0.39080","2.34481","37.47952"
"37.60000","37.57956","2.39905","1.17436","0.39984","2.39905","37.57956"
"37.70000","37.67938","2.34878","1.17748","0.39146","2.34878","37.67938"
"37.80000","37.77936","2.40691","1.18060","0.40115","2.40691","37.77936"
"37.90000","37.87951","2.41036","1.18373","0.40173","2.41036","37.87951"
"38.00000","37.97946","2.31678","1.18686","0.38613","2.31678","37.97946"
"38.10000","38.07935","2.43479","1.18998","0.40580","2.43479","38.07935"
"38.20000","38.17939","2.39928","1.19311","0.39988","2.39928","38.17939"
"38.30000","38.27950","2.34583","1.19623","0.39097","2.34583","38.27950"
"38.40000","38.37949","2.40102","1.19936","0.40017","2.40102","38.37949"
"38.50000","38.47939","2.41590","1.20248","0.40265","2.41590","38.47939"
"38.60000","38.57942","2.40429","1.20561","0.40072","2.40429","38.57942"
"38.70000","38.67950","2.49728","1.20873","0.41621","2.49728","38.67950"
"38.80000","38.77948","2.47876","1.21186","0.41313","2.47876","38.77948"
"38.90000","38.87938","2.43403","1.21498","0.40567","2.43403","38.87938"
"39.00000","38.97929","2.45876","1.21810","0.40979","2.45876","38.97929"
"39.10000","39.07945","2.44039","1.22123","0.40673","2.44039","39.07945"
"39.20000","39.17956","2.48466","1.22436","0.41411","2.48466","39.17956"
"39.30000","39.27943","2.50815","1.22748","0.41802","2.50815","39.27943"
"39.40000","39.37939","2.49900","1.23061","0.41650","2.49900","39.37939"
"39.50000","39.47943","2.52855","1.23373","0.42143","2.52855","39.47943"
"39.60000","39.57952","2.50792","1.23686","0.41799","2.50792","39.57952"
"39.70000","39.67939","2.47012","1.23998","0.41169","2.47012","39.67939"
"39.80000","39.77936","2.54258","1.24310","0.42376","2.54258","39.77936"
"39.90000","39.87955","2.51814","1.24624","0.41969","2.51814","39.87955"
"40.00000","39.97958","2.59692","1.24936","0.43282","2.59692","39.97958"
"40.10000","40.07941","2.54978","1.25248","0.42496","2.54978","40.07941"
"40.20000","40.17939","2.59240","1.25561","0.43207","2.59240","40.17939"
"40.30000","40.27952","2.52700","1.25874","0.42117","2.52700","40.27952"
"40.40000","40.37952","2.57559","1.26186","0.42926","2.57559","40.37952"
"40.50000","40.47936","2.56162","1.26498","0.42694","2.56162","40.47936"
"40.60000","40.57937","2.63144","1.26811","0.43857","2.63144","40.57937"
"40.70000","40.67954","2.67094","1.27124","0.44516","2.67094","40.67954"
"40.80000","40.77953","2.56541","1.27436","0.42757","2.56541","40.77953"
"40.90000","40.87941","2.67596","1.27748","0.44599","2.67596","40.87941"
"41.00000","40.97942","2.62984","1.28061","0.43831","2.62984","40.97942"
"41.10000","41.07951","2.67760","1.28373","0.44627","2.67760","41.07951"
"41.20000","41.17955","2.71606","1.28686","0.45268","2.71606","41.17955"
"41.30000","41.27943","2.67664","1.28998","0.44611","2.67664","41.27943"
"41.40000","41.37941","2.60128","1.29311","0.43355","2.60128","41.37941"
"41.50000","41.47946","2.75146","1.29623","0.45858","2.75146","41.47946"
"41.60000","41.57955","2.64918","1.29936","0.44153","2.64918","41.57955"
"41.70000","41.67947","2.68684","1.30248","0.44781","2.68684","41.67947"
"41.80000","41.77940","2.75494","1.30561","0.45916","2.75494","41.77940"
"41.90000","41.87948","2.73385","1.30873","0.45564","2.73385","41.87948"
"42.00000","41.97955","2.71310","1.31186","0.45218","2.71310","41.97955"
"42.10000","42.07942","2.72370","1.31498","0.45395","2.72370","42.07942"
"42.20000","42.17943","2.71526","1.31811","0.45254","2.71526","42.17943"
"42.30000","42.27955","2.78876","1.32124","0.46479","2.78876","42.27955"
"42.40000","42.37956","2.76442","1.32436","0.46074","2.76442","42.37956"
"42.50000","42.47944","2.78805","1.32748","0.46468","2.78805","42.47944"
"42.60000","42.57940","2.80230","1.33061","0.46705","2.80230","42.57940"
"42.70000","42.67955","2.74438","1.33374","0.45740","2.74438","42.67955"
"42.80000","42.77956","2.81749","1.33686","0.46958","2.81749","42.77956"
"42.90000","42.87941","2.85373","1.33998","0.47562","2.85373","42.87941"
"43.00000","42.97948","2.81122","1.34311","0.46854","2.81122","42.97948"
"43.10000","43.07956","2.85062","1.34624","0.47510","2.85062","43.07956"
"43.20000","43.17958","2.82068","1.34936","0.47011","2.82068","43.17958"
"43.30000","43.27945","2.87048","1.35248","0.47841","2.87048","43.27945"
"43.40000","43.37947","2.89281","1.35561","0.48214","2.89281","43.37947"
"43.50000","43.47955","2.86362","1.35874","0.47727","2.86362","43.47955"
"43.60000","43.57960","2.93344","1.36186","0.48891","2.93344","43.57960"
"43.70000","43.67949","2.99262","1.36498","0.49877","2.99262","43.67949"
"43.80000","43.77940","2.86479","1.36811","0.47746","2.86479","43.77940"
"43.90000","43.87947","2.89852","1.37123","0.48309","2.89852","43.87947"
"44.00000","43.97959","2.96121","1.37436","0.49353","2.96121","43.97959"
"44.10000","44.07949","2.96037","1.37748","0.49339","2.96037","44.07949"
"44.20000","44.17941","2.94934","1.38061","0.49156","2.94934","44.17941"
"44.30000","44.27953","2.96003","1.38374","0.49334","2.96003","44.27953"
"44.40000","44.37961","2.92247","1.38686","0.48708","2.92247","44.37961"
"44.50000","44.47946","2.90065","1.38998","0.48344","2.90065","44.47946"
"44.60000","44.57944","3.05331","1.39311","0.50888","3.05331","44.57944"
"44.70000","44.67957","2.99242","1.39624","0.49874","2.99242","44.67957"
"44.80000","44.77962","2.96798","1.39936","0.49466","2.96798","44.77962"
"44.90000","44.87952","3.02774","1.40249","0.50462","3.02774","44.87952"
"45.00000","44.97948","2.98256","1.40561","0.49709","2.98256","44.97948"
"45.10000","45.07955","3.02648","1.40874","0.50441","3.02648","45.07955"
"45.20000","45.17961","3.01723","1.41186","0.50287","3.01723","45.17961"
"45.30000","45.27947","3.09247","1.41498","0.51541","3.09247","45.27947"
"45.40000","45.37950","3.11881","1.41811","0.51980","3.11881","45.37950"
"45.50000","45.47955","3.06082","1.42124","0.51014","3.06082","45.47955"
"45.60000","45.57962","3.08864","1.42436","0.51477","3.08864","45.57962"
"45.70000","45.67951","3.11092","1.42748","0.51849","3.11092","45.67951"
"45.80000","45.77948","3.09975","1.43061","0.51662","3.09975","45.77948"
"45.90000","45.87954","3.14234","1.43374","0.52372","3.14234","45.87954"
"46.00000","45.97966","3.13796","1.43686","0.52299","3.13796","45.97966"
"46.10000","46.07954","3.08182","1.43999","0.51364","3.08182","46.07954"
"46.20000","46.17947","3.18040","1.44311","0.53007","3.18040","46.17947"
"46.30000","46.27954","3.09192","1.44624","0.51532","3.09192","46.27954"
"46.40000","46.37965","3.18744","1.44936","0.53124","3.18744","46.37965"
"46.50000","46.47954","3.19086","1.45249","0.53181","3.19086","46.47954"
"46.60000","46.57942","3.13845","1.45561","0.52307","3.13845","46.57942"
"46.70000","46.67958","3.25841","1.45874","0.54307","3.25841","46.67958"
"46.80000","46.77967","3.21281","1.46186","0.53547","3.21281","46.77967"
"46.90000","46.87948","3.22686","1.46498","0.53781","3.22686","46.87948"
"47.00000","46.97950","3.23919","1.46811","0.53987","3.23919","46.97950"
"47.10000","47.07962","3.28103","1.47124","0.54684","3.28103","47.07962"
"47.20000","47.17967","3.21170","1.47436","0.53528","3.21170","47.17967"
"47.30000","47.27954","3.27675","1.47749","0.54612","3.27675","47.27954"
"47.40000","47.37946","3.23468","1.48061","0.53911","3.23468","47.37946"
"47.50000","47.47947","3.32640","1.48373","0.55440","3.32640","47.47947"
"47.60000","47.57959","3.33500","1.48686","0.55583","3.33500","47.57959"
"47.70000","47.67952","3.30989","1.48999","0.55165","3.30989","47.67952"
"47.80000","47.77953","3.33383","1.49311","0.55564","3.33383","47.77953"
"47.90000","47.87959","3.35142","1.49624","0.55857","3.35142","47.87959"
"48.00000","47.97964","3.30189","1.49936","0.55032","3.30189","47.97964"
"48.10000","48.07955","3.37221","1.50249","0.56204","3.37221","48.07955"
"48.20000","48.17952","3.34597","1.50561","0.55766","3.34597","48.17952"
"48.30000","48.27955","3.41010","1.50874","0.56835","3.41010","48.27955"
"48.40000","48.37967","3.45169","1.51186","0.57528","3.45169","48.37967"
"48.50000","48.47958","3.34934","1.51499","0.55822","3.34934","48.47958"
"48.60000","48.57949","3.40922","1.51811","0.56820","3.40922","48.57949"
"48.70000","48.67955","3.36838","1.52124","0.56140","3.36838","48.67955"
"48.80000","48.77966","3.38473","1.52436","0.56412","3.38473","48.77966"
"48.90000","48.87954","3.46649","1.52749","0.57775","3.46649","48.87954"
"49.00000","48.97948","3.48429","1.53061","0.58072","3.48429","48.97948"
"49.10000","49.07956","3.40279","1.53374","0.56713","3.40279","49.07956"
"49.20000","49.17966","3.51153","1.53686","0.58525","3.51153","49.17966"
"49.30000","49.27948","3.48943","1.53998","0.58157","3.48943","49.27948"
"49.40000","49.37951","3.47866","1.54311","0.57978","3.47866","49.37951"
"49.50000","49.47958","3.47269","1.54624","0.57878","3.47269","49.47958"
"49.60000","49.57965","3.46150","1.54936","0.57692","3.46150","49.57965"
"49.70000","49.67958","3.51578","1.55249","0.58596","3.51578","49.67958"
"49.80000","49.77951","3.53792","1.55561","0.58965","3.53792","49.77951"
"49.90000","49.87956","3.53613","1.55874","0.58936","3.53613","49.87956"
"50.00000","49.97961","3.53591","1.56186","0.58932","3.53591","49.97961"
"50.10000","50.07956","3.47907","1.56499","0.57985","3.47907","50.07956"
"50.20000","50.17947","3.52555","1.56811","0.58759","3.52555","50.17947"
"50.30000","50.27952","3.58224","1.57124","0.59704","3.58224","50.27952"
"50.40000","50.37963","3.59033","1.57436","0.59839","3.59033","50.37963"
"50.50000","50.47958","3.54907","1.57749","0.59151","3.54907","50.47958"
"50.60000","50.57949","3.60240","1.58061","0.60040","3.60240","50.57949"
"50.70000","50.67954","3.58142","1.58374","0.59690","3.58142","50.67954"
"50.80000","50.77966","3.57276","1.58686","0.59546","3.57276","50.77966"
"50.90000","50.87957","3.63864","1.58999","0.60644","3.63864","50.87957"
"51.00000","50.97946","3.60090","1.59311","0.60015","3.60090","50.97946"
"51.10000","51.07951","3.68287","1.59623","0.61381","3.68287","51.07951"
"51.20000","51.17961","3.70108","1.59936","0.61685","3.70108","51.17961"
"51.30000","51.27957","3.70729","1.60249","0.61788","3.70729","51.27957"
"51.40000","51.37944","3.66554","1.60561","0.61092","3.66554","51.37944"
"51.50000","51.47956","3.76385","1.60874","0.62731","3.76385","51.47956"
"51.60000","51.57964","3.64983","1.61186","0.60830","3.64983","51.57964"
"51.70000","51.67953","3.74985","1.61499","0.62497","3.74985","51.67953"
"51.80000","51.77952","3.71775","1.61811","0.61963","3.71775","51.77952"
"51.90000","51.87958","3.74804","1.62124","0.62467","3.74804","51.87958"
"52.00000","51.97960","3.71864","1.62436","0.61977","3.71864","51.97960"
"52.10000","52.07955","3.78012","1.62749","0.63002","3.78012","52.07955"
"52.20000","52.17948","3.75999","1.63061","0.62667","3.75999","52.17948"
"52.30000","52.27949","3.75782","1.63373","0.62630","3.75782","52.27949"
"52.40000","52.37957","3.79658","1.63686","0.63276","3.79658","52.37957"
"52.50000","52.47957","3.84432","1.63999","0.64072","3.84432","52.47957"
"52.60000","52.57948","3.86877","1.64311","0.64480","3.86877","52.57948"
"52.70000","52.67951","3.84388","1.64623","0.64065","3.84388","52.67951"
"52.80000","52.77961","3.77992","1.64936","0.62999","3.77992","52.77961"
"52.90000","52.87957","3.86594","1.65249","0.64432","3.86594","52.87957"
"53.00000","52.97945","3.86650","1.65561","0.64442","3.86650","52.97945"
"53.10000","53.07949","3.86234","1.65873","0.64372","3.86234","53.07949"
"53.20000","53.17963","3.88196","1.66186","0.64699","3.88196","53.17963"
"53.30000","53.27954","3.93556","1.66499","0.65593","3.93556","53.27954"
"53.40000","53.37942","3.96915","1.66811","0.66152","3.96915","53.37942"
"53.50000","53.47952","3.97975","1.67123","0.66329","3.97975","53.47952"
"53.60000","53.57966","3.90971","1.67436","0.65162","3.90971","53.57966"
"53.70000","53.67950","3.92568","1.67748","0.65428","3.92568","53.67950"
"53.80000","53.77938","3.97024","1.68061","0.66171","3.97024","53.77938"
"53.90000","53.87947","3.96614","1.68373","0.66102","3.96614","53.87947"
"54.00000","53.97958","4.00496","1.68686","0.66749","4.00496","53.97958"
"54.10000","54.07951","3.99689","1.68998","0.66615","3.99689","54.07951"
"54.20000","54.17944","4.03040","1.69311","0.67173","4.03040","54.17944"
"54.30000","54.27947","3.99912","1.69623","0.66652","3.99912","54.27947"
"54.40000","54.37960","4.01481","1.69936","0.66913","4.01481","54.37960"
"54.50000","54.47952","4.04585","1.70248","0.67431","4.04585","54.47952"
"54.60000","54.57946","4.07208","1.70561","0.67868","4.07208","54.57946"
"54.70000","54.67946","4.05645","1.70873","0.67607","4.05645","54.67946"
"54.80000","54.77949","4.07289","1.71186","0.67881","4.07289","54.77949"
"54.90000","54.87959","4.12869","1.71499","0.68811","4.12869","54.87959"
"55.00000","54.97943","4.15597","1.71811","0.69266","4.15597","54.97943"
"55.10000","55.07945","4.10775","1.72123","0.68463","4.10775","55.07945"
"55.20000","55.17957","4.06945","1.72436","0.67824","4.06945","55.17957"
"55.30000","55.27958","4.12022","1.72749","0.68670","4.12022","55.27958"
"55.40000","55.37943","4.17636","1.73061","0.69606","4.17636","55.37943"
"55.50000","55.47947","4.18063","1.73373","0.69677","4.18063","55.47947"
"55.60000","55.57960","4.18412","1.73686","0.69735","4.18412","55.57960"
"55.70000","55.67949","4.17516","1.73998","0.69586","4.17516","55.67949"
"55.80000","55.77934","4.21772","1.74310","0.70295","4.21772","55.77934"
"55.90000","55.87942","4.21611","1.74623","0.70269","4.21611","55.87942"
"56.00000","55.97955","4.19282","1.74936","0.69880","4.19282","55.97955"
"56.10000","56.07948","4.26290","1.75248","0.71048","4.26290","56.07948"
"56.20000","56.17940","4.27841","1.75561","0.71307","4.27841","56.17940"
"56.30000","56.27946","4.22317","1.75873","0.70386","4.22317","56.27946"
"56.40000","56.37949","4.27171","1.76186","0.71195","4.27171","56.37949"
"56.50000","56.47950","4.25147","1.76498","0.70858","4.25147","56.47950"
"56.60000","56.57938","4.26407","1.76811","0.71068","4.26407","56.57938"
"56.70000","56.67942","4.32992","1.77123","0.72165","4.32992","56.67942"
"56.80000","56.77956","4.29379","1.77436","0.71563","4.29379","56.77956"
"56.90000","56.87952","4.30757","1.77748","0.71793","4.30757","56.87952"
"57.00000","56.97940","4.34562","1.78061","0.72427","4.34562","56.97940"
"57.10000","57.07940","4.29949","1.78373","0.71658","4.29949","57.07940"
"57.20000","57.17950","4.41838","1.78686","0.73640","4.41838","57.17950"
"57.30000","57.27953","4.34845","1.78999","0.72474","4.34845","57.27953"
"57.40000","57.37941","4.32544","1.79311","0.72091","4.32544","57.37941"
"57.50000","57.47937","4.43918","1.79623","0.73986","4.43918","57.47937"
"57.60000","57.57952","4.39361","1.79936","0.73227","4.39361","57.57952"
"57.70000","57.67952","4.48483","1.80249","0.74747","4.48483","57.67952"
"57.80000","57.77935","4.45408","1.80560","0.74235","4.45408","57.77935"
"57.90000","57.87943","4.42480","1.80873","0.73747","4.42480","57.87943"
"58.00000","57.97955","4.46179","1.81186","0.74363","4.46179","57.97955"
"58.10000","58.07949","4.53895","1.81498","0.75649","4.53895","58.07949"
"58.20000","58.17934","4.49883","1.81810","0.74980","4.49883","58.17934"
"58.30000","58.27941","4.54053","1.82123","0.75676","4.54053","58.27941"
"58.40000","58.37954","4.57938","1.82436","0.76323","4.57938","58.37954"
"58.50000","58.47946","4.44097","1.82748","0.74016","4.44097","58.47946"
"58.60000","58.57939","4.49804","1.83061","0.74967","4.49804","58.57939"
"58.70000","58.67940","4.58115","1.83373","0.76353","4.58115","58.67940"
"58.80000","58.77948","4.55476","1.83686","0.75913","4.55476","58.77948"
"58.90000","58.87950","4.55483","1.83998","0.75914","4.55483","58.87950"
"59.00000","58.97938","4.60364","1.84311","0.76727","4.60364","58.97938"
"59.10000","59.07937","4.53823","1.84623","0.75637","4.53823","59.07937"
"59.20000","59.17951","4.66685","1.84936","0.77781","4.66685","59.17951"
"59.30000","59.27948","4.60880","1.85248","0.76813","4.60880","59.27948"
"59.40000","59.37936","4.70982","1.85561","0.78497","4.70982","59.37936"
"59.50000","59.47935","4.60124","1.85873","0.76687","4.60124","59.47935"
"59.60000","59.57944","4.57374","1.86186","0.76229","4.57374","59.57944"
"59.70000","59.67954","4.67937","1.86499","0.77989","4.67937","59.67954"
"59.80000","59.77938","4.66991","1.86811","0.77832","4.66991","59.77938"
"59.90000","59.87938","4.63696","1.87123","0.77283","4.63696","59.87938"
"60.00000","59.97953","4.73551","1.87436","0.78925","4.73551","59.97953"
"60.10000","60.07952","4.70663","1.87749","0.78444","4.70663","60.07952"
"60.20000","60.17935","4.70833","1.88060","0.78472","4.70833","60.17935"
"60.30000","60.27940","4.75653","1.88373","0.79275","4.75653","60.27940"
"60.40000","60.37954","4.68532","1.88686","0.78089","4.68532","60.37954"
"60.50000","60.47949","4.73620","1.88998","0.78937","4.73620","60.47949"
"60.60000","60.57935","4.82544","1.89310","0.80424","4.82544","60.57935"
"60.70000","60.67940","4.82182","1.89623","0.80364","4.82182","60.67940"
"60.80000","60.77948","4.82131","1.89936","0.80355","4.82131","60.77948"
"60.90000","60.87947","4.91068","1.90248","0.81845","4.91068","60.87947"
"61.00000","60.97941","4.79633","1.90561","0.79939","4.79633","60.97941"
"61.10000","61.07940","4.86971","1.90873","0.81162","4.86971","61.07940"
"61.20000","61.17943","4.84160","1.91186","0.80693","4.84160","61.17943"
"61.30000","61.27953","4.92559","1.91499","0.82093","4.92559","61.27953"
"61.40000","61.37940","4.91128","1.91811","0.81855","4.91128","61.37940"
"61.50000","61.47939","4.90235","1.92123","0.81706","4.90235","61.47939"
"61.60000","61.57948","5.01009","1.92436","0.83502","5.01009","61.57948"
"61.70000","61.67951","4.92415","1.92748","0.82069","4.92415","61.67951"
"61.80000","61.77935","4.99693","1.93060","0.83282","4.99693","61.77935"
"61.90000","61.87936","5.00181","1.93373","0.83364","5.00181","61.87936"
"62.00000","61.97949","4.96072","1.93686","0.82679","4.96072","61.97949"
"62.10000","62.07952","4.96510","1.93999","0.82752","4.96510","62.07952"
"62.20000","62.17937","5.05401","1.94311","0.84234","5.05401","62.17937"
"62.30000","62.27936","4.99359","1.94623","0.83226","4.99359","62.27936"
"62.40000","62.37954","4.97462","1.94936","0.82910","4.97462","62.37954"
"62.50000","62.47955","5.03644","1.95249","0.83941","5.03644","62.47955"
"62.60000","62.57936","4.99786","1.95561","0.83298","4.99786","62.57936"
"62.70000","62.67939","5.08053","1.95873","0.84675","5.08053","62.67939"
"62.80000","62.77951","5.06617","1.96186","0.84436","5.06617","62.77951"
"62.90000","62.87951","4.99364","1.96498","0.83227","4.99364","62.87951"
"63.00000","62.97942","5.10974","1.96811","0.85162","5.10974","62.97942"
"63.10000","63.07944","5.10368","1.97123","0.85061","5.10368","63.07944"
"63.20000","63.17952","1.80415","1.97436","0.30069","1.80415","63.17952"
"63.30000","63.27953","0.18617","1.97749","0.03103","0.18617","63.27953"
"63.40000","63.37943","0.25025","1.98061","0.04171","0.25025","63.37943"
"63.50000","63.47937","0.22403","1.98373","0.03734","0.22403","63.47937"
"63.60000","63.57948","0.15735","1.98686","0.02622","0.15735","63.57948"
"63.70000","63.67959","0.17557","1.98999","0.02926","0.17557","63.67959"
"63.80000","63.77944","0.20351","1.99311","0.03392","0.20351","63.77944"
"63.90000","63.87941","0.26072","1.99623","0.04345","0.26072","63.87941"
"64.00000","63.97954","0.17473","1.99936","0.02912","0.17473","63.97954"
"64.10000","64.07958","0.23144","2.00249","0.03857","0.23144","64.07958"
"64.20000","64.17942","0.21947","2.00561","0.03658","0.21947","64.17942"
"64.30000","64.27936","0.20666","2.00873","0.03444","0.20666","64.27936"
"64.40000","64.37946","0.17493","2.01186","0.02915","0.17493","64.37946"
"64.50000","64.47952","0.23051","2.01498","0.03842","0.23051","64.47952"
"64.60000","64.57944","0.17284","2.01811","0.02881","0.17284","64.57944"
"64.70000","64.67944","0.22849","2.02123","0.03808","0.22849","64.67944"
"64.72700","64.70641","0.21263","2.02208","0.03544","0.21263","64.70641"