File: 10silicone20.csv
Tenacity at Break (Standard),"0.23566",N/tex
Tensile extension at Break (Standard),"74.01347",mm
Tenacity at Yield ,,N/tex

Time,Extension,Load,Tensile strain (Extension),Tensile stress,Tenacity,Tensile extension
(s),(mm),(N),(mm/mm),(MPa),(N/tex),(mm)
"0.00000","0.00000","0.02224","0.00000","0.00371","0.02224","0.00000"
"0.20000","0.17915","0.03748","0.00560","0.00625","0.03748","0.17915"
"0.40000","0.37954","-0.03792","0.01186","-0.00632","-0.03792","0.37954"
"0.60000","0.57956","-0.00990","0.01811","-0.00165","-0.00990","0.57956"
"0.80000","0.77953","-0.02206","0.02436","-0.00368","-0.02206","0.77953"
"1.00000","0.97956","0.04147","0.03061","0.00691","0.04147","0.97956"
"1.20000","1.17958","0.14919","0.03686","0.02487","0.14919","1.17958"
"1.40000","1.37949","0.11394","0.04311","0.01899","0.11394","1.37949"
"1.60000","1.57958","0.09682","0.04936","0.01614","0.09682","1.57958"
"1.80000","1.77954","0.09341","0.05561","0.01557","0.09341","1.77954"
"2.00000","1.97950","0.12914","0.06186","0.02152","0.12914","1.97950"
"2.20000","2.17959","0.10282","0.06811","0.01714","0.10282","2.17959"
"2.40000","2.37956","0.18897","0.07436","0.03149","0.18897","2.37956"
"2.60000","2.57958","0.12643","0.08061","0.02107","0.12643","2.57958"
"2.80000","2.77950","0.07996","0.08686","0.01333","0.07996","2.77950"
"3.00000","2.97958","0.07350","0.09311","0.01225","0.07350","2.97958"
"3.20000","3.17955","0.18365","0.09936","0.03061","0.18365","3.17955"
"3.40000","3.37957","0.15202","0.10561","0.02534","0.15202","3.37957"
"3.60000","3.57958","0.16204","0.11186","0.02701","0.16204","3.57958"
"3.80000","3.77951","0.16499","0.11811","0.02750","0.16499","3.77951"
"4.00000","3.97963","0.17154","0.12436","0.02859","0.17154","3.97963"
"4.20000","4.17956","0.20500","0.13061","0.03417","0.20500","4.17956"
"4.40000","4.37941","0.22097","0.13686","0.03683","0.22097","4.37941"
"4.60000","4.57956","0.13998","0.14311","0.02333","0.13998","4.57956"
"4.80000","4.77952","0.22724","0.14936","0.03787","0.22724","4.77952"
"5.00000","4.97956","0.25305","0.15561","0.04218","0.25305","4.97956"
"5.20000","5.17953","0.22647","0.16186","0.03774","0.22647","5.17953"
"5.40000","5.37956","0.19957","0.16811","0.03326","0.19957","5.37956"
"5.60000","5.57958","0.24808","0.17436","0.04135","0.24808","5.57958"
"5.80000","5.77955","0.22869","0.18061","0.03812","0.22869","5.77955"
"6.00000","5.97958","0.26287","0.18686","0.04381","0.26287","5.97958"
"6.20000","6.17946","0.27589","0.19311","0.04598","0.27589","6.17946"
"6.40000","6.37959","0.31291","0.19936","0.05215","0.31291","6.37959"
"6.60000","6.57952","0.22124","0.20561","0.03687","0.22124","6.57952"
"6.80000","6.77950","0.24711","0.21186","0.04118","0.24711","6.77950"
"7.00000","6.97954","0.36200","0.21811","0.06033","0.36200","6.97954"
"7.20000","7.17951","0.33606","0.22436","0.05601","0.33606","7.17951"
"7.40000","7.37949","0.32015","0.23061","0.05336","0.32015","7.37949"
"7.60000","7.57954","0.29562","0.23686","0.04927","0.29562","7.57954"
"7.80000","7.77950","0.28468","0.24311","0.04745","0.28468","7.77950"
"8.00000","7.97950","0.41440","0.24936","0.06907","0.41440","7.97950"
"8.20000","8.17947","0.36985","0.25561","0.06164","0.36985","8.17947"
"8.40000","8.37958","0.33359","0.26186","0.05560","0.33359","8.37958"
"8.60000","8.57947","0.33494","0.26811","0.05582","0.33494","8.57947"
"8.80000","8.77956","0.33017","0.27436","0.05503","0.33017","8.77956"
"9.00000","8.97947","0.32042","0.28061","0.05340","0.32042","8.97947"
"9.20000","9.17945","0.35115","0.28686","0.05853","0.35115","9.17945"
"9.40000","9.37952","0.47887","0.29311","0.07981","0.47887","9.37952"
"9.60000","9.57948","0.39535","0.29936","0.06589","0.39535","9.57948"
"9.80000","9.77941","0.36756","0.30561","0.06126","0.36756","9.77941"
"10.00000","9.97949","0.42176","0.31186","0.07029","0.42176","9.97949"
"10.20000","10.17945","0.43553","0.31811","0.07259","0.43553","10.17945"
"10.40000","10.37958","0.43072","0.32436","0.07179","0.43072","10.37958"
"10.60000","10.57941","0.41430","0.33061","0.06905","0.41430","10.57941"
"10.80000","10.77952","0.45828","0.33686","0.07638","0.45828","10.77952"
"11.00000","10.97943","0.44852","0.34311","0.07475","0.44852","10.97943"
"11.20000","11.17951","0.50203","0.34936","0.08367","0.50203","11.17951"
"11.40000","11.37943","0.50613","0.35561","0.08435","0.50613","11.37943"
"11.60000","11.57949","0.45112","0.36186","0.07519","0.45112","11.57949"
"11.80000","11.77946","0.45498","0.36811","0.07583","0.45498","11.77946"
"12.00000","11.97948","0.48665","0.37436","0.08111","0.48665","11.97948"
"12.20000","12.17939","0.54925","0.38061","0.09154","0.54925","12.17939"
"12.40000","12.37950","0.57041","0.38686","0.09507","0.57041","12.37950"
"12.60000","12.57939","0.51042","0.39311","0.08507","0.51042","12.57939"
"12.80000","12.77952","0.53729","0.39936","0.08955","0.53729","12.77952"
"13.00000","12.97938","0.48519","0.40561","0.08086","0.48519","12.97938"
"13.20000","13.17950","0.52874","0.41186","0.08812","0.52874","13.17950"
"13.40000","13.37939","0.55141","0.41811","0.09190","0.55141","13.37939"
"13.60000","13.57947","0.51234","0.42436","0.08539","0.51234","13.57947"
"13.80000","13.77941","0.54522","0.43061","0.09087","0.54522","13.77941"
"14.00000","13.97950","0.51007","0.43686","0.08501","0.51007","13.97950"
"14.20000","14.17940","0.53890","0.44311","0.08982","0.53890","14.17940"
"14.40000","14.37949","0.53628","0.44936","0.08938","0.53628","14.37949"
"14.60000","14.57935","0.61255","0.45560","0.10209","0.61255","14.57935"
"14.80000","14.77953","0.57250","0.46186","0.09542","0.57250","14.77953"
"15.00000","14.97935","0.56194","0.46810","0.09366","0.56194","14.97935"
"15.20000","15.17950","0.60275","0.47436","0.10046","0.60275","15.17950"
"15.40000","15.37938","0.62622","0.48061","0.10437","0.62622","15.37938"
"15.60000","15.57950","0.60979","0.48686","0.10163","0.60979","15.57950"
"15.80000","15.77941","0.59538","0.49311","0.09923","0.59538","15.77941"
"16.00000","15.97947","0.59977","0.49936","0.09996","0.59977","15.97947"
"16.20000","16.17939","0.58982","0.50561","0.09830","0.58982","16.17939"
"16.40000","16.37949","0.69638","0.51186","0.11606","0.69638","16.37949"
"16.60000","16.57938","0.62606","0.51811","0.10434","0.62606","16.57938"
"16.80000","16.77951","0.70790","0.52436","0.11798","0.70790","16.77951"
"17.00000","16.97935","0.64181","0.53060","0.10697","0.64181","16.97935"
"17.20000","17.17954","0.60441","0.53686","0.10073","0.60441","17.17954"
"17.40000","17.37942","0.66196","0.54311","0.11033","0.66196","17.37942"
"17.60000","17.57955","0.66404","0.54936","0.11067","0.66404","17.57955"
"17.80000","17.77940","0.66388","0.55561","0.11065","0.66388","17.77940"
"18.00000","17.97950","0.71281","0.56186","0.11880","0.71281","17.97950"
"18.20000","18.17941","0.73531","0.56811","0.12255","0.73531","18.17941"
"18.40000","18.37952","0.73359","0.57436","0.12227","0.73359","18.37952"
"18.60000","18.57942","0.73659","0.58061","0.12277","0.73659","18.57942"
"18.80000","18.77955","0.74079","0.58686","0.12347","0.74079","18.77955"
"19.00000","18.97939","0.72273","0.59311","0.12046","0.72273","18.97939"
"19.20000","19.17955","0.74422","0.59936","0.12404","0.74422","19.17955"
"19.40000","19.37942","0.68928","0.60561","0.11488","0.68928","19.37942"
"19.60000","19.57958","0.79120","0.61186","0.13187","0.79120","19.57958"
"19.80000","19.77942","0.77813","0.61811","0.12969","0.77813","19.77942"
"20.00000","19.97960","0.73237","0.62436","0.12206","0.73237","19.97960"
"20.20000","20.17944","0.69809","0.63061","0.11635","0.69809","20.17944"
"20.40000","20.37956","0.75143","0.63686","0.12524","0.75143","20.37956"
"20.60000","20.57945","0.78472","0.64311","0.13079","0.78472","20.57945"
"20.80000","20.77957","0.73083","0.64936","0.12180","0.73083","20.77957"
"21.00000","20.97952","0.71285","0.65561","0.11881","0.71285","20.97952"
"21.20000","21.17963","0.75292","0.66186","0.12549","0.75292","21.17963"
"21.40000","21.37940","0.78441","0.66811","0.13073","0.78441","21.37940"
"21.60000","21.57961","0.84111","0.67436","0.14019","0.84111","21.57961"
"21.80000","21.77942","0.80536","0.68061","0.13423","0.80536","21.77942"
"22.00000","21.97962","0.78243","0.68686","0.13041","0.78243","21.97962"
"22.20000","22.17947","0.76683","0.69311","0.12781","0.76683","22.17947"
"22.40000","22.37963","0.82879","0.69936","0.13813","0.82879","22.37963"
"22.60000","22.57947","0.83263","0.70561","0.13877","0.83263","22.57947"
"22.80000","22.77962","0.87393","0.71186","0.14566","0.87393","22.77962"
"23.00000","22.97951","0.77344","0.71811","0.12891","0.77344","22.97951"
"23.20000","23.17955","0.84621","0.72436","0.14104","0.84621","23.17955"
"23.40000","23.37947","0.89289","0.73061","0.14881","0.89289","23.37947"
"23.60000","23.57972","0.88563","0.73687","0.14761","0.88563","23.57972"
"23.80000","23.77952","0.85318","0.74311","0.14220","0.85318","23.77952"
"24.00000","23.97967","0.84887","0.74936","0.14148","0.84887","23.97967"
"24.20000","24.17944","0.85026","0.75561","0.14171","0.85026","24.17944"
"24.40000","24.37967","0.89929","0.76186","0.14988","0.89929","24.37967"
"24.60000","24.57952","0.92209","0.76811","0.15368","0.92209","24.57952"
"24.80000","24.77964","0.90945","0.77436","0.15158","0.90945","24.77964"
"25.00000","24.97944","0.94938","0.78061","0.15823","0.94938","24.97944"
"25.20000","25.17961","0.88713","0.78686","0.14785","0.88713","25.17961"
"25.40000","25.37954","0.89798","0.79311","0.14966","0.89798","25.37954"
"25.60000","25.57963","0.97500","0.79936","0.16250","0.97500","25.57963"
"25.80000","25.77951","0.98214","0.80561","0.16369","0.98214","25.77951"
"26.00000","25.97970","0.91026","0.81187","0.15171","0.91026","25.97970"
"26.20000","26.17948","0.95146","0.81811","0.15858","0.95146","26.17948"
"26.40000","26.37967","0.95524","0.82436","0.15921","0.95524","26.37967"
"26.60000","26.57945","0.95385","0.83061","0.15897","0.95385","26.57945"
"26.80000","26.77963","1.00692","0.83686","0.16782","1.00692","26.77963"
"27.00000","26.97946","0.91068","0.84311","0.15178","0.91068","26.97946"
"27.20000","27.17966","1.01193","0.84936","0.16866","1.01193","27.17966"
"27.40000","27.37951","0.97095","0.85561","0.16182","0.97095","27.37951"
"27.60000","27.57958","0.99258","0.86186","0.16543","0.99258","27.57958"
"27.80000","27.77950","1.04835","0.86811","0.17473","1.04835","27.77950"
"28.00000","27.97960","1.01916","0.87436","0.16986","1.01916","27.97960"
"28.20000","28.17945","0.98660","0.88061","0.16443","0.98660","28.17945"
"28.40000","28.37967","1.05407","0.88686","0.17568","1.05407","28.37967"
"28.60000","28.57948","1.02749","0.89311","0.17125","1.02749","28.57948"
"28.80000","28.77971","1.05946","0.89937","0.17658","1.05946","28.77971"
"29.00000","28.97948","1.01960","0.90561","0.16993","1.01960","28.97948"
"29.20000","29.17963","1.06096","0.91186","0.17683","1.06096","29.17963"
"29.40000","29.37947","1.06335","0.91811","0.17722","1.06335","29.37947"
"29.60000","29.57961","1.01486","0.92436","0.16914","1.01486","29.57961"
"29.80000","29.77943","1.08594","0.93061","0.18099","1.08594","29.77943"
"30.00000","29.97957","1.10267","0.93686","0.18378","1.10267","29.97957"
"30.20000","30.17949","1.09850","0.94311","0.18308","1.09850","30.17949"
"30.40000","30.37960","1.09238","0.94936","0.18206","1.09238","30.37960"
"30.60000","30.57941","1.12524","0.95561","0.18754","1.12524","30.57941"
"30.80000","30.77963","1.14934","0.96186","0.19156","1.14934","30.77963"
"31.00000","30.97944","1.18149","0.96811","0.19692","1.18149","30.97944"
"31.20000","31.17959","1.16824","0.97436","0.19471","1.16824","31.17959"
"31.40000","31.37941","1.12141","0.98061","0.18690","1.12141","31.37941"
"31.60000","31.57958","1.20358","0.98686","0.20060","1.20358","31.57958"
"31.80000","31.77942","1.14224","0.99311","0.19037","1.14224","31.77942"
"32.00000","31.97957","1.18499","0.99936","0.19750","1.18499","31.97957"
"32.20000","32.17944","1.20209","1.00561","0.20035","1.20209","32.17944"
"32.40000","32.37954","1.22974","1.01186","0.20496","1.22974","32.37954"
"32.60000","32.57940","1.21224","1.01811","0.20204","1.21224","32.57940"
"32.80000","32.77959","1.24055","1.02436","0.20676","1.24055","32.77959"
"33.00000","32.97936","1.27053","1.03061","0.21175","1.27053","32.97936"
"33.20000","33.17958","1.24040","1.03686","0.20673","1.24040","33.17958"
"33.40000","33.37939","1.23179","1.04311","0.20530","1.23179","33.37939"
"33.60000","33.57955","1.20955","1.04936","0.20159","1.20955","33.57955"
"33.80000","33.77939","1.25513","1.05561","0.20919","1.25513","33.77939"
"34.00000","33.97948","1.23323","1.06186","0.20554","1.23323","33.97948"
"34.20000","34.17941","1.26504","1.06811","0.21084","1.26504","34.17941"
"34.40000","34.37952","1.20317","1.07436","0.20053","1.20317","34.37952"
"34.60000","34.57940","1.26804","1.08061","0.21134","1.26804","34.57940"
"34.80000","34.77947","1.26446","1.08686","0.21074","1.26446","34.77947"
"35.00000","34.97937","1.28003","1.09311","0.21334","1.28003","34.97937"
"35.20000","35.17952","1.27195","1.09936","0.21199","1.27195","35.17952"
"35.40000","35.37934","1.35014","1.10560","0.22502","1.35014","35.37934"
"35.60000","35.57953","1.31103","1.11186","0.21850","1.31103","35.57953"
"35.80000","35.77939","1.31338","1.11811","0.21890","1.31338","35.77939"
"36.00000","35.97948","1.34232","1.12436","0.22372","1.34232","35.97948"
"36.20000","36.17935","1.40541","1.13060","0.23423","1.40541","36.17935"
"36.40000","36.37951","1.37493","1.13686","0.22916","1.37493","36.37951"
"36.60000","36.57936","1.35170","1.14311","0.22528","1.35170","36.57936"
"36.80000","36.77948","1.32670","1.14936","0.22112","1.32670","36.77948"
"37.00000","36.97937","1.36221","1.15561","0.22703","1.36221","36.97937"
"37.20000","37.17953","1.41391","1.16186","0.23565","1.41391","37.17953"
"37.40000","37.37932","1.41498","1.16810","0.23583","1.41498","37.37932"
"37.60000","37.57948","1.41607","1.17436","0.23601","1.41607","37.57948"
"37.80000","37.77937","1.46553","1.18061","0.24425","1.46553","37.77937"
"38.00000","37.97953","1.45373","1.18686","0.24229","1.45373","37.97953"
"38.20000","38.17935","1.52438","1.19310","0.25406","1.52438","38.17935"
"38.40000","38.37945","1.51591","1.19936","0.25265","1.51591","38.37945"
"38.60000","38.57941","1.43308","1.20561","0.23885","1.43308","38.57941"
"38.80000","38.77950","1.42656","1.21186","0.23776","1.42656","38.77950"
"39.00000","38.97940","1.47688","1.21811","0.24615","1.47688","38.97940"
"39.20000","39.17953","1.50111","1.22436","0.25019","1.50111","39.17953"
"39.40000","39.37938","1.54006","1.23061","0.25668","1.54006","39.37938"
"39.60000","39.57951","1.48041","1.23686","0.24673","1.48041","39.57951"
"39.80000","39.77937","1.44753","1.24311","0.24126","1.44753","39.77937"
"40.00000","39.97954","1.50393","1.24936","0.25066","1.50393","39.97954"
"40.20000","40.17937","1.55299","1.25561","0.25883","1.55299","40.17937"
"40.40000","40.37951","1.52115","1.26186","0.25353","1.52115","40.37951"
"40.60000","40.57943","1.53580","1.26811","0.25597","1.53580","40.57943"
"40.80000","40.77951","1.60282","1.27436","0.26714","1.60282","40.77951"
"41.00000","40.97946","1.57533","1.28061","0.26256","1.57533","40.97946"
"41.20000","41.17951","1.56964","1.28686","0.26161","1.56964","41.17951"
"41.40000","41.37944","1.55609","1.29311","0.25935","1.55609","41.37944"
"41.60000","41.57953","1.62585","1.29936","0.27098","1.62585","41.57953"
"41.80000","41.77940","1.61692","1.30561","0.26949","1.61692","41.77940"
"42.00000","41.97952","1.63460","1.31186","0.27243","1.63460","41.97952"
"42.20000","42.17944","1.67002","1.31811","0.27834","1.67002","42.17944"
"42.40000","42.37954","1.65589","1.32436","0.27598","1.65589","42.37954"
"42.60000","42.57945","1.60472","1.33061","0.26745","1.60472","42.57945"
"42.80000","42.77955","1.74490","1.33686","0.29082","1.74490","42.77955"
"43.00000","42.97944","1.70478","1.34311","0.28413","1.70478","42.97944"
"43.20000","43.17951","1.71263","1.34936","0.28544","1.71263","43.17951"
"43.40000","43.37952","1.80659","1.35561","0.30110","1.80659","43.37952"
"43.60000","43.57957","1.78322","1.36186","0.29720","1.78322","43.57957"
"43.80000","43.77949","1.72499","1.36811","0.28750","1.72499","43.77949"
"44.00000","43.97958","1.68371","1.37436","0.28062","1.68371","43.97958"
"44.20000","44.17950","1.73775","1.38061","0.28962","1.73775","44.17950"
"44.40000","44.37957","1.71990","1.38686","0.28665","1.71990","44.37957"
"44.60000","44.57944","1.76958","1.39311","0.29493","1.76958","44.57944"
"44.80000","44.77955","1.76335","1.39936","0.29389","1.76335","44.77955"
"45.00000","44.97951","1.75220","1.40561","0.29203","1.75220","44.97951"
"45.20000","45.17955","1.82399","1.41186","0.30400","1.82399","45.17955"
"45.40000","45.37953","1.76652","1.41811","0.29442","1.76652","45.37953"
"45.60000","45.57954","1.84748","1.42436","0.30791","1.84748","45.57954"
"45.80000","45.77957","1.89939","1.43061","0.31657","1.89939","45.77957"
"46.00000","45.97958","1.85498","1.43686","0.30916","1.85498","45.97958"
"46.20000","46.17954","1.85891","1.44311","0.30982","1.85891","46.17954"
"46.40000","46.37959","1.86009","1.44936","0.31001","1.86009","46.37959"
"46.60000","46.57952","1.87570","1.45561","0.31262","1.87570","46.57952"
"46.80000","46.77948","1.80816","1.46186","0.30136","1.80816","46.77948"
"47.00000","46.97955","1.94221","1.46811","0.32370","1.94221","46.97955"
"47.20000","47.17960","1.92357","1.47436","0.32060","1.92357","47.17960"
"47.40000","47.37955","1.93321","1.48061","0.32220","1.93321","47.37955"
"47.60000","47.57957","1.96397","1.48686","0.32733","1.96397","47.57957"
"47.80000","47.77958","1.96800","1.49311","0.32800","1.96800","47.77958"
"48.00000","47.97950","1.95215","1.49936","0.32536","1.95215","47.97950"
"48.20000","48.17956","1.96988","1.50561","0.32831","1.96988","48.17956"
"48.40000","48.37955","1.98976","1.51186","0.33163","1.98976","48.37955"
"48.60000","48.57957","1.98500","1.51811","0.33083","1.98500","48.57957"
"48.80000","48.77957","1.96307","1.52436","0.32718","1.96307","48.77957"
"49.00000","48.97955","1.99165","1.53061","0.33194","1.99165","48.97955"
"49.20000","49.17960","2.03914","1.53686","0.33986","2.03914","49.17960"
"49.40000","49.37955","2.02307","1.54311","0.33718","2.02307","49.37955"
"49.60000","49.57954","2.04032","1.54936","0.34005","2.04032","49.57954"
"49.80000","49.77960","2.08343","1.55561","0.34724","2.08343","49.77960"
"50.00000","49.97954","2.09195","1.56186","0.34866","2.09195","49.97954"
"50.20000","50.17956","2.15970","1.56811","0.35995","2.15970","50.17956"
"50.40000","50.37949","2.14352","1.57436","0.35725","2.14352","50.37949"
"50.60000","50.57957","2.09876","1.58061","0.34979","2.09876","50.57957"
"50.80000","50.77957","2.13862","1.58686","0.35644","2.13862","50.77957"
"51.00000","50.97955","2.15040","1.59311","0.35840","2.15040","50.97955"
"51.20000","51.17956","2.20101","1.59936","0.36684","2.20101","51.17956"
"51.40000","51.37953","2.16241","1.60561","0.36040","2.16241","51.37953"
"51.60000","51.57956","2.12901","1.61186","0.35483","2.12901","51.57956"
"51.80000","51.77954","2.17550","1.61811","0.36258","2.17550","51.77954"
"52.00000","51.97945","2.16842","1.62436","0.36140","2.16842","51.97945"
"52.20000","52.17962","2.20951","1.63061","0.36825","2.20951","52.17962"
"52.40000","52.37951","2.21926","1.63686","0.36988","2.21926","52.37951"
"52.60000","52.57957","2.22657","1.64311","0.37109","2.22657","52.57957"
"52.80000","52.77949","2.17340","1.64936","0.36223","2.17340","52.77949"
"53.00000","52.97958","2.23404","1.65561","0.37234","2.23404","52.97958"
"53.20000","53.17947","2.31073","1.66186","0.38512","2.31073","53.17947"
"53.40000","53.37957","2.35375","1.66811","0.39229","2.35375","53.37957"
"53.60000","53.57949","2.29120","1.67436","0.38187","2.29120","53.57949"
"53.80000","53.77950","2.31929","1.68061","0.38655","2.31929","53.77950"
"54.00000","53.97955","2.37544","1.68686","0.39591","2.37544","53.97955"
"54.20000","54.17955","2.39070","1.69311","0.39845","2.39070","54.17955"
"54.40000","54.37938","2.35182","1.69936","0.39197","2.35182","54.37938"
"54.60000","54.57954","2.36198","1.70561","0.39366","2.36198","54.57954"
"54.80000","54.77946","2.33638","1.71186","0.38940","2.33638","54.77946"
"55.00000","54.97955","2.38668","1.71811","0.39778","2.38668","54.97955"
"55.20000","55.17940","2.39838","1.72436","0.39973","2.39838","55.17940"
"55.40000","55.37951","2.36983","1.73061","0.39497","2.36983","55.37951"
"55.60000","55.57948","2.38314","1.73686","0.39719","2.38314","55.57948"
"55.80000","55.77953","2.41075","1.74311","0.40179","2.41075","55.77953"
"56.00000","55.97947","2.45830","1.74936","0.40972","2.45830","55.97947"
"56.20000","56.17947","2.52725","1.75561","0.42121","2.52725","56.17947"
"56.40000","56.37946","2.54454","1.76186","0.42409","2.54454","56.37946"
"56.60000","56.57950","2.45734","1.76811","0.40956","2.45734","56.57950"
"56.80000","56.77938","2.53046","1.77436","0.42174","2.53046","56.77938"
"57.00000","56.97951","2.55495","1.78061","0.42583","2.55495","56.97951"
"57.20000","57.17941","2.52486","1.78686","0.42081","2.52486","57.17941"
"57.40000","57.37948","2.53123","1.79311","0.42187","2.53123","57.37948"
"57.60000","57.57939","2.52275","1.79936","0.42046","2.52275","57.57939"
"57.80000","57.77950","2.53345","1.80561","0.42224","2.53345","57.77950"
"58.00000","57.97939","2.62525","1.81186","0.43754","2.62525","57.97939"
"58.20000","58.17946","2.57846","1.81811","0.42974","2.57846","58.17946"
"58.40000","58.37942","2.61839","1.82436","0.43640","2.61839","58.37942"
"58.60000","58.57948","2.61441","1.83061","0.43574","2.61441","58.57948"
"58.80000","58.77938","2.62752","1.83686","0.43792","2.62752","58.77938"
"59.00000","58.97952","2.64089","1.84311","0.44015","2.64089","58.97952"
"59.20000","59.17932","2.74248","1.84935","0.45708","2.74248","59.17932"
"59.40000","59.37955","2.68374","1.85561","0.44729","2.68374","59.37955"
"59.60000","59.57935","2.65651","1.86185","0.44275","2.65651","59.57935"
"59.80000","59.77949","2.69516","1.86811","0.44919","2.69516","59.77949"
"60.00000","59.97934","2.76977","1.87435","0.46163","2.76977","59.97934"
"60.20000","60.17949","2.74357","1.88061","0.45726","2.74357","60.17949"
"60.40000","60.37939","2.79729","1.88686","0.46621","2.79729","60.37939"
"60.60000","60.57947","2.71987","1.89311","0.45331","2.71987","60.57947"
"60.80000","60.77941","2.76635","1.89936","0.46106","2.76635","60.77941"
"61.00000","60.97952","2.79305","1.90561","0.46551","2.79305","60.97952"
"61.20000","61.17940","2.82579","1.91186","0.47096","2.82579","61.17940"
"61.40000","61.37951","2.78396","1.91811","0.46399","2.78396","61.37951"
"61.60000","61.57932","2.84999","1.92435","0.47500","2.84999","61.57932"
"61.80000","61.77956","2.86381","1.93061","0.47730","2.86381","61.77956"
"62.00000","61.97937","2.92253","1.93686","0.48709","2.92253","61.97937"
"62.20000","62.17949","2.87740","1.94311","0.47957","2.87740","62.17949"
"62.40000","62.37940","2.86147","1.94936","0.47691","2.86147","62.37940"
"62.60000","62.57951","2.96273","1.95561","0.49379","2.96273","62.57951"
"62.80000","62.77940","2.93546","1.96186","0.48924","2.93546","62.77940"
"63.00000","62.97956","2.96933","1.96811","0.49489","2.96933","62.97956"
"63.20000","63.17942","2.91428","1.97436","0.48571","2.91428","63.17942"
"63.40000","63.37959","2.92759","1.98061","0.48793","2.92759","63.37959"
"63.60000","63.57939","3.01714","1.98686","0.50286","3.01714","63.57939"
"63.80000","63.77950","2.99508","1.99311","0.49918","2.99508","63.77950"
"64.00000","63.97940","2.98479","1.99936","0.49746","2.98479","63.97940"
"64.20000","64.17958","3.05014","2.00561","0.50836","3.05014","64.17958"
"64.40000","64.37939","3.07526","2.01186","0.51254","3.07526","64.37939"
"64.60000","64.57956","3.02398","2.01811","0.50400","3.02398","64.57956"
"64.80000","64.77945","3.10718","2.02436","0.51786","3.10718","64.77945"
"65.00000","64.97957","3.08336","2.03061","0.51389","3.08336","64.97957"
"65.20000","65.17944","3.16721","2.03686","0.52787","3.16721","65.17944"
"65.40000","65.37959","3.16400","2.04311","0.52733","3.16400","65.37959"
"65.60000","65.57940","3.18184","2.04936","0.53031","3.18184","65.57940"
"65.80000","65.77961","3.11745","2.05561","0.51958","3.11745","65.77961"
"66.00000","65.97943","3.23090","2.06186","0.53848","3.23090","65.97943"
"66.20000","66.17963","3.13796","2.06811","0.52299","3.13796","66.17963"
"66.40000","66.37944","3.14458","2.07436","0.52410","3.14458","66.37944"
"66.60000","66.57961","3.12136","2.08061","0.52023","3.12136","66.57961"
"66.80000","66.77945","3.27441","2.08686","0.54573","3.27441","66.77945"
"67.00000","66.97963","3.28962","2.09311","0.54827","3.28962","66.97963"
"67.20000","67.17951","3.24354","2.09936","0.54059","3.24354","67.17951"
"67.40000","67.37959","3.29765","2.10561","0.54961","3.29765","67.37959"
"67.60000","67.57951","3.29707","2.11186","0.54951","3.29707","67.57951"
"67.80000","67.77965","3.36370","2.11811","0.56062","3.36370","67.77965"
"68.00000","67.97944","3.32956","2.12436","0.55493","3.32956","67.97944"
"68.20000","68.17963","3.38752","2.13061","0.56459","3.38752","68.17963"
"68.40000","68.37947","3.34300","2.13686","0.55717","3.34300","68.37947"
"68.60000","68.57964","3.41364","2.14311","0.56894","3.41364","68.57964"
"68.80000","68.77946","3.42380","2.14936","0.57063","3.42380","68.77946"
"69.00000","68.97965","3.39315","2.15561","0.56553","3.39315","68.97965"
"69.20000","69.17947","3.46109","2.16186","0.57685","3.46109","69.17947"
"69.40000","69.37962","3.38161","2.16811","0.56360","3.38161","69.37962"
"69.60000","69.57951","3.44919","2.17436","0.57487","3.44919","69.57951"
"69.80000","69.77966","3.49774","2.18061","0.58296","3.49774","69.77966"
"70.00000","69.97948","3.45599","2.18686","0.57600","3.45599","69.97948"
"70.20000","70.17968","3.42979","2.19311","0.57163","3.42979","70.17968"
"70.40000","70.37944","3.53560","2.19936","0.58927","3.53560","70.37944"
"70.60000","70.57967","3.48123","2.20561","0.58020","3.48123","70.57967"
"70.80000","70.77946","3.57599","2.21186","0.59600","3.57599","70.77946"
"71.00000","70.97971","3.53484","2.21812","0.58914","3.53484","70.97971"
"71.20000","71.17952","3.55310","2.22436","0.59218","3.55310","71.17952"
"71.40000","71.37962","3.60323","2.23061","0.60054","3.60323","71.37962"
"71.60000","71.57947","3.60475","2.23686","0.60079","3.60475","71.57947"
"71.80000","71.77962","3.63468","2.24311","0.60578","3.63468","71.77962"
"72.00000","71.97952","3.62248","2.24936","0.60375","3.62248","71.97952"
"72.20000","72.17960","3.72372","2.25561","0.62062","3.72372","72.17960"
"72.40000","72.37947","3.56702","2.26186","0.59450","3.56702","72.37947"
"72.60000","72.57969","0.14631","2.26812","0.02439","0.14631","72.57969"
"72.80000","72.77947","0.20727","2.27436","0.03454","0.20727","72.77947"
"73.00000","72.97967","0.16392","2.28061","0.02732","0.16392","72.97967"
"73.20000","73.17945","0.25411","2.28686","0.04235","0.25411","73.17945"
"73.40000","73.37964","0.16767","2.29311","0.02794","0.16767","73.37964"
"73.60000","73.57951","0.19386","2.29936","0.03231","0.19386","73.57951"
"73.80000","73.77962","0.21881","2.30561","0.03647","0.21881","73.77962"
"74.00000","73.97948","0.18024","2.31186","0.03004","0.18024","73.97948"
"74.03400","74.01347","0.23566","2.31292","0.03928","0.23566","74.01347"