File: 1silicon5.csv
Tenacity at Break (Standard),"0.22267",N/tex
Tensile extension at Break (Standard),"70.45257",mm
Tenacity at Yield ,,N/tex

Time,Extension,Load,Tensile strain (Extension),Tensile stress,Tenacity,Tensile extension
(s),(mm),(N),(mm/mm),(MPa),(N/tex),(mm)
"0.00000","0.00000","0.00520","0.00000","0.00072","0.00520","0.00000"
"0.20000","0.17923","0.00353","0.00560","0.00049","0.00353","0.17923"
"0.40000","0.37948","0.04744","0.01186","0.00659","0.04744","0.37948"
"0.60000","0.57964","0.02369","0.01811","0.00329","0.02369","0.57964"
"0.80000","0.77945","0.09413","0.02436","0.01307","0.09413","0.77945"
"1.00000","0.97963","0.06469","0.03061","0.00898","0.06469","0.97963"
"1.20000","1.17949","0.16087","0.03686","0.02234","0.16087","1.17949"
"1.40000","1.37956","0.15821","0.04311","0.02197","0.15821","1.37956"
"1.60000","1.57954","0.17936","0.04936","0.02491","0.17936","1.57954"
"1.80000","1.77959","0.20466","0.05561","0.02842","0.20466","1.77959"
"2.00000","1.97944","0.24025","0.06186","0.03337","0.24025","1.97944"
"2.20000","2.17967","0.15961","0.06811","0.02217","0.15961","2.17967"
"2.40000","2.37946","0.21140","0.07436","0.02936","0.21140","2.37946"
"2.60000","2.57966","0.18580","0.08061","0.02581","0.18580","2.57966"
"2.80000","2.77946","0.25945","0.08686","0.03603","0.25945","2.77946"
"3.00000","2.97961","0.27414","0.09311","0.03808","0.27414","2.97961"
"3.20000","3.17950","0.29663","0.09936","0.04120","0.29663","3.17950"
"3.40000","3.37970","0.35358","0.10562","0.04911","0.35358","3.37970"
"3.60000","3.57949","0.37082","0.11186","0.05150","0.37082","3.57949"
"3.80000","3.77957","0.37248","0.11811","0.05173","0.37248","3.77957"
"4.00000","3.97954","0.35010","0.12436","0.04863","0.35010","3.97954"
"4.20000","4.17964","0.40816","0.13061","0.05669","0.40816","4.17964"
"4.40000","4.37944","0.34128","0.13686","0.04740","0.34128","4.37944"
"4.60000","4.57966","0.50256","0.14311","0.06980","0.50256","4.57966"
"4.80000","4.77946","0.45284","0.14936","0.06289","0.45284","4.77946"
"5.00000","4.97968","0.41372","0.15561","0.05746","0.41372","4.97968"
"5.20000","5.17947","0.48312","0.16186","0.06710","0.48312","5.17947"
"5.40000","5.37963","0.47965","0.16811","0.06662","0.47965","5.37963"
"5.60000","5.57951","0.49210","0.17436","0.06835","0.49210","5.57951"
"5.80000","5.77964","0.53340","0.18061","0.07408","0.53340","5.77964"
"6.00000","5.97950","0.49375","0.18686","0.06858","0.49375","5.97950"
"6.20000","6.17961","0.51750","0.19311","0.07188","0.51750","6.17961"
"6.40000","6.37948","0.48185","0.19936","0.06692","0.48185","6.37948"
"6.60000","6.57966","0.52727","0.20561","0.07323","0.52727","6.57966"
"6.80000","6.77945","0.54287","0.21186","0.07540","0.54287","6.77945"
"7.00000","6.97964","0.62998","0.21811","0.08750","0.62998","6.97964"
"7.20000","7.17942","0.59470","0.22436","0.08260","0.59470","7.17942"
"7.40000","7.37959","0.62257","0.23061","0.08647","0.62257","7.37959"
"7.60000","7.57946","0.58212","0.23686","0.08085","0.58212","7.57946"
"7.80000","7.77958","0.57374","0.24311","0.07969","0.57374","7.77958"
"8.00000","7.97949","0.72290","0.24936","0.10040","0.72290","7.97949"
"8.20000","8.17961","0.66603","0.25561","0.09250","0.66603","8.17961"
"8.40000","8.37948","0.63627","0.26186","0.08837","0.63627","8.37948"
"8.60000","8.57957","0.74989","0.26811","0.10415","0.74989","8.57957"
"8.80000","8.77944","0.71253","0.27436","0.09896","0.71253","8.77944"
"9.00000","8.97963","0.71781","0.28061","0.09970","0.71781","8.97963"
"9.20000","9.17941","0.73783","0.28686","0.10248","0.73783","9.17941"
"9.40000","9.37963","0.74347","0.29311","0.10326","0.74347","9.37963"
"9.60000","9.57942","0.68140","0.29936","0.09464","0.68140","9.57942"
"9.80000","9.77954","0.77362","0.30561","0.10745","0.77362","9.77954"
"10.00000","9.97943","0.82832","0.31186","0.11505","0.82832","9.97943"
"10.20000","10.17961","0.81492","0.31811","0.11318","0.81492","10.17961"
"10.40000","10.37944","0.84766","0.32436","0.11773","0.84766","10.37944"
"10.60000","10.57953","0.85601","0.33061","0.11889","0.85601","10.57953"
"10.80000","10.77940","0.86782","0.33686","0.12053","0.86782","10.77940"
"11.00000","10.97959","0.87933","0.34311","0.12213","0.87933","10.97959"
"11.20000","11.17941","0.87750","0.34936","0.12187","0.87750","11.17941"
"11.40000","11.37959","0.92774","0.35561","0.12885","0.92774","11.37959"
"11.60000","11.57936","0.92480","0.36185","0.12844","0.92480","11.57936"
"11.80000","11.77955","0.91579","0.36811","0.12719","0.91579","11.77955"
"12.00000","11.97938","1.00758","0.37436","0.13994","1.00758","11.97938"
"12.20000","12.17952","1.00495","0.38061","0.13958","1.00495","12.17952"
"12.40000","12.37942","0.96591","0.38686","0.13415","0.96591","12.37942"
"12.60000","12.57954","0.92984","0.39311","0.12914","0.92984","12.57954"
"12.80000","12.77942","0.96945","0.39936","0.13465","0.96945","12.77942"
"13.00000","12.97954","1.02337","0.40561","0.14213","1.02337","12.97954"
"13.20000","13.17939","0.96936","0.41186","0.13463","0.96936","13.17939"
"13.40000","13.37953","1.05872","0.41811","0.14704","1.05872","13.37953"
"13.60000","13.57933","1.04865","0.42435","0.14565","1.04865","13.57933"
"13.80000","13.77951","1.00849","0.43061","0.14007","1.00849","13.77951"
"14.00000","13.97939","1.03298","0.43686","0.14347","1.03298","13.97939"
"14.20000","14.17952","1.05778","0.44311","0.14691","1.05778","14.17952"
"14.40000","14.37939","1.04835","0.44936","0.14560","1.04835","14.37939"
"14.60000","14.57950","1.08593","0.45561","0.15082","1.08593","14.57950"
"14.80000","14.77942","1.13475","0.46186","0.15760","1.13475","14.77942"
"15.00000","14.97951","1.14014","0.46811","0.15835","1.14014","14.97951"
"15.20000","15.17941","1.14432","0.47436","0.15893","1.14432","15.17941"
"15.40000","15.37949","1.13542","0.48061","0.15770","1.13542","15.37949"
"15.60000","15.57934","1.22583","0.48685","0.17025","1.22583","15.57934"
"15.80000","15.77952","1.14944","0.49311","0.15964","1.14944","15.77952"
"16.00000","15.97936","1.23130","0.49935","0.17101","1.23130","15.97936"
"16.20000","16.17950","1.25289","0.50561","0.17401","1.25289","16.17950"
"16.40000","16.37937","1.19388","0.51186","0.16582","1.19388","16.37937"
"16.60000","16.57950","1.24518","0.51811","0.17294","1.24518","16.57950"
"16.80000","16.77940","1.22706","0.52436","0.17043","1.22706","16.77940"
"17.00000","16.97944","1.29642","0.53061","0.18006","1.29642","16.97944"
"17.20000","17.17939","1.28822","0.53686","0.17892","1.28822","17.17939"
"17.40000","17.37951","1.29106","0.54311","0.17931","1.29106","17.37951"
"17.60000","17.57939","1.25744","0.54936","0.17464","1.25744","17.57939"
"17.80000","17.77951","1.35494","0.55561","0.18819","1.35494","17.77951"
"18.00000","17.97938","1.27772","0.56186","0.17746","1.27772","17.97938"
"18.20000","18.17953","1.34523","0.56811","0.18684","1.34523","18.17953"
"18.40000","18.37938","1.38849","0.57436","0.19285","1.38849","18.37938"
"18.60000","18.57952","1.37035","0.58061","0.19033","1.37035","18.57952"
"18.80000","18.77940","1.48687","0.58686","0.20651","1.48687","18.77940"
"19.00000","18.97949","1.38317","0.59311","0.19211","1.38317","18.97949"
"19.20000","19.17943","1.41566","0.59936","0.19662","1.41566","19.17943"
"19.40000","19.37948","1.48287","0.60561","0.20595","1.48287","19.37948"
"19.60000","19.57943","1.44701","0.61186","0.20097","1.44701","19.57943"
"19.80000","19.77954","1.49968","0.61811","0.20829","1.49968","19.77954"
"20.00000","19.97935","1.55930","0.62435","0.21657","1.55930","19.97935"
"20.20000","20.17956","1.46027","0.63061","0.20282","1.46027","20.17956"
"20.40000","20.37946","1.61973","0.63686","0.22496","1.61973","20.37946"
"20.60000","20.57953","1.53844","0.64311","0.21367","1.53844","20.57953"
"20.80000","20.77944","1.55602","0.64936","0.21611","1.55602","20.77944"
"21.00000","20.97958","1.53176","0.65561","0.21274","1.53176","20.97958"
"21.20000","21.17952","1.62557","0.66186","0.22577","1.62557","21.17952"
"21.40000","21.37953","1.61864","0.66811","0.22481","1.61864","21.37953"
"21.60000","21.57949","1.66127","0.67436","0.23073","1.66127","21.57949"
"21.80000","21.77949","1.59861","0.68061","0.22203","1.59861","21.77949"
"22.00000","21.97947","1.67580","0.68686","0.23275","1.67580","21.97947"
"22.20000","22.17954","1.70820","0.69311","0.23725","1.70820","22.17954"
"22.40000","22.37949","1.75764","0.69936","0.24412","1.75764","22.37949"
"22.60000","22.57956","1.69389","0.70561","0.23526","1.69389","22.57956"
"22.80000","22.77949","1.77677","0.71186","0.24677","1.77677","22.77949"
"23.00000","22.97962","1.76949","0.71811","0.24576","1.76949","22.97962"
"23.20000","23.17950","1.76438","0.72436","0.24505","1.76438","23.17950"
"23.40000","23.37955","1.75058","0.73061","0.24314","1.75058","23.37955"
"23.60000","23.57953","1.78250","0.73686","0.24757","1.78250","23.57953"
"23.80000","23.77956","1.84320","0.74311","0.25600","1.84320","23.77956"
"24.00000","23.97955","1.91285","0.74936","0.26567","1.91285","23.97955"
"24.20000","24.17953","1.82153","0.75561","0.25299","1.82153","24.17953"
"24.40000","24.37951","1.91627","0.76186","0.26615","1.91627","24.37951"
"24.60000","24.57955","1.92978","0.76811","0.26802","1.92978","24.57955"
"24.80000","24.77955","1.86721","0.77436","0.25933","1.86721","24.77955"
"25.00000","24.97957","1.94257","0.78061","0.26980","1.94257","24.97957"
"25.20000","25.17951","1.95705","0.78686","0.27181","1.95705","25.17951"
"25.40000","25.37962","2.02228","0.79311","0.28087","2.02228","25.37962"
"25.60000","25.57952","1.97888","0.79936","0.27484","1.97888","25.57952"
"25.80000","25.77953","1.96154","0.80561","0.27244","1.96154","25.77953"
"26.00000","25.97962","2.11767","0.81186","0.29412","2.11767","25.97962"
"26.20000","26.17959","2.01548","0.81811","0.27993","2.01548","26.17959"
"26.40000","26.37955","2.05609","0.82436","0.28557","2.05609","26.37955"
"26.60000","26.57954","2.04098","0.83061","0.28347","2.04098","26.57954"
"26.80000","26.77955","2.11429","0.83686","0.29365","2.11429","26.77955"
"27.00000","26.97955","2.14596","0.84311","0.29805","2.14596","26.97955"
"27.20000","27.17957","2.21144","0.84936","0.30714","2.21144","27.17957"
"27.40000","27.37962","2.17977","0.85561","0.30275","2.17977","27.37962"
"27.60000","27.57948","2.21553","0.86186","0.30771","2.21553","27.57948"
"27.80000","27.77958","2.21785","0.86811","0.30803","2.21785","27.77958"
"28.00000","27.97954","2.22507","0.87436","0.30904","2.22507","27.97954"
"28.20000","28.17953","2.26153","0.88061","0.31410","2.26153","28.17953"
"28.40000","28.37958","2.31290","0.88686","0.32124","2.31290","28.37958"
"28.60000","28.57953","2.32012","0.89311","0.32224","2.32012","28.57953"
"28.80000","28.77951","2.39435","0.89936","0.33255","2.39435","28.77951"
"29.00000","28.97952","2.33170","0.90561","0.32385","2.33170","28.97952"
"29.20000","29.17957","2.35383","0.91186","0.32692","2.35383","29.17957"
"29.40000","29.37955","2.43353","0.91811","0.33799","2.43353","29.37955"
"29.60000","29.57957","2.40954","0.92436","0.33466","2.40954","29.57957"
"29.80000","29.77955","2.44513","0.93061","0.33960","2.44513","29.77955"
"30.00000","29.97952","2.49457","0.93686","0.34647","2.49457","29.97952"
"30.20000","30.17956","2.50293","0.94311","0.34763","2.50293","30.17956"
"30.40000","30.37954","2.50463","0.94936","0.34787","2.50463","30.37954"
"30.60000","30.57943","2.50726","0.95561","0.34823","2.50726","30.57943"
"30.80000","30.77957","2.48669","0.96186","0.34537","2.48669","30.77957"
"31.00000","30.97950","2.55557","0.96811","0.35494","2.55557","30.97950"
"31.20000","31.17953","2.52216","0.97436","0.35030","2.52216","31.17953"
"31.40000","31.37946","2.55200","0.98061","0.35444","2.55200","31.37946"
"31.60000","31.57955","2.69108","0.98686","0.37376","2.69108","31.57955"
"31.80000","31.77950","2.57733","0.99311","0.35796","2.57733","31.77950"
"32.00000","31.97951","2.69439","0.99936","0.37422","2.69439","31.97951"
"32.20000","32.17947","2.69442","1.00561","0.37423","2.69442","32.17947"
"32.40000","32.37949","2.66372","1.01186","0.36996","2.66372","32.37949"
"32.60000","32.57949","2.70506","1.01811","0.37570","2.70506","32.57949"
"32.80000","32.77955","2.70446","1.02436","0.37562","2.70446","32.77955"
"33.00000","32.97943","2.74862","1.03061","0.38175","2.74862","32.97943"
"33.20000","33.17956","2.79273","1.03686","0.38788","2.79273","33.17956"
"33.40000","33.37943","2.82937","1.04311","0.39297","2.82937","33.37943"
"33.60000","33.57948","2.79726","1.04936","0.38851","2.79726","33.57948"
"33.80000","33.77942","2.83566","1.05561","0.39384","2.83566","33.77942"
"34.00000","33.97950","2.86445","1.06186","0.39784","2.86445","33.97950"
"34.20000","34.17944","2.85060","1.06811","0.39592","2.85060","34.17944"
"34.40000","34.37951","2.85014","1.07436","0.39585","2.85014","34.37951"
"34.60000","34.57944","2.87019","1.08061","0.39864","2.87019","34.57944"
"34.80000","34.77949","3.02877","1.08686","0.42066","3.02877","34.77949"
"35.00000","34.97943","2.97044","1.09311","0.41256","2.97044","34.97943"
"35.20000","35.17952","3.03925","1.09936","0.42212","3.03925","35.17952"
"35.40000","35.37936","2.99714","1.10561","0.41627","2.99714","35.37936"
"35.60000","35.57950","2.97575","1.11186","0.41330","2.97575","35.57950"
"35.80000","35.77937","3.08827","1.11811","0.42893","3.08827","35.77937"
"36.00000","35.97948","3.01863","1.12436","0.41925","3.01863","35.97948"
"36.20000","36.17942","3.10843","1.13061","0.43173","3.10843","36.17942"
"36.40000","36.37951","3.13029","1.13686","0.43476","3.13029","36.37951"
"36.60000","36.57945","3.21891","1.14311","0.44707","3.21891","36.57945"
"36.80000","36.77949","3.20388","1.14936","0.44498","3.20388","36.77949"
"37.00000","36.97929","3.18759","1.15560","0.44272","3.18759","36.97929"
"37.20000","37.17954","3.22999","1.16186","0.44861","3.22999","37.17954"
"37.40000","37.37939","3.21275","1.16811","0.44621","3.21275","37.37939"
"37.60000","37.57950","3.23471","1.17436","0.44927","3.23471","37.57950"
"37.80000","37.77934","3.28624","1.18060","0.45642","3.28624","37.77934"
"38.00000","37.97953","3.27066","1.18686","0.45426","3.27066","37.97953"
"38.20000","38.17937","3.34656","1.19311","0.46480","3.34656","38.17937"
"38.40000","38.37949","3.30717","1.19936","0.45933","3.30717","38.37949"
"38.60000","38.57939","3.34584","1.20561","0.46470","3.34584","38.57939"
"38.80000","38.77950","3.44231","1.21186","0.47810","3.44231","38.77950"
"39.00000","38.97940","3.40914","1.21811","0.47349","3.40914","38.97940"
"39.20000","39.17953","3.46662","1.22436","0.48147","3.46662","39.17953"
"39.40000","39.37936","3.44153","1.23061","0.47799","3.44153","39.37936"
"39.60000","39.57952","3.49957","1.23686","0.48605","3.49957","39.57952"
"39.80000","39.77936","3.49075","1.24311","0.48483","3.49075","39.77936"
"40.00000","39.97950","3.50919","1.24936","0.48739","3.50919","39.97950"
"40.20000","40.17943","3.54672","1.25561","0.49260","3.54672","40.17943"
"40.40000","40.37951","3.58930","1.26186","0.49851","3.58930","40.37951"
"40.60000","40.57938","3.54649","1.26811","0.49257","3.54649","40.57938"
"40.80000","40.77951","3.64623","1.27436","0.50642","3.64623","40.77951"
"41.00000","40.97942","3.63774","1.28061","0.50524","3.63774","40.97942"
"41.20000","41.17954","3.68279","1.28686","0.51150","3.68279","41.17954"
"41.40000","41.37944","3.61865","1.29311","0.50259","3.61865","41.37944"
"41.60000","41.57957","3.72800","1.29936","0.51778","3.72800","41.57957"
"41.80000","41.77933","3.76088","1.30560","0.52234","3.76088","41.77933"
"42.00000","41.97955","3.73980","1.31186","0.51942","3.73980","41.97955"
"42.20000","42.17936","3.80833","1.31810","0.52893","3.80833","42.17936"
"42.40000","42.37957","3.73755","1.32436","0.51910","3.73755","42.37957"
"42.60000","42.57941","3.87894","1.33061","0.53874","3.87894","42.57941"
"42.80000","42.77958","3.87339","1.33686","0.53797","3.87339","42.77958"
"43.00000","42.97945","3.88153","1.34311","0.53910","3.88153","42.97945"
"43.20000","43.17955","3.97283","1.34936","0.55178","3.97283","43.17955"
"43.40000","43.37944","3.92340","1.35561","0.54492","3.92340","43.37944"
"43.60000","43.57957","3.97392","1.36186","0.55193","3.97392","43.57957"
"43.80000","43.77945","3.91996","1.36811","0.54444","3.91996","43.77945"
"44.00000","43.97960","3.97357","1.37436","0.55188","3.97357","43.97960"
"44.20000","44.17944","4.04992","1.38061","0.56249","4.04992","44.17944"
"44.40000","44.37962","4.10470","1.38686","0.57010","4.10470","44.37962"
"44.60000","44.57940","4.11374","1.39311","0.57135","4.11374","44.57940"
"44.80000","44.77961","4.11829","1.39936","0.57198","4.11829","44.77961"
"45.00000","44.97948","4.13123","1.40561","0.57378","4.13123","44.97948"
"45.20000","45.17964","4.21001","1.41186","0.58472","4.21001","45.17964"
"45.40000","45.37941","4.16463","1.41811","0.57842","4.16463","45.37941"
"45.60000","45.57957","4.27133","1.42436","0.59324","4.27133","45.57957"
"45.80000","45.77948","4.25400","1.43061","0.59083","4.25400","45.77948"
"46.00000","45.97964","4.23484","1.43686","0.58817","4.23484","45.97964"
"46.20000","46.17951","4.33715","1.44311","0.60238","4.33715","46.17951"
"46.40000","46.37963","4.30272","1.44936","0.59760","4.30272","46.37963"
"46.60000","46.57947","4.38631","1.45561","0.60921","4.38631","46.57947"
"46.80000","46.77964","4.38906","1.46186","0.60959","4.38906","46.77964"
"47.00000","46.97947","4.38619","1.46811","0.60919","4.38619","46.97947"
"47.20000","47.17964","4.49241","1.47436","0.62395","4.49241","47.17964"
"47.40000","47.37952","4.42615","1.48061","0.61474","4.42615","47.37952"
"47.60000","47.57965","4.47203","1.48686","0.62112","4.47203","47.57965"
"47.80000","47.77953","4.44736","1.49311","0.61769","4.44736","47.77953"
"48.00000","47.97962","4.50404","1.49936","0.62556","4.50404","47.97962"
"48.20000","48.17947","4.58456","1.50561","0.63674","4.58456","48.17947"
"48.40000","48.37964","4.57495","1.51186","0.63541","4.57495","48.37964"
"48.60000","48.57951","4.63049","1.51811","0.64312","4.63049","48.57951"
"48.80000","48.77967","4.65131","1.52436","0.64601","4.65131","48.77967"
"49.00000","48.97947","4.68358","1.53061","0.65050","4.68358","48.97947"
"49.20000","49.17965","4.69090","1.53686","0.65151","4.69090","49.17965"
"49.40000","49.37946","4.70722","1.54311","0.65378","4.70722","49.37946"
"49.60000","49.57965","4.84517","1.54936","0.67294","4.84517","49.57965"
"49.80000","49.77951","4.76970","1.55561","0.66246","4.76970","49.77951"
"50.00000","49.97963","4.82067","1.56186","0.66954","4.82067","49.97963"
"50.20000","50.17950","4.83807","1.56811","0.67195","4.83807","50.17950"
"50.40000","50.37961","4.84635","1.57436","0.67310","4.84635","50.37961"
"50.60000","50.57951","4.94325","1.58061","0.68656","4.94325","50.57951"
"50.80000","50.77964","4.97128","1.58686","0.69046","4.97128","50.77964"
"51.00000","50.97948","4.98084","1.59311","0.69178","4.98084","50.97948"
"51.20000","51.17967","5.01108","1.59936","0.69598","5.01108","51.17967"
"51.40000","51.37944","4.99341","1.60561","0.69353","4.99341","51.37944"
"51.60000","51.57968","5.06675","1.61187","0.70372","5.06675","51.57968"
"51.80000","51.77943","5.05203","1.61811","0.70167","5.05203","51.77943"
"52.00000","51.97960","5.07113","1.62436","0.70432","5.07113","51.97960"
"52.20000","52.17949","5.12808","1.63061","0.71223","5.12808","52.17949"
"52.40000","52.37962","5.13434","1.63686","0.71310","5.13434","52.37962"
"52.60000","52.57948","5.20735","1.64311","0.72324","5.20735","52.57948"
"52.80000","52.77959","5.18482","1.64936","0.72011","5.18482","52.77959"
"53.00000","52.97945","5.22965","1.65561","0.72634","5.22965","52.97945"
"53.20000","53.17962","5.28446","1.66186","0.73395","5.28446","53.17962"
"53.40000","53.37947","5.30933","1.66811","0.73741","5.30933","53.37947"
"53.60000","53.57967","5.31310","1.67436","0.73793","5.31310","53.57967"
"53.80000","53.77939","5.34363","1.68061","0.74217","5.34363","53.77939"
"54.00000","53.97959","5.42769","1.68686","0.75385","5.42769","53.97959"
"54.20000","54.17944","5.39071","1.69311","0.74871","5.39071","54.17944"
"54.40000","54.37955","5.47384","1.69936","0.76026","5.47384","54.37955"
"54.60000","54.57946","5.49588","1.70561","0.76332","5.49588","54.57946"
"54.80000","54.77960","5.46557","1.71186","0.75911","5.46557","54.77960"
"55.00000","54.97944","5.58502","1.71811","0.77570","5.58502","54.97944"
"55.20000","55.17957","5.60286","1.72436","0.77817","5.60286","55.17957"
"55.40000","55.37941","5.62627","1.73061","0.78143","5.62627","55.37941"
"55.60000","55.57959","5.64028","1.73686","0.78337","5.64028","55.57959"
"55.80000","55.77938","5.67618","1.74311","0.78836","5.67618","55.77938"
"56.00000","55.97959","5.67286","1.74936","0.78790","5.67286","55.97959"
"56.20000","56.17938","5.72215","1.75561","0.79474","5.72215","56.17938"
"56.40000","56.37959","5.69097","1.76186","0.79041","5.69097","56.37959"
"56.60000","56.57941","5.78710","1.76811","0.80376","5.78710","56.57941"
"56.80000","56.77951","5.78779","1.77436","0.80386","5.78779","56.77951"
"57.00000","56.97942","5.87094","1.78061","0.81541","5.87094","56.97942"
"57.20000","57.17953","5.86707","1.78686","0.81487","5.86707","57.17953"
"57.40000","57.37938","5.92448","1.79311","0.82284","5.92448","57.37938"
"57.60000","57.57950","5.93888","1.79936","0.82484","5.93888","57.57950"
"57.80000","57.77939","5.91158","1.80561","0.82105","5.91158","57.77939"
"58.00000","57.97954","5.98293","1.81186","0.83096","5.98293","57.97954"
"58.20000","58.17931","6.05822","1.81810","0.84142","6.05822","58.17931"
"58.40000","58.37955","6.08108","1.82436","0.84459","6.08108","58.37955"
"58.60000","58.57935","6.14699","1.83060","0.85375","6.14699","58.57935"
"58.80000","58.77949","6.10137","1.83686","0.84741","6.10137","58.77949"
"59.00000","58.97942","6.21984","1.84311","0.86387","6.21984","58.97942"
"59.20000","59.17949","6.13073","1.84936","0.85149","6.13073","59.17949"
"59.40000","59.37940","6.16088","1.85561","0.85568","6.16088","59.37940"
"59.60000","59.57948","6.28377","1.86186","0.87275","6.28377","59.57948"
"59.80000","59.77934","6.26339","1.86810","0.86992","6.26339","59.77934"
"60.00000","59.97949","6.34880","1.87436","0.88178","6.34880","59.97949"
"60.20000","60.17937","6.34206","1.88061","0.88084","6.34206","60.17937"
"60.40000","60.37951","6.40802","1.88686","0.89000","6.40802","60.37951"
"60.60000","60.57936","6.40669","1.89310","0.88982","6.40669","60.57936"
"60.80000","60.77949","6.43915","1.89936","0.89433","6.43915","60.77949"
"61.00000","60.97938","6.45718","1.90561","0.89683","6.45718","60.97938"
"61.20000","61.17949","6.48364","1.91186","0.90051","6.48364","61.17949"
"61.40000","61.37941","6.52367","1.91811","0.90607","6.52367","61.37941"
"61.60000","61.57947","6.61333","1.92436","0.91852","6.61333","61.57947"
"61.80000","61.77939","6.58454","1.93061","0.91452","6.58454","61.77939"
"62.00000","61.97953","6.66334","1.93686","0.92546","6.66334","61.97953"
"62.20000","62.17937","6.68097","1.94311","0.92791","6.68097","62.17937"
"62.40000","62.37943","6.69515","1.94936","0.92988","6.69515","62.37943"
"62.60000","62.57934","6.70600","1.95560","0.93139","6.70600","62.57934"
"62.80000","62.77957","6.69888","1.96186","0.93040","6.69888","62.77957"
"63.00000","62.97939","6.75781","1.96811","0.93858","6.75781","62.97939"
"63.20000","63.17949","6.83013","1.97436","0.94863","6.83013","63.17949"
"63.40000","63.37944","6.84695","1.98061","0.95097","6.84695","63.37944"
"63.60000","63.57948","6.81198","1.98686","0.94611","6.81198","63.57948"
"63.80000","63.77943","6.93412","1.99311","0.96307","6.93412","63.77943"
"64.00000","63.97948","6.96094","1.99936","0.96680","6.96094","63.97948"
"64.20000","64.17943","6.91856","2.00561","0.96091","6.91856","64.17943"
"64.40000","64.37950","6.99033","2.01186","0.97088","6.99033","64.37950"
"64.60000","64.57944","7.08360","2.01811","0.98383","7.08360","64.57944"
"64.80000","64.77953","7.03686","2.02436","0.97734","7.03686","64.77953"
"65.00000","64.97945","7.11503","2.03061","0.98820","7.11503","64.97945"
"65.20000","65.17953","7.05139","2.03686","0.97936","7.05139","65.17953"
"65.40000","65.37945","7.14635","2.04311","0.99255","7.14635","65.37945"
"65.60000","65.57951","7.20931","2.04936","1.00129","7.20931","65.57951"
"65.80000","65.77945","7.27875","2.05561","1.01094","7.27875","65.77945"
"66.00000","65.97951","7.23665","2.06186","1.00509","7.23665","65.97951"
"66.20000","66.17947","7.24458","2.06811","1.00619","7.24458","66.17947"
"66.40000","66.37953","7.30132","2.07436","1.01407","7.30132","66.37953"
"66.60000","66.57948","7.29208","2.08061","1.01279","7.29208","66.57948"
"66.80000","66.77954","7.40464","2.08686","1.02842","7.40464","66.77954"
"67.00000","66.97944","7.39710","2.09311","1.02738","7.39710","66.97944"
"67.20000","67.17953","7.42219","2.09936","1.03086","7.42219","67.17953"
"67.40000","67.37951","7.44014","2.10561","1.03335","7.44014","67.37951"
"67.60000","67.57959","7.44841","2.11186","1.03450","7.44841","67.57959"
"67.80000","67.77951","7.59684","2.11811","1.05512","7.59684","67.77951"
"68.00000","67.97956","7.45630","2.12436","1.03560","7.45630","67.97956"
"68.20000","68.17953","7.48815","2.13061","1.04002","7.48815","68.17953"
"68.40000","68.37956","7.55742","2.13686","1.04964","7.55742","68.37956"
"68.60000","68.57953","7.61324","2.14311","1.05739","7.61324","68.57953"
"68.80000","68.77953","7.63571","2.14936","1.06052","7.63571","68.77953"
"69.00000","68.97954","7.60255","2.15561","1.05591","7.60255","68.97954"
"69.20000","69.17957","7.73000","2.16186","1.07361","7.73000","69.17957"
"69.40000","69.37949","0.12005","2.16811","0.01667","0.12005","69.37949"
"69.60000","69.57957","0.23350","2.17436","0.03243","0.23350","69.57957"
"69.80000","69.77956","0.24255","2.18061","0.03369","0.24255","69.77956"
"70.00000","69.97957","0.24590","2.18686","0.03415","0.24590","69.97957"
"70.20000","70.17957","0.22377","2.19311","0.03108","0.22377","70.17957"
"70.40000","70.37955","0.21118","2.19936","0.02933","0.21118","70.37955"
"70.47300","70.45257","0.22267","2.20164","0.03093","0.22267","70.45257"