File: 1silicon10.csv
Tenacity at Break (Standard),"0.24298",N/tex
Tensile extension at Break (Standard),"112.57944",mm
Tenacity at Yield ,,N/tex

Time,Extension,Load,Tensile strain (Extension),Tensile stress,Tenacity,Tensile extension
(s),(mm),(N),(mm/mm),(MPa),(N/tex),(mm)
"0.00000","0.00000","-0.10679","0.00000","-0.01780","-0.10679","0.00000"
"0.20000","0.17916","0.01804","0.00560","0.00301","0.01804","0.17916"
"0.40000","0.37945","0.01789","0.01186","0.00298","0.01789","0.37945"
"0.60000","0.57950","0.05080","0.01811","0.00847","0.05080","0.57950"
"0.80000","0.77940","0.02630","0.02436","0.00438","0.02630","0.77940"
"1.00000","0.97952","0.07458","0.03061","0.01243","0.07458","0.97952"
"1.20000","1.17943","0.02230","0.03686","0.00372","0.02230","1.17943"
"1.40000","1.37952","0.04236","0.04311","0.00706","0.04236","1.37952"
"1.60000","1.57942","0.11093","0.04936","0.01849","0.11093","1.57942"
"1.80000","1.77959","0.04465","0.05561","0.00744","0.04465","1.77959"
"2.00000","1.97941","0.06154","0.06186","0.01026","0.06154","1.97941"
"2.20000","2.17956","0.11699","0.06811","0.01950","0.11699","2.17956"
"2.40000","2.37942","0.11471","0.07436","0.01912","0.11471","2.37942"
"2.60000","2.57959","0.11597","0.08061","0.01933","0.11597","2.57959"
"2.80000","2.77942","0.14937","0.08686","0.02490","0.14937","2.77942"
"3.00000","2.97956","0.14375","0.09311","0.02396","0.14375","2.97956"
"3.20000","3.17945","0.20076","0.09936","0.03346","0.20076","3.17945"
"3.40000","3.37959","0.15947","0.10561","0.02658","0.15947","3.37959"
"3.60000","3.57947","0.16888","0.11186","0.02815","0.16888","3.57947"
"3.80000","3.77960","0.17125","0.11811","0.02854","0.17125","3.77960"
"4.00000","3.97944","0.20706","0.12436","0.03451","0.20706","3.97944"
"4.20000","4.17960","0.16562","0.13061","0.02760","0.16562","4.17960"
"4.40000","4.37945","0.19903","0.13686","0.03317","0.19903","4.37945"
"4.60000","4.57963","0.23370","0.14311","0.03895","0.23370","4.57963"
"4.80000","4.77943","0.31056","0.14936","0.05176","0.31056","4.77943"
"5.00000","4.97963","0.23012","0.15561","0.03835","0.23012","4.97963"
"5.20000","5.17948","0.28116","0.16186","0.04686","0.28116","5.17948"
"5.40000","5.37960","0.21002","0.16811","0.03500","0.21002","5.37960"
"5.60000","5.57950","0.26010","0.17436","0.04335","0.26010","5.57950"
"5.80000","5.77966","0.20063","0.18061","0.03344","0.20063","5.77966"
"6.00000","5.97950","0.23083","0.18686","0.03847","0.23083","5.97950"
"6.20000","6.17965","0.22450","0.19311","0.03742","0.22450","6.17965"
"6.40000","6.37942","0.28601","0.19936","0.04767","0.28601","6.37942"
"6.60000","6.57967","0.25453","0.20561","0.04242","0.25453","6.57967"
"6.80000","6.77947","0.31198","0.21186","0.05200","0.31198","6.77947"
"7.00000","6.97968","0.31424","0.21811","0.05237","0.31424","6.97968"
"7.20000","7.17943","0.32712","0.22436","0.05452","0.32712","7.17943"
"7.40000","7.37966","0.31218","0.23061","0.05203","0.31218","7.37966"
"7.60000","7.57948","0.36940","0.23686","0.06157","0.36940","7.57948"
"7.80000","7.77961","0.25665","0.24311","0.04277","0.25665","7.77961"
"8.00000","7.97953","0.26039","0.24936","0.04340","0.26039","7.97953"
"8.20000","8.17965","0.30296","0.25561","0.05049","0.30296","8.17965"
"8.40000","8.37949","0.32971","0.26186","0.05495","0.32971","8.37949"
"8.60000","8.57967","0.39423","0.26811","0.06570","0.39423","8.57967"
"8.80000","8.77947","0.32784","0.27436","0.05464","0.32784","8.77947"
"9.00000","8.97964","0.41664","0.28061","0.06944","0.41664","8.97964"
"9.20000","9.17946","0.29261","0.28686","0.04877","0.29261","9.17946"
"9.40000","9.37967","0.41499","0.29311","0.06917","0.41499","9.37967"
"9.60000","9.57946","0.39131","0.29936","0.06522","0.39131","9.57946"
"9.80000","9.77966","0.40881","0.30561","0.06814","0.40881","9.77966"
"10.00000","9.97948","0.38908","0.31186","0.06485","0.38908","9.97948"
"10.20000","10.17961","0.41897","0.31811","0.06983","0.41897","10.17961"
"10.40000","10.37949","0.40988","0.32436","0.06831","0.40988","10.37949"
"10.60000","10.57963","0.49100","0.33061","0.08183","0.49100","10.57963"
"10.80000","10.77947","0.39878","0.33686","0.06646","0.39878","10.77947"
"11.00000","10.97965","0.44473","0.34311","0.07412","0.44473","10.97965"
"11.20000","11.17950","0.41104","0.34936","0.06851","0.41104","11.17950"
"11.40000","11.37965","0.48178","0.35561","0.08030","0.48178","11.37965"
"11.60000","11.57945","0.47650","0.36186","0.07942","0.47650","11.57945"
"11.80000","11.77966","0.51889","0.36811","0.08648","0.51889","11.77966"
"12.00000","11.97948","0.44327","0.37436","0.07388","0.44327","11.97948"
"12.20000","12.17961","0.45762","0.38061","0.07627","0.45762","12.17961"
"12.40000","12.37946","0.44928","0.38686","0.07488","0.44928","12.37946"
"12.60000","12.57952","0.38729","0.39311","0.06455","0.38729","12.57952"
"12.80000","12.77945","0.50166","0.39936","0.08361","0.50166","12.77945"
"13.00000","12.97960","0.46883","0.40561","0.07814","0.46883","12.97960"
"13.20000","13.17944","0.54537","0.41186","0.09090","0.54537","13.17944"
"13.40000","13.37958","0.54957","0.41811","0.09160","0.54957","13.37958"
"13.60000","13.57942","0.51608","0.42436","0.08601","0.51608","13.57942"
"13.80000","13.77964","0.50268","0.43061","0.08378","0.50268","13.77964"
"14.00000","13.97941","0.50306","0.43686","0.08384","0.50306","13.97941"
"14.20000","14.17960","0.54563","0.44311","0.09094","0.54563","14.17960"
"14.40000","14.37946","0.56814","0.44936","0.09469","0.56814","14.37946"
"14.60000","14.57957","0.55402","0.45561","0.09234","0.55402","14.57957"
"14.80000","14.77944","0.60394","0.46186","0.10066","0.60394","14.77944"
"15.00000","14.97953","0.57414","0.46811","0.09569","0.57414","14.97953"
"15.20000","15.17948","0.57586","0.47436","0.09598","0.57586","15.17948"
"15.40000","15.37956","0.59454","0.48061","0.09909","0.59454","15.37956"
"15.60000","15.57936","0.61996","0.48686","0.10333","0.61996","15.57936"
"15.80000","15.77960","0.61615","0.49311","0.10269","0.61615","15.77960"
"16.00000","15.97936","0.68602","0.49936","0.11434","0.68602","15.97936"
"16.20000","16.17958","0.65179","0.50561","0.10863","0.65179","16.17958"
"16.40000","16.37939","0.54004","0.51186","0.09001","0.54004","16.37939"
"16.60000","16.57954","0.66210","0.51811","0.11035","0.66210","16.57954"
"16.80000","16.77944","0.59356","0.52436","0.09893","0.59356","16.77944"
"17.00000","16.97952","0.62277","0.53061","0.10380","0.62277","16.97952"
"17.20000","17.17940","0.62301","0.53686","0.10384","0.62301","17.17940"
"17.40000","17.37949","0.65753","0.54311","0.10959","0.65753","17.37949"
"17.60000","17.57938","0.67150","0.54936","0.11192","0.67150","17.57938"
"17.80000","17.77949","0.62020","0.55561","0.10337","0.62020","17.77949"
"18.00000","17.97937","0.67553","0.56186","0.11259","0.67553","17.97937"
"18.20000","18.17956","0.65286","0.56811","0.10881","0.65286","18.17956"
"18.40000","18.37933","0.73680","0.57435","0.12280","0.73680","18.37933"
"18.60000","18.57957","0.74300","0.58061","0.12383","0.74300","18.57957"
"18.80000","18.77939","0.81036","0.58686","0.13506","0.81036","18.77939"
"19.00000","18.97943","0.68033","0.59311","0.11339","0.68033","18.97943"
"19.20000","19.17936","0.69518","0.59935","0.11586","0.69518","19.17936"
"19.40000","19.37950","0.73961","0.60561","0.12327","0.73961","19.37950"
"19.60000","19.57937","0.74839","0.61186","0.12473","0.74839","19.57937"
"19.80000","19.77946","0.73756","0.61811","0.12293","0.73756","19.77946"
"20.00000","19.97941","0.74859","0.62436","0.12477","0.74859","19.97941"
"20.20000","20.17951","0.72105","0.63061","0.12017","0.72105","20.17951"
"20.40000","20.37935","0.74637","0.63685","0.12440","0.74637","20.37935"
"20.60000","20.57950","0.75544","0.64311","0.12591","0.75544","20.57950"
"20.80000","20.77934","0.81308","0.64935","0.13551","0.81308","20.77934"
"21.00000","20.97952","0.79683","0.65561","0.13281","0.79683","20.97952"
"21.20000","21.17939","0.77633","0.66186","0.12939","0.77633","21.17939"
"21.40000","21.37945","0.79987","0.66811","0.13331","0.79987","21.37945"
"21.60000","21.57938","0.83583","0.67436","0.13930","0.83583","21.57938"
"21.80000","21.77949","0.81726","0.68061","0.13621","0.81726","21.77949"
"22.00000","21.97938","0.75193","0.68686","0.12532","0.75193","21.97938"
"22.20000","22.17947","0.80742","0.69311","0.13457","0.80742","22.17947"
"22.40000","22.37938","0.80086","0.69936","0.13348","0.80086","22.37938"
"22.60000","22.57949","0.81240","0.70561","0.13540","0.81240","22.57949"
"22.80000","22.77937","0.78931","0.71186","0.13155","0.78931","22.77937"
"23.00000","22.97953","0.81913","0.71811","0.13652","0.81913","22.97953"
"23.20000","23.17936","0.79257","0.72436","0.13210","0.79257","23.17936"
"23.40000","23.37952","0.82331","0.73061","0.13722","0.82331","23.37952"
"23.60000","23.57945","0.79782","0.73686","0.13297","0.79782","23.57945"
"23.80000","23.77948","0.87597","0.74311","0.14599","0.87597","23.77948"
"24.00000","23.97944","0.80079","0.74936","0.13346","0.80079","23.97944"
"24.20000","24.17951","0.88179","0.75561","0.14697","0.88179","24.17951"
"24.40000","24.37943","0.86952","0.76186","0.14492","0.86952","24.37943"
"24.60000","24.57948","0.89502","0.76811","0.14917","0.89502","24.57948"
"24.80000","24.77945","0.83767","0.77436","0.13961","0.83767","24.77945"
"25.00000","24.97953","0.85489","0.78061","0.14248","0.85489","24.97953"
"25.20000","25.17944","0.79139","0.78686","0.13190","0.79139","25.17944"
"25.40000","25.37953","0.92544","0.79311","0.15424","0.92544","25.37953"
"25.60000","25.57947","0.89640","0.79936","0.14940","0.89640","25.57947"
"25.80000","25.77952","0.90280","0.80561","0.15047","0.90280","25.77952"
"26.00000","25.97949","0.94347","0.81186","0.15725","0.94347","25.97949"
"26.20000","26.17951","0.86752","0.81811","0.14459","0.86752","26.17951"
"26.40000","26.37951","0.92915","0.82436","0.15486","0.92915","26.37951"
"26.60000","26.57955","0.95968","0.83061","0.15995","0.95968","26.57955"
"26.80000","26.77948","0.97835","0.83686","0.16306","0.97835","26.77948"
"27.00000","26.97957","0.96157","0.84311","0.16026","0.96157","26.97957"
"27.20000","27.17950","0.93068","0.84936","0.15511","0.93068","27.17950"
"27.40000","27.37957","0.95920","0.85561","0.15987","0.95920","27.37957"
"27.60000","27.57949","0.96593","0.86186","0.16099","0.96593","27.57949"
"27.80000","27.77952","0.96396","0.86811","0.16066","0.96396","27.77952"
"28.00000","27.97952","1.01246","0.87436","0.16874","1.01246","27.97952"
"28.20000","28.17956","0.96885","0.88061","0.16148","0.96885","28.17956"
"28.40000","28.37955","1.00183","0.88686","0.16697","1.00183","28.37955"
"28.60000","28.57953","1.01274","0.89311","0.16879","1.01274","28.57953"
"28.80000","28.77954","0.96247","0.89936","0.16041","0.96247","28.77954"
"29.00000","28.97958","1.06901","0.90561","0.17817","1.06901","28.97958"
"29.20000","29.17949","1.02012","0.91186","0.17002","1.02012","29.17949"
"29.40000","29.37958","1.01097","0.91811","0.16849","1.01097","29.37958"
"29.60000","29.57951","1.05437","0.92436","0.17573","1.05437","29.57951"
"29.80000","29.77959","1.09865","0.93061","0.18311","1.09865","29.77959"
"30.00000","29.97959","0.98641","0.93686","0.16440","0.98641","29.97959"
"30.20000","30.17954","1.03935","0.94311","0.17323","1.03935","30.17954"
"30.40000","30.37955","1.00940","0.94936","0.16823","1.00940","30.37955"
"30.60000","30.57957","1.09497","0.95561","0.18250","1.09497","30.57957"
"30.80000","30.77957","1.04078","0.96186","0.17346","1.04078","30.77957"
"31.00000","30.97953","1.15959","0.96811","0.19326","1.15959","30.97953"
"31.20000","31.17957","1.02205","0.97436","0.17034","1.02205","31.17957"
"31.40000","31.37954","1.08774","0.98061","0.18129","1.08774","31.37954"
"31.60000","31.57952","1.09490","0.98686","0.18248","1.09490","31.57952"
"31.80000","31.77961","1.08866","0.99311","0.18144","1.08866","31.77961"
"32.00000","31.97956","1.16082","0.99936","0.19347","1.16082","31.97956"
"32.20000","32.17962","1.11956","1.00561","0.18659","1.11956","32.17962"
"32.40000","32.37958","1.09622","1.01186","0.18270","1.09622","32.37958"
"32.60000","32.57950","1.08394","1.01811","0.18066","1.08394","32.57950"
"32.80000","32.77957","1.10795","1.02436","0.18466","1.10795","32.77957"
"33.00000","32.97953","1.14275","1.03061","0.19046","1.14275","32.97953"
"33.20000","33.17959","1.18061","1.03686","0.19677","1.18061","33.17959"
"33.40000","33.37954","1.14204","1.04311","0.19034","1.14204","33.37954"
"33.60000","33.57956","1.21138","1.04936","0.20190","1.21138","33.57956"
"33.80000","33.77952","1.21705","1.05561","0.20284","1.21705","33.77952"
"34.00000","33.97950","1.15773","1.06186","0.19295","1.15773","33.97950"
"34.20000","34.17953","1.15192","1.06811","0.19199","1.15192","34.17953"
"34.40000","34.37956","1.19747","1.07436","0.19958","1.19747","34.37956"
"34.60000","34.57953","1.30508","1.08061","0.21751","1.30508","34.57953"
"34.80000","34.77956","1.24338","1.08686","0.20723","1.24338","34.77956"
"35.00000","34.97951","1.26148","1.09311","0.21025","1.26148","34.97951"
"35.20000","35.17959","1.20767","1.09936","0.20128","1.20767","35.17959"
"35.40000","35.37949","1.24727","1.10561","0.20788","1.24727","35.37949"
"35.60000","35.57956","1.26687","1.11186","0.21114","1.26687","35.57956"
"35.80000","35.77952","1.24362","1.11811","0.20727","1.24362","35.77952"
"36.00000","35.97954","1.17536","1.12436","0.19589","1.17536","35.97954"
"36.20000","36.17950","1.21309","1.13061","0.20218","1.21309","36.17950"
"36.40000","36.37951","1.28589","1.13686","0.21432","1.28589","36.37951"
"36.60000","36.57950","1.19664","1.14311","0.19944","1.19664","36.57950"
"36.80000","36.77952","1.24451","1.14936","0.20742","1.24451","36.77952"
"37.00000","36.97952","1.23160","1.15561","0.20527","1.23160","36.97952"
"37.20000","37.17955","1.16027","1.16186","0.19338","1.16027","37.17955"
"37.40000","37.37943","1.29708","1.16811","0.21618","1.29708","37.37943"
"37.60000","37.57953","1.28026","1.17436","0.21338","1.28026","37.57953"
"37.80000","37.77942","1.31288","1.18061","0.21881","1.31288","37.77942"
"38.00000","37.97951","1.30046","1.18686","0.21674","1.30046","37.97951"
"38.20000","38.17948","1.27246","1.19311","0.21208","1.27246","38.17948"
"38.40000","38.37952","1.33611","1.19936","0.22268","1.33611","38.37952"
"38.60000","38.57945","1.28140","1.20561","0.21357","1.28140","38.57945"
"38.80000","38.77948","1.35947","1.21186","0.22658","1.35947","38.77948"
"39.00000","38.97944","1.33574","1.21811","0.22262","1.33574","38.97944"
"39.20000","39.17949","1.40215","1.22436","0.23369","1.40215","39.17949"
"39.40000","39.37943","1.25160","1.23061","0.20860","1.25160","39.37943"
"39.60000","39.57951","1.34936","1.23686","0.22489","1.34936","39.57951"
"39.80000","39.77936","1.33579","1.24310","0.22263","1.33579","39.77936"
"40.00000","39.97955","1.31097","1.24936","0.21849","1.31097","39.97955"
"40.20000","40.17938","1.42061","1.25561","0.23677","1.42061","40.17938"
"40.40000","40.37946","1.43639","1.26186","0.23940","1.43639","40.37946"
"40.60000","40.57944","1.43996","1.26811","0.23999","1.43996","40.57944"
"40.80000","40.77951","1.37714","1.27436","0.22952","1.37714","40.77951"
"41.00000","40.97929","1.37698","1.28060","0.22950","1.37698","40.97929"
"41.20000","41.17945","1.45744","1.28686","0.24291","1.45744","41.17945"
"41.40000","41.37943","1.49216","1.29311","0.24869","1.49216","41.37943"
"41.60000","41.57949","1.42738","1.29936","0.23790","1.42738","41.57949"
"41.80000","41.77943","1.54676","1.30561","0.25779","1.54676","41.77943"
"42.00000","41.97954","1.36914","1.31186","0.22819","1.36914","41.97954"
"42.20000","42.17933","1.51848","1.31810","0.25308","1.51848","42.17933"
"42.40000","42.37954","1.46822","1.32436","0.24470","1.46822","42.37954"
"42.60000","42.57932","1.45188","1.33060","0.24198","1.45188","42.57932"
"42.80000","42.77945","1.40961","1.33686","0.23493","1.40961","42.77945"
"43.00000","42.97938","1.50300","1.34311","0.25050","1.50300","42.97938"
"43.20000","43.17952","1.47048","1.34936","0.24508","1.47048","43.17952"
"43.40000","43.37941","1.48097","1.35561","0.24683","1.48097","43.37941"
"43.60000","43.57948","1.55711","1.36186","0.25952","1.55711","43.57948"
"43.80000","43.77938","1.52586","1.36811","0.25431","1.52586","43.77938"
"44.00000","43.97950","1.53134","1.37436","0.25522","1.53134","43.97950"
"44.20000","44.17940","1.53177","1.38061","0.25529","1.53177","44.17940"
"44.40000","44.37953","1.53643","1.38686","0.25607","1.53643","44.37953"
"44.60000","44.57931","1.52271","1.39310","0.25379","1.52271","44.57931"
"44.80000","44.77954","1.60585","1.39936","0.26764","1.60585","44.77954"
"45.00000","44.97943","1.54147","1.40561","0.25691","1.54147","44.97943"
"45.20000","45.17948","1.62031","1.41186","0.27005","1.62031","45.17948"
"45.40000","45.37941","1.54963","1.41811","0.25827","1.54963","45.37941"
"45.60000","45.57951","1.62902","1.42436","0.27150","1.62902","45.57951"
"45.80000","45.77938","1.55367","1.43061","0.25895","1.55367","45.77938"
"46.00000","45.97953","1.61328","1.43686","0.26888","1.61328","45.97953"
"46.20000","46.17941","1.61770","1.44311","0.26962","1.61770","46.17941"
"46.40000","46.37954","1.64375","1.44936","0.27396","1.64375","46.37954"
"46.60000","46.57941","1.57871","1.45561","0.26312","1.57871","46.57941"
"46.80000","46.77959","1.57207","1.46186","0.26201","1.57207","46.77959"
"47.00000","46.97941","1.74704","1.46811","0.29117","1.74704","46.97941"
"47.20000","47.17958","1.70881","1.47436","0.28480","1.70881","47.17958"
"47.40000","47.37941","1.69685","1.48061","0.28281","1.69685","47.37941"
"47.60000","47.57953","1.67969","1.48686","0.27995","1.67969","47.57953"
"47.80000","47.77943","1.71851","1.49311","0.28642","1.71851","47.77943"
"48.00000","47.97956","1.70243","1.49936","0.28374","1.70243","47.97956"
"48.20000","48.17941","1.73240","1.50561","0.28873","1.73240","48.17941"
"48.40000","48.37958","1.68898","1.51186","0.28150","1.68898","48.37958"
"48.60000","48.57943","1.77501","1.51811","0.29583","1.77501","48.57943"
"48.80000","48.77961","1.82126","1.52436","0.30354","1.82126","48.77961"
"49.00000","48.97942","1.69838","1.53061","0.28306","1.69838","48.97942"
"49.20000","49.17962","1.80870","1.53686","0.30145","1.80870","49.17962"
"49.40000","49.37945","1.72607","1.54311","0.28768","1.72607","49.37945"
"49.60000","49.57956","1.80987","1.54936","0.30165","1.80987","49.57956"
"49.80000","49.77948","1.77054","1.55561","0.29509","1.77054","49.77948"
"50.00000","49.97957","1.85064","1.56186","0.30844","1.85064","49.97957"
"50.20000","50.17950","1.79753","1.56811","0.29959","1.79753","50.17950"
"50.40000","50.37963","1.81842","1.57436","0.30307","1.81842","50.37963"
"50.60000","50.57944","1.84153","1.58061","0.30692","1.84153","50.57944"
"50.80000","50.77964","1.82646","1.58686","0.30441","1.82646","50.77964"
"51.00000","50.97944","1.86707","1.59311","0.31118","1.86707","50.97944"
"51.20000","51.17965","1.85631","1.59936","0.30938","1.85631","51.17965"
"51.40000","51.37946","1.86966","1.60561","0.31161","1.86966","51.37946"
"51.60000","51.57962","1.81369","1.61186","0.30228","1.81369","51.57962"
"51.80000","51.77950","1.91658","1.61811","0.31943","1.91658","51.77950"
"52.00000","51.97961","1.84306","1.62436","0.30718","1.84306","51.97961"
"52.20000","52.17951","1.90643","1.63061","0.31774","1.90643","52.17951"
"52.40000","52.37962","1.93132","1.63686","0.32189","1.93132","52.37962"
"52.60000","52.57950","1.94885","1.64311","0.32481","1.94885","52.57950"
"52.80000","52.77963","1.88151","1.64936","0.31358","1.88151","52.77963"
"53.00000","52.97946","1.96273","1.65561","0.32712","1.96273","52.97946"
"53.20000","53.17965","1.97054","1.66186","0.32842","1.97054","53.17965"
"53.40000","53.37950","1.96449","1.66811","0.32741","1.96449","53.37950"
"53.60000","53.57967","1.98957","1.67436","0.33160","1.98957","53.57967"
"53.80000","53.77949","1.95433","1.68061","0.32572","1.95433","53.77949"
"54.00000","53.97965","1.97360","1.68686","0.32893","1.97360","53.97965"
"54.20000","54.17950","1.95992","1.69311","0.32665","1.95992","54.17950"
"54.40000","54.37958","2.03469","1.69936","0.33912","2.03469","54.37958"
"54.60000","54.57948","1.96049","1.70561","0.32675","1.96049","54.57948"
"54.80000","54.77966","2.05551","1.71186","0.34259","2.05551","54.77966"
"55.00000","54.97948","1.99827","1.71811","0.33305","1.99827","54.97948"
"55.20000","55.17964","2.07462","1.72436","0.34577","2.07462","55.17964"
"55.40000","55.37947","2.05634","1.73061","0.34272","2.05634","55.37947"
"55.60000","55.57969","2.09566","1.73687","0.34928","2.09566","55.57969"
"55.80000","55.77946","2.03754","1.74311","0.33959","2.03754","55.77946"
"56.00000","55.97968","2.08926","1.74936","0.34821","2.08926","55.97968"
"56.20000","56.17944","2.09683","1.75561","0.34947","2.09683","56.17944"
"56.40000","56.37960","2.11210","1.76186","0.35202","2.11210","56.37960"
"56.60000","56.57947","2.10013","1.76811","0.35002","2.10013","56.57947"
"56.80000","56.77958","2.06442","1.77436","0.34407","2.06442","56.77958"
"57.00000","56.97947","2.11660","1.78061","0.35277","2.11660","56.97947"
"57.20000","57.17960","2.14738","1.78686","0.35790","2.14738","57.17960"
"57.40000","57.37946","2.20490","1.79311","0.36748","2.20490","57.37946"
"57.60000","57.57965","2.13180","1.79936","0.35530","2.13180","57.57965"
"57.80000","57.77945","2.20493","1.80561","0.36749","2.20493","57.77945"
"58.00000","57.97956","2.15647","1.81186","0.35941","2.15647","57.97956"
"58.20000","58.17946","2.18192","1.81811","0.36365","2.18192","58.17946"
"58.40000","58.37963","2.15198","1.82436","0.35866","2.15198","58.37963"
"58.60000","58.57946","2.15607","1.83061","0.35935","2.15607","58.57946"
"58.80000","58.77958","2.27689","1.83686","0.37948","2.27689","58.77958"
"59.00000","58.97946","2.29799","1.84311","0.38300","2.29799","58.97946"
"59.20000","59.17953","2.26078","1.84936","0.37680","2.26078","59.17953"
"59.40000","59.37946","2.26387","1.85561","0.37731","2.26387","59.37946"
"59.60000","59.57959","2.26749","1.86186","0.37791","2.26749","59.57959"
"59.80000","59.77941","2.31860","1.86811","0.38643","2.31860","59.77941"
"60.00000","59.97956","2.30394","1.87436","0.38399","2.30394","59.97956"
"60.20000","60.17939","2.25236","1.88061","0.37539","2.25236","60.17939"
"60.40000","60.37960","2.32037","1.88686","0.38673","2.32037","60.37960"
"60.60000","60.57942","2.32691","1.89311","0.38782","2.32691","60.57942"
"60.80000","60.77956","2.34332","1.89936","0.39055","2.34332","60.77956"
"61.00000","60.97941","2.40431","1.90561","0.40072","2.40431","60.97941"
"61.20000","61.17955","2.36715","1.91186","0.39453","2.36715","61.17955"
"61.40000","61.37943","2.34409","1.91811","0.39068","2.34409","61.37943"
"61.60000","61.57948","2.33107","1.92436","0.38851","2.33107","61.57948"
"61.80000","61.77940","2.36686","1.93061","0.39448","2.36686","61.77940"
"62.00000","61.97959","2.38893","1.93686","0.39815","2.38893","61.97959"
"62.20000","62.17940","2.39150","1.94311","0.39858","2.39150","62.17940"
"62.40000","62.37954","2.34630","1.94936","0.39105","2.34630","62.37954"
"62.60000","62.57933","2.44270","1.95560","0.40712","2.44270","62.57933"
"62.80000","62.77951","2.41845","1.96186","0.40308","2.41845","62.77951"
"63.00000","62.97937","2.41566","1.96811","0.40261","2.41566","62.97937"
"63.20000","63.17950","2.45988","1.97436","0.40998","2.45988","63.17950"
"63.40000","63.37938","2.47032","1.98061","0.41172","2.47032","63.37938"
"63.60000","63.57947","2.50016","1.98686","0.41669","2.50016","63.57947"
"63.80000","63.77942","2.50108","1.99311","0.41685","2.50108","63.77942"
"64.00000","63.97948","2.47825","1.99936","0.41304","2.47825","63.97948"
"64.20000","64.17935","2.46889","2.00560","0.41148","2.46889","64.17935"
"64.40000","64.37955","2.54480","2.01186","0.42413","2.54480","64.37955"
"64.60000","64.57939","2.49193","2.01811","0.41532","2.49193","64.57939"
"64.80000","64.77952","2.55384","2.02436","0.42564","2.55384","64.77952"
"65.00000","64.97935","2.54074","2.03060","0.42346","2.54074","64.97935"
"65.20000","65.17950","2.61039","2.03686","0.43506","2.61039","65.17950"
"65.40000","65.37939","2.58587","2.04311","0.43098","2.58587","65.37939"
"65.60000","65.57952","2.62604","2.04936","0.43767","2.62604","65.57952"
"65.80000","65.77939","2.58419","2.05561","0.43070","2.58419","65.77939"
"66.00000","65.97943","2.57742","2.06186","0.42957","2.57742","65.97943"
"66.20000","66.17943","2.63350","2.06811","0.43892","2.63350","66.17943"
"66.40000","66.37945","2.58555","2.07436","0.43092","2.58555","66.37945"
"66.60000","66.57935","2.65773","2.08060","0.44295","2.65773","66.57935"
"66.80000","66.77959","2.64667","2.08686","0.44111","2.64667","66.77959"
"67.00000","66.97938","2.64295","2.09311","0.44049","2.64295","66.97938"
"67.20000","67.17951","2.66160","2.09936","0.44360","2.66160","67.17951"
"67.40000","67.37936","2.70830","2.10561","0.45138","2.70830","67.37936"
"67.60000","67.57952","2.72298","2.11186","0.45383","2.72298","67.57952"
"67.80000","67.77938","2.71363","2.11811","0.45227","2.71363","67.77938"
"68.00000","67.97950","2.72030","2.12436","0.45338","2.72030","67.97950"
"68.20000","68.17943","2.78727","2.13061","0.46455","2.78727","68.17943"
"68.40000","68.37948","2.70793","2.13686","0.45132","2.70793","68.37948"
"68.60000","68.57944","2.76862","2.14311","0.46144","2.76862","68.57944"
"68.80000","68.77950","2.73351","2.14936","0.45558","2.73351","68.77950"
"69.00000","68.97938","2.76848","2.15561","0.46141","2.76848","68.97938"
"69.20000","69.17953","2.79183","2.16186","0.46531","2.79183","69.17953"
"69.40000","69.37944","2.79056","2.16811","0.46509","2.79056","69.37944"
"69.60000","69.57954","2.80595","2.17436","0.46766","2.80595","69.57954"
"69.80000","69.77941","2.82553","2.18061","0.47092","2.82553","69.77941"
"70.00000","69.97952","2.88277","2.18686","0.48046","2.88277","69.97952"
"70.20000","70.17944","2.86504","2.19311","0.47751","2.86504","70.17944"
"70.40000","70.37949","2.88676","2.19936","0.48113","2.88676","70.37949"
"70.60000","70.57948","2.88666","2.20561","0.48111","2.88666","70.57948"
"70.80000","70.77949","2.91421","2.21186","0.48570","2.91421","70.77949"
"71.00000","70.97951","2.87289","2.21811","0.47882","2.87289","70.97951"
"71.20000","71.17955","2.95870","2.22436","0.49312","2.95870","71.17955"
"71.40000","71.37942","2.86840","2.23061","0.47807","2.86840","71.37942"
"71.60000","71.57957","2.93875","2.23686","0.48979","2.93875","71.57957"
"71.80000","71.77948","2.93621","2.24311","0.48937","2.93621","71.77948"
"72.00000","71.97954","2.98904","2.24936","0.49817","2.98904","71.97954"
"72.20000","72.17947","2.90342","2.25561","0.48390","2.90342","72.17947"
"72.40000","72.37955","2.93759","2.26186","0.48960","2.93759","72.37955"
"72.60000","72.57951","2.96650","2.26811","0.49442","2.96650","72.57951"
"72.80000","72.77950","2.97400","2.27436","0.49567","2.97400","72.77950"
"73.00000","72.97954","3.04244","2.28061","0.50707","3.04244","72.97954"
"73.20000","73.17954","2.92731","2.28686","0.48788","2.92731","73.17954"
"73.40000","73.37952","3.05474","2.29311","0.50912","3.05474","73.37952"
"73.60000","73.57958","3.05100","2.29936","0.50850","3.05100","73.57958"
"73.80000","73.77951","3.08504","2.30561","0.51417","3.08504","73.77951"
"74.00000","73.97957","3.10109","2.31186","0.51685","3.10109","73.97957"
"74.20000","74.17952","3.06016","2.31811","0.51003","3.06016","74.17952"
"74.40000","74.37958","2.99745","2.32436","0.49958","2.99745","74.37958"
"74.60000","74.57957","3.09027","2.33061","0.51505","3.09027","74.57957"
"74.80000","74.77957","3.14483","2.33686","0.52414","3.14483","74.77957"
"75.00000","74.97953","3.15699","2.34311","0.52616","3.15699","74.97953"
"75.20000","75.17955","3.17215","2.34936","0.52869","3.17215","75.17955"
"75.40000","75.37958","3.13050","2.35561","0.52175","3.13050","75.37958"
"75.60000","75.57957","3.20505","2.36186","0.53417","3.20505","75.57957"
"75.80000","75.77956","3.12680","2.36811","0.52113","3.12680","75.77956"
"76.00000","75.97956","3.24906","2.37436","0.54151","3.24906","75.97956"
"76.20000","76.17953","3.18140","2.38061","0.53023","3.18140","76.17953"
"76.40000","76.37960","3.23067","2.38686","0.53844","3.23067","76.37960"
"76.60000","76.57961","3.22435","2.39311","0.53739","3.22435","76.57961"
"76.80000","76.77953","3.30190","2.39936","0.55032","3.30190","76.77953"
"77.00000","76.97958","3.23649","2.40561","0.53941","3.23649","76.97958"
"77.20000","77.17951","3.30805","2.41186","0.55134","3.30805","77.17951"
"77.40000","77.37963","3.28031","2.41811","0.54672","3.28031","77.37963"
"77.60000","77.57956","3.31965","2.42436","0.55327","3.31965","77.57956"
"77.80000","77.77953","3.32056","2.43061","0.55343","3.32056","77.77953"
"78.00000","77.97957","3.31371","2.43686","0.55229","3.31371","77.97957"
"78.20000","78.17957","3.36011","2.44311","0.56002","3.36011","78.17957"
"78.40000","78.37956","3.35162","2.44936","0.55860","3.35162","78.37956"
"78.60000","78.57954","3.45767","2.45561","0.57628","3.45767","78.57954"
"78.80000","78.77955","3.34399","2.46186","0.55733","3.34399","78.77955"
"79.00000","78.97955","3.45507","2.46811","0.57584","3.45507","78.97955"
"79.20000","79.17953","3.37531","2.47436","0.56255","3.37531","79.17953"
"79.40000","79.37959","3.41867","2.48061","0.56978","3.41867","79.37959"
"79.60000","79.57952","3.46339","2.48686","0.57723","3.46339","79.57952"
"79.80000","79.77957","3.38537","2.49311","0.56423","3.38537","79.77957"
"80.00000","79.97956","3.40352","2.49936","0.56725","3.40352","79.97956"
"80.20000","80.17952","3.47085","2.50561","0.57848","3.47085","80.17952"
"80.40000","80.37951","3.46652","2.51186","0.57775","3.46652","80.37951"
"80.60000","80.57951","3.51432","2.51811","0.58572","3.51432","80.57951"
"80.80000","80.77953","3.49193","2.52436","0.58199","3.49193","80.77953"
"81.00000","80.97952","3.49839","2.53061","0.58306","3.49839","80.97952"
"81.20000","81.17948","3.51059","2.53686","0.58510","3.51059","81.17948"
"81.40000","81.37953","3.58151","2.54311","0.59692","3.58151","81.37953"
"81.60000","81.57947","3.53158","2.54936","0.58860","3.53158","81.57947"
"81.80000","81.77959","3.58345","2.55561","0.59724","3.58345","81.77959"
"82.00000","81.97947","3.55620","2.56186","0.59270","3.55620","81.97947"
"82.20000","82.17955","3.54451","2.56811","0.59075","3.54451","82.17955"
"82.40000","82.37950","3.63734","2.57436","0.60622","3.63734","82.37950"
"82.60000","82.57954","3.58796","2.58061","0.59799","3.58796","82.57954"
"82.80000","82.77947","3.57150","2.58686","0.59525","3.57150","82.77947"
"83.00000","82.97951","3.61112","2.59311","0.60185","3.61112","82.97951"
"83.20000","83.17947","3.69840","2.59936","0.61640","3.69840","83.17947"
"83.40000","83.37944","3.67215","2.60561","0.61202","3.67215","83.37944"
"83.60000","83.57946","3.67415","2.61186","0.61236","3.67415","83.57946"
"83.80000","83.77954","3.71809","2.61811","0.61968","3.71809","83.77954"
"84.00000","83.97940","3.67042","2.62436","0.61174","3.67042","83.97940"
"84.20000","84.17953","3.69789","2.63061","0.61631","3.69789","84.17953"
"84.40000","84.37943","3.71545","2.63686","0.61924","3.71545","84.37943"
"84.60000","84.57951","3.67678","2.64311","0.61280","3.67678","84.57951"
"84.80000","84.77941","3.69655","2.64936","0.61609","3.69655","84.77941"
"85.00000","84.97950","3.69721","2.65561","0.61620","3.69721","84.97950"
"85.20000","85.17944","3.72215","2.66186","0.62036","3.72215","85.17944"
"85.40000","85.37949","3.81048","2.66811","0.63508","3.81048","85.37949"
"85.60000","85.57943","3.83147","2.67436","0.63858","3.83147","85.57943"
"85.80000","85.77952","3.75265","2.68061","0.62544","3.75265","85.77952"
"86.00000","85.97939","3.86248","2.68686","0.64375","3.86248","85.97939"
"86.20000","86.17948","3.80999","2.69311","0.63500","3.80999","86.17948"
"86.40000","86.37936","3.84399","2.69935","0.64067","3.84399","86.37936"
"86.60000","86.57953","3.93698","2.70561","0.65616","3.93698","86.57953"
"86.80000","86.77937","3.89509","2.71186","0.64918","3.89509","86.77937"
"87.00000","86.97950","3.83853","2.71811","0.63975","3.83853","86.97950"
"87.20000","87.17937","3.89429","2.72436","0.64905","3.89429","87.17937"
"87.40000","87.37949","3.90718","2.73061","0.65120","3.90718","87.37949"
"87.60000","87.57941","3.85567","2.73686","0.64261","3.85567","87.57941"
"87.80000","87.77943","3.90628","2.74311","0.65105","3.90628","87.77943"
"88.00000","87.97939","3.89249","2.74936","0.64875","3.89249","87.97939"
"88.20000","88.17956","3.98253","2.75561","0.66375","3.98253","88.17956"
"88.40000","88.37938","4.03194","2.76186","0.67199","4.03194","88.37938"
"88.60000","88.57953","3.94853","2.76811","0.65809","3.94853","88.57953"
"88.80000","88.77935","3.95369","2.77435","0.65895","3.95369","88.77935"
"89.00000","88.97950","3.98844","2.78061","0.66474","3.98844","88.97950"
"89.20000","89.17938","4.01610","2.78686","0.66935","4.01610","89.17938"
"89.40000","89.37952","4.05473","2.79311","0.67579","4.05473","89.37952"
"89.60000","89.57941","4.08688","2.79936","0.68115","4.08688","89.57941"
"89.80000","89.77948","4.02932","2.80561","0.67155","4.02932","89.77948"
"90.00000","89.97944","4.12409","2.81186","0.68735","4.12409","89.97944"
"90.20000","90.17949","4.07654","2.81811","0.67942","4.07654","90.17949"
"90.40000","90.37936","4.13550","2.82435","0.68925","4.13550","90.37936"
"90.60000","90.57961","4.11531","2.83061","0.68588","4.11531","90.57961"
"90.80000","90.77944","4.15738","2.83686","0.69290","4.15738","90.77944"
"91.00000","90.97954","4.15164","2.84311","0.69194","4.15164","90.97954"
"91.20000","91.17935","4.15001","2.84935","0.69167","4.15001","91.17935"
"91.40000","91.37957","4.12038","2.85561","0.68673","4.12038","91.37957"
"91.60000","91.57942","4.14001","2.86186","0.69000","4.14001","91.57942"
"91.80000","91.77956","4.21618","2.86811","0.70270","4.21618","91.77956"
"92.00000","91.97939","4.18414","2.87436","0.69736","4.18414","91.97939"
"92.20000","92.17950","4.25936","2.88061","0.70989","4.25936","92.17950"
"92.40000","92.37946","4.23733","2.88686","0.70622","4.23733","92.37946"
"92.60000","92.57953","4.26765","2.89311","0.71127","4.26765","92.57953"
"92.80000","92.77940","4.23059","2.89936","0.70510","4.23059","92.77940"
"93.00000","92.97958","4.36978","2.90561","0.72830","4.36978","92.97958"
"93.20000","93.17946","4.28231","2.91186","0.71372","4.28231","93.17946"
"93.40000","93.37959","4.29444","2.91811","0.71574","4.29444","93.37959"
"93.60000","93.57944","4.29366","2.92436","0.71561","4.29366","93.57944"
"93.80000","93.77959","4.36364","2.93061","0.72727","4.36364","93.77959"
"94.00000","93.97942","4.32276","2.93686","0.72046","4.32276","93.97942"
"94.20000","94.17960","4.41516","2.94311","0.73586","4.41516","94.17960"
"94.40000","94.37949","4.40667","2.94936","0.73444","4.40667","94.37949"
"94.60000","94.57954","4.41921","2.95561","0.73654","4.41921","94.57954"
"94.80000","94.77948","4.34057","2.96186","0.72343","4.34057","94.77948"
"95.00000","94.97963","4.37231","2.96811","0.72872","4.37231","94.97963"
"95.20000","95.17942","4.43599","2.97436","0.73933","4.43599","95.17942"
"95.40000","95.37964","4.42423","2.98061","0.73737","4.42423","95.37964"
"95.60000","95.57944","4.38482","2.98686","0.73080","4.38482","95.57944"
"95.80000","95.77962","4.48449","2.99311","0.74741","4.48449","95.77962"
"96.00000","95.97945","4.42329","2.99936","0.73721","4.42329","95.97945"
"96.20000","96.17961","4.55448","3.00561","0.75908","4.55448","96.17961"
"96.40000","96.37949","4.44647","3.01186","0.74108","4.44647","96.37949"
"96.60000","96.57964","4.53047","3.01811","0.75508","4.53047","96.57964"
"96.80000","96.77950","4.52467","3.02436","0.75411","4.52467","96.77950"
"97.00000","96.97962","4.50858","3.03061","0.75143","4.50858","96.97962"
"97.20000","97.17952","4.65309","3.03686","0.77552","4.65309","97.17952"
"97.40000","97.37964","4.56411","3.04311","0.76069","4.56411","97.37964"
"97.60000","97.57943","4.63242","3.04936","0.77207","4.63242","97.57943"
"97.80000","97.77968","4.57626","3.05561","0.76271","4.57626","97.77968"
"98.00000","97.97946","4.62150","3.06186","0.77025","4.62150","97.97946"
"98.20000","98.17960","4.62801","3.06811","0.77134","4.62801","98.17960"
"98.40000","98.37948","4.56866","3.07436","0.76144","4.56866","98.37948"
"98.60000","98.57966","4.69451","3.08061","0.78242","4.69451","98.57966"
"98.80000","98.77953","4.67992","3.08686","0.77999","4.67992","98.77953"
"99.00000","98.97962","4.69541","3.09311","0.78257","4.69541","98.97962"
"99.20000","99.17950","4.68485","3.09936","0.78081","4.68485","99.17950"
"99.40000","99.37965","4.77436","3.10561","0.79573","4.77436","99.37965"
"99.60000","99.57948","4.65986","3.11186","0.77664","4.65986","99.57948"
"99.80000","99.77966","4.64776","3.11811","0.77463","4.64776","99.77966"
"100.00000","99.97948","4.82131","3.12436","0.80355","4.82131","99.97948"
"100.20000","100.17967","4.78019","3.13061","0.79670","4.78019","100.17967"
"100.40000","100.37937","4.78105","3.13686","0.79684","4.78105","100.37937"
"100.60000","100.57964","4.82165","3.14311","0.80361","4.82165","100.57964"
"100.80000","100.77952","4.81271","3.14936","0.80212","4.81271","100.77952"
"101.00000","100.97962","4.81513","3.15561","0.80252","4.81513","100.97962"
"101.20000","101.17950","4.74319","3.16186","0.79053","4.74319","101.17950"
"101.40000","101.37965","4.84795","3.16811","0.80799","4.84795","101.37965"
"101.60000","101.57947","4.82504","3.17436","0.80417","4.82504","101.57947"
"101.80000","101.77962","4.88734","3.18061","0.81456","4.88734","101.77962"
"102.00000","101.97943","4.85461","3.18686","0.80910","4.85461","101.97943"
"102.20000","102.17969","4.96086","3.19312","0.82681","4.96086","102.17969"
"102.40000","102.37944","4.92029","3.19936","0.82005","4.92029","102.37944"
"102.60000","102.57962","4.93459","3.20561","0.82243","4.93459","102.57962"
"102.80000","102.77944","4.94011","3.21186","0.82335","4.94011","102.77944"
"103.00000","102.97960","4.94054","3.21811","0.82342","4.94054","102.97960"
"103.20000","103.17949","4.92031","3.22436","0.82005","4.92031","103.17949"
"103.40000","103.37961","4.95900","3.23061","0.82650","4.95900","103.37961"
"103.60000","103.57946","5.01709","3.23686","0.83618","5.01709","103.57946"
"103.80000","103.77962","4.98418","3.24311","0.83070","4.98418","103.77962"
"104.00000","103.97937","4.98563","3.24936","0.83094","4.98563","103.97937"
"104.20000","104.17959","4.99754","3.25561","0.83292","4.99754","104.17959"
"104.40000","104.37940","4.95555","3.26186","0.82593","4.95555","104.37940"
"104.60000","104.57959","4.99084","3.26811","0.83181","4.99084","104.57959"
"104.80000","104.77941","5.03857","3.27436","0.83976","5.03857","104.77941"
"105.00000","104.97958","5.04263","3.28061","0.84044","5.04263","104.97958"
"105.20000","105.17941","5.06658","3.28686","0.84443","5.06658","105.17941"
"105.40000","105.37956","5.09818","3.29311","0.84970","5.09818","105.37956"
"105.60000","105.57946","5.05323","3.29936","0.84220","5.05323","105.57946"
"105.80000","105.77956","5.08207","3.30561","0.84701","5.08207","105.77956"
"106.00000","105.97942","5.06914","3.31186","0.84486","5.06914","105.97942"
"106.20000","106.17956","5.16967","3.31811","0.86161","5.16967","106.17956"
"106.40000","106.37938","5.15700","3.32436","0.85950","5.15700","106.37938"
"106.60000","106.57957","5.23165","3.33061","0.87194","5.23165","106.57957"
"106.80000","106.77936","5.24690","3.33685","0.87448","5.24690","106.77936"
"107.00000","106.97958","5.26897","3.34311","0.87816","5.26897","106.97958"
"107.20000","107.17939","5.19913","3.34936","0.86652","5.19913","107.17939"
"107.40000","107.37949","5.16912","3.35561","0.86152","5.16912","107.37949"
"107.60000","107.57938","5.22159","3.36186","0.87027","5.22159","107.57938"
"107.80000","107.77953","5.25806","3.36811","0.87634","5.25806","107.77953"
"108.00000","107.97940","5.27392","3.37436","0.87899","5.27392","107.97940"
"108.20000","108.17951","5.22371","3.38061","0.87062","5.22371","108.17951"
"108.40000","108.37939","5.39467","3.38686","0.89911","5.39467","108.37939"
"108.60000","108.57957","5.27641","3.39311","0.87940","5.27641","108.57957"
"108.80000","108.77934","5.38969","3.39935","0.89828","5.38969","108.77934"
"109.00000","108.97951","5.30542","3.40561","0.88424","5.30542","108.97951"
"109.20000","109.17937","5.34038","3.41186","0.89006","5.34038","109.17937"
"109.40000","109.37952","5.35598","3.41811","0.89266","5.35598","109.37952"
"109.60000","109.57940","5.47825","3.42436","0.91304","5.47825","109.57940"
"109.80000","109.77950","5.38100","3.43061","0.89683","5.38100","109.77950"
"110.00000","109.97940","5.45707","3.43686","0.90951","5.45707","109.97940"
"110.20000","110.17944","5.42465","3.44311","0.90411","5.42465","110.17944"
"110.40000","110.37940","5.39896","3.44936","0.89983","5.39896","110.37940"
"110.60000","110.57950","5.41373","3.45561","0.90229","5.41373","110.57950"
"110.80000","110.77940","5.39262","3.46186","0.89877","5.39262","110.77940"
"111.00000","110.97950","5.46181","3.46811","0.91030","5.46181","110.97950"
"111.20000","111.17942","5.52808","3.47436","0.92135","5.52808","111.17942"
"111.40000","111.37954","5.50459","3.48061","0.91743","5.50459","111.37954"
"111.60000","111.57937","5.42920","3.48686","0.90487","5.42920","111.57937"
"111.80000","111.77948","5.46606","3.49311","0.91101","5.46606","111.77948"
"112.00000","111.97943","2.79854","3.49936","0.46642","2.79854","111.97943"
"112.20000","112.17949","0.22150","3.50561","0.03692","0.22150","112.17949"
"112.40000","112.37939","0.13312","3.51186","0.02219","0.13312","112.37939"
"112.60000","112.57944","0.24298","3.51811","0.04050","0.24298","112.57944"
"112.65500","112.63460","0.19811","3.51983","0.03302","0.19811","112.63460"