File: 1silicon20.csv
Tenacity at Break (Standard),"0.25506",N/tex
Tensile extension at Break (Standard),"108.94954",mm
Tenacity at Yield ,,N/tex

Time,Extension,Load,Tensile strain (Extension),Tensile stress,Tenacity,Tensile extension
(s),(mm),(N),(mm/mm),(MPa),(N/tex),(mm)
"0.00000","0.00000","-0.00565","0.00000","-0.00094","-0.00565","0.00000"
"0.20000","0.17917","0.02853","0.00560","0.00475","0.02853","0.17917"
"0.40000","0.37952","-0.02285","0.01186","-0.00381","-0.02285","0.37952"
"0.60000","0.57951","0.00701","0.01811","0.00117","0.00701","0.57951"
"0.80000","0.77945","0.01883","0.02436","0.00314","0.01883","0.77945"
"1.00000","0.97951","0.04399","0.03061","0.00733","0.04399","0.97951"
"1.20000","1.17948","0.03571","0.03686","0.00595","0.03571","1.17948"
"1.40000","1.37948","0.07116","0.04311","0.01186","0.07116","1.37948"
"1.60000","1.57952","0.09481","0.04936","0.01580","0.09481","1.57952"
"1.80000","1.77955","0.14229","0.05561","0.02372","0.14229","1.77955"
"2.00000","1.97943","0.12041","0.06186","0.02007","0.12041","1.97943"
"2.20000","2.17953","0.17886","0.06811","0.02981","0.17886","2.17953"
"2.40000","2.37938","0.15172","0.07436","0.02529","0.15172","2.37938"
"2.60000","2.57952","0.10216","0.08061","0.01703","0.10216","2.57952"
"2.80000","2.77942","0.20558","0.08686","0.03426","0.20558","2.77942"
"3.00000","2.97951","0.13144","0.09311","0.02191","0.13144","2.97951"
"3.20000","3.17941","0.19861","0.09936","0.03310","0.19861","3.17941"
"3.40000","3.37947","0.20960","0.10561","0.03493","0.20960","3.37947"
"3.60000","3.57944","0.21168","0.11186","0.03528","0.21168","3.57944"
"3.80000","3.77950","0.27444","0.11811","0.04574","0.27444","3.77950"
"4.00000","3.97940","0.24553","0.12436","0.04092","0.24553","3.97940"
"4.20000","4.17949","0.22764","0.13061","0.03794","0.22764","4.17949"
"4.40000","4.37938","0.27734","0.13686","0.04622","0.27734","4.37938"
"4.60000","4.57956","0.21602","0.14311","0.03600","0.21602","4.57956"
"4.80000","4.77934","0.26776","0.14935","0.04463","0.26776","4.77934"
"5.00000","4.97949","0.26618","0.15561","0.04436","0.26618","4.97949"
"5.20000","5.17941","0.27704","0.16186","0.04617","0.27704","5.17941"
"5.40000","5.37953","0.33278","0.16811","0.05546","0.33278","5.37953"
"5.60000","5.57938","0.30758","0.17436","0.05126","0.30758","5.57938"
"5.80000","5.77944","0.34192","0.18061","0.05699","0.34192","5.77944"
"6.00000","5.97938","0.29243","0.18686","0.04874","0.29243","5.97938"
"6.20000","6.17948","0.32197","0.19311","0.05366","0.32197","6.17948"
"6.40000","6.37945","0.32105","0.19936","0.05351","0.32105","6.37945"
"6.60000","6.57950","0.41213","0.20561","0.06869","0.41213","6.57950"
"6.80000","6.77933","0.34872","0.21185","0.05812","0.34872","6.77933"
"7.00000","6.97957","0.34627","0.21811","0.05771","0.34627","6.97957"
"7.20000","7.17929","0.40861","0.22435","0.06810","0.40861","7.17929"
"7.40000","7.37951","0.39263","0.23061","0.06544","0.39263","7.37951"
"7.60000","7.57942","0.35311","0.23686","0.05885","0.35311","7.57942"
"7.80000","7.77950","0.45871","0.24311","0.07645","0.45871","7.77950"
"8.00000","7.97942","0.42292","0.24936","0.07049","0.42292","7.97942"
"8.20000","8.17955","0.39447","0.25561","0.06575","0.39447","8.17955"
"8.40000","8.37939","0.39381","0.26186","0.06563","0.39381","8.37939"
"8.60000","8.57947","0.45427","0.26811","0.07571","0.45427","8.57947"
"8.80000","8.77942","0.40681","0.27436","0.06780","0.40681","8.77942"
"9.00000","8.97957","0.52774","0.28061","0.08796","0.52774","8.97957"
"9.20000","9.17936","0.44827","0.28685","0.07471","0.44827","9.17936"
"9.40000","9.37960","0.41382","0.29311","0.06897","0.41382","9.37960"
"9.60000","9.57930","0.52908","0.29935","0.08818","0.52908","9.57930"
"9.80000","9.77950","0.44403","0.30561","0.07401","0.44403","9.77950"
"10.00000","9.97943","0.50822","0.31186","0.08470","0.50822","9.97943"
"10.20000","10.17955","0.51125","0.31811","0.08521","0.51125","10.17955"
"10.40000","10.37940","0.54022","0.32436","0.09004","0.54022","10.37940"
"10.60000","10.57950","0.54891","0.33061","0.09148","0.54891","10.57950"
"10.80000","10.77941","0.52717","0.33686","0.08786","0.52717","10.77941"
"11.00000","10.97960","0.53536","0.34311","0.08923","0.53536","10.97960"
"11.20000","11.17943","0.57237","0.34936","0.09539","0.57237","11.17943"
"11.40000","11.37957","0.53783","0.35561","0.08964","0.53783","11.37957"
"11.60000","11.57938","0.50047","0.36186","0.08341","0.50047","11.57938"
"11.80000","11.77963","0.58135","0.36811","0.09689","0.58135","11.77963"
"12.00000","11.97940","0.56683","0.37436","0.09447","0.56683","11.97940"
"12.20000","12.17954","0.57732","0.38061","0.09622","0.57732","12.17954"
"12.40000","12.37946","0.58523","0.38686","0.09754","0.58523","12.37946"
"12.60000","12.57958","0.56762","0.39311","0.09460","0.56762","12.57958"
"12.80000","12.77946","0.61344","0.39936","0.10224","0.61344","12.77946"
"13.00000","12.97958","0.67055","0.40561","0.11176","0.67055","12.97958"
"13.20000","13.17949","0.65752","0.41186","0.10959","0.65752","13.17949"
"13.40000","13.37962","0.62462","0.41811","0.10410","0.62462","13.37962"
"13.60000","13.57944","0.65813","0.42436","0.10969","0.65813","13.57944"
"13.80000","13.77965","0.64032","0.43061","0.10672","0.64032","13.77965"
"14.00000","13.97941","0.63189","0.43686","0.10531","0.63189","13.97941"
"14.20000","14.17962","0.71523","0.44311","0.11920","0.71523","14.17962"
"14.40000","14.37946","0.64050","0.44936","0.10675","0.64050","14.37946"
"14.60000","14.57962","0.61064","0.45561","0.10177","0.61064","14.57962"
"14.80000","14.77951","0.68607","0.46186","0.11435","0.68607","14.77951"
"15.00000","14.97962","0.70279","0.46811","0.11713","0.70279","14.97962"
"15.20000","15.17946","0.75310","0.47436","0.12552","0.75310","15.17946"
"15.40000","15.37961","0.72003","0.48061","0.12000","0.72003","15.37961"
"15.60000","15.57944","0.74043","0.48686","0.12340","0.74043","15.57944"
"15.80000","15.77964","0.73940","0.49311","0.12323","0.73940","15.77964"
"16.00000","15.97945","0.76206","0.49936","0.12701","0.76206","15.97945"
"16.20000","16.17969","0.74865","0.50562","0.12478","0.74865","16.17969"
"16.40000","16.37951","0.72420","0.51186","0.12070","0.72420","16.37951"
"16.60000","16.57965","0.78001","0.51811","0.13000","0.78001","16.57965"
"16.80000","16.77950","0.72823","0.52436","0.12137","0.72823","16.77950"
"17.00000","16.97958","0.82467","0.53061","0.13745","0.82467","16.97958"
"17.20000","17.17953","0.79164","0.53686","0.13194","0.79164","17.17953"
"17.40000","17.37966","0.79282","0.54311","0.13214","0.79282","17.37966"
"17.60000","17.57945","0.81341","0.54936","0.13557","0.81341","17.57945"
"17.80000","17.77963","0.83519","0.55561","0.13920","0.83519","17.77963"
"18.00000","17.97950","0.72752","0.56186","0.12125","0.72752","17.97950"
"18.20000","18.17967","0.86159","0.56811","0.14360","0.86159","18.17967"
"18.40000","18.37945","0.87625","0.57436","0.14604","0.87625","18.37945"
"18.60000","18.57963","0.80473","0.58061","0.13412","0.80473","18.57963"
"18.80000","18.77951","0.86376","0.58686","0.14396","0.86376","18.77951"
"19.00000","18.97959","0.92277","0.59311","0.15379","0.92277","18.97959"
"19.20000","19.17948","0.80199","0.59936","0.13366","0.80199","19.17948"
"19.40000","19.37963","0.87869","0.60561","0.14645","0.87869","19.37963"
"19.60000","19.57949","0.93282","0.61186","0.15547","0.93282","19.57949"
"19.80000","19.77962","0.85802","0.61811","0.14300","0.85802","19.77962"
"20.00000","19.97948","0.92612","0.62436","0.15435","0.92612","19.97948"
"20.20000","20.17965","0.96400","0.63061","0.16067","0.96400","20.17965"
"20.40000","20.37945","0.87048","0.63686","0.14508","0.87048","20.37945"
"20.60000","20.57965","0.91125","0.64311","0.15187","0.91125","20.57965"
"20.80000","20.77945","0.96087","0.64936","0.16015","0.96087","20.77945"
"21.00000","20.97961","0.92786","0.65561","0.15464","0.92786","20.97961"
"21.20000","21.17947","0.86094","0.66186","0.14349","0.86094","21.17947"
"21.40000","21.37958","1.02081","0.66811","0.17013","1.02081","21.37958"
"21.60000","21.57949","0.94671","0.67436","0.15779","0.94671","21.57949"
"21.80000","21.77961","0.94817","0.68061","0.15803","0.94817","21.77961"
"22.00000","21.97934","1.02426","0.68685","0.17071","1.02426","21.97934"
"22.20000","22.17961","0.98080","0.69311","0.16347","0.98080","22.17961"
"22.40000","22.37945","1.02602","0.69936","0.17100","1.02602","22.37945"
"22.60000","22.57962","1.05265","0.70561","0.17544","1.05265","22.57962"
"22.80000","22.77938","1.05423","0.71186","0.17571","1.05423","22.77938"
"23.00000","22.97962","1.06486","0.71811","0.17748","1.06486","22.97962"
"23.20000","23.17944","1.08303","0.72436","0.18051","1.08303","23.17944"
"23.40000","23.37954","1.06834","0.73061","0.17806","1.06834","23.37954"
"23.60000","23.57944","1.02168","0.73686","0.17028","1.02168","23.57944"
"23.80000","23.77951","1.05998","0.74311","0.17666","1.05998","23.77951"
"24.00000","23.97942","1.03678","0.74936","0.17280","1.03678","23.97942"
"24.20000","24.17953","1.07913","0.75561","0.17986","1.07913","24.17953"
"24.40000","24.37942","1.03860","0.76186","0.17310","1.03860","24.37942"
"24.60000","24.57955","1.15448","0.76811","0.19241","1.15448","24.57955"
"24.80000","24.77939","1.10632","0.77436","0.18439","1.10632","24.77939"
"25.00000","24.97957","1.11208","0.78061","0.18535","1.11208","24.97957"
"25.20000","25.17941","1.18260","0.78686","0.19710","1.18260","25.17941"
"25.40000","25.37957","1.13656","0.79311","0.18943","1.13656","25.37957"
"25.60000","25.57933","1.17754","0.79935","0.19626","1.17754","25.57933"
"25.80000","25.77950","1.23333","0.80561","0.20556","1.23333","25.77950"
"26.00000","25.97941","1.18505","0.81186","0.19751","1.18505","25.97941"
"26.20000","26.17950","1.18429","0.81811","0.19738","1.18429","26.17950"
"26.40000","26.37942","1.21186","0.82436","0.20198","1.21186","26.37942"
"26.60000","26.57952","1.21395","0.83061","0.20233","1.21395","26.57952"
"26.80000","26.77938","1.18721","0.83686","0.19787","1.18721","26.77938"
"27.00000","26.97953","1.26597","0.84311","0.21100","1.26597","26.97953"
"27.20000","27.17935","1.26838","0.84935","0.21140","1.26838","27.17935"
"27.40000","27.37952","1.22199","0.85561","0.20367","1.22199","27.37952"
"27.60000","27.57934","1.23040","0.86185","0.20507","1.23040","27.57934"
"27.80000","27.77952","1.27758","0.86811","0.21293","1.27758","27.77952"
"28.00000","27.97941","1.25418","0.87436","0.20903","1.25418","27.97941"
"28.20000","28.17951","1.24393","0.88061","0.20732","1.24393","28.17951"
"28.40000","28.37941","1.27540","0.88686","0.21257","1.27540","28.37941"
"28.60000","28.57943","1.26719","0.89311","0.21120","1.26719","28.57943"
"28.80000","28.77940","1.28158","0.89936","0.21360","1.28158","28.77940"
"29.00000","28.97953","1.33734","0.90561","0.22289","1.33734","28.97953"
"29.20000","29.17938","1.29582","0.91186","0.21597","1.29582","29.17938"
"29.40000","29.37952","1.30205","0.91811","0.21701","1.30205","29.37952"
"29.60000","29.57935","1.37818","0.92435","0.22970","1.37818","29.57935"
"29.80000","29.77949","1.30136","0.93061","0.21689","1.30136","29.77949"
"30.00000","29.97940","1.30879","0.93686","0.21813","1.30879","29.97940"
"30.20000","30.17950","1.36695","0.94311","0.22782","1.36695","30.17950"
"30.40000","30.37936","1.32630","0.94935","0.22105","1.32630","30.37936"
"30.60000","30.57941","1.40368","0.95561","0.23395","1.40368","30.57941"
"30.80000","30.77945","1.31128","0.96186","0.21855","1.31128","30.77945"
"31.00000","30.97941","1.41129","0.96811","0.23521","1.41129","30.97941"
"31.20000","31.17940","1.39996","0.97436","0.23333","1.39996","31.17940"
"31.40000","31.37957","1.41124","0.98061","0.23521","1.41124","31.37957"
"31.60000","31.57941","1.47581","0.98686","0.24597","1.47581","31.57941"
"31.80000","31.77952","1.39102","0.99311","0.23184","1.39102","31.77952"
"32.00000","31.97936","1.39990","0.99936","0.23332","1.39990","31.97936"
"32.20000","32.17952","1.47668","1.00561","0.24611","1.47668","32.17952"
"32.40000","32.37941","1.47400","1.01186","0.24567","1.47400","32.37941"
"32.60000","32.57954","1.45540","1.01811","0.24257","1.45540","32.57954"
"32.80000","32.77944","1.45905","1.02436","0.24318","1.45905","32.77944"
"33.00000","32.97945","1.49104","1.03061","0.24851","1.49104","32.97945"
"33.20000","33.17949","1.49397","1.03686","0.24900","1.49397","33.17949"
"33.40000","33.37946","1.50108","1.04311","0.25018","1.50108","33.37946"
"33.60000","33.57942","1.51779","1.04936","0.25296","1.51779","33.57942"
"33.80000","33.77956","1.49660","1.05561","0.24943","1.49660","33.77956"
"34.00000","33.97943","1.56284","1.06186","0.26047","1.56284","33.97943"
"34.20000","34.17955","1.61195","1.06811","0.26866","1.61195","34.17955"
"34.40000","34.37943","1.55798","1.07436","0.25966","1.55798","34.37943"
"34.60000","34.57956","1.61910","1.08061","0.26985","1.61910","34.57956"
"34.80000","34.77946","1.60800","1.08686","0.26800","1.60800","34.77946"
"35.00000","34.97958","1.54902","1.09311","0.25817","1.54902","34.97958"
"35.20000","35.17949","1.57529","1.09936","0.26255","1.57529","35.17949"
"35.40000","35.37947","1.64381","1.10561","0.27397","1.64381","35.37947"
"35.60000","35.57951","1.56184","1.11186","0.26031","1.56184","35.57951"
"35.80000","35.77950","1.57672","1.11811","0.26279","1.57672","35.77950"
"36.00000","35.97943","1.65369","1.12436","0.27562","1.65369","35.97943"
"36.20000","36.17957","1.61030","1.13061","0.26838","1.61030","36.17957"
"36.40000","36.37953","1.68720","1.13686","0.28120","1.68720","36.37953"
"36.60000","36.57957","1.66231","1.14311","0.27705","1.66231","36.57957"
"36.80000","36.77947","1.68497","1.14936","0.28083","1.68497","36.77947"
"37.00000","36.97955","1.67156","1.15561","0.27859","1.67156","36.97955"
"37.20000","37.17952","1.72040","1.16186","0.28673","1.72040","37.17952"
"37.40000","37.37953","1.70737","1.16811","0.28456","1.70737","37.37953"
"37.60000","37.57954","1.70491","1.17436","0.28415","1.70491","37.57954"
"37.80000","37.77953","1.74207","1.18061","0.29035","1.74207","37.77953"
"38.00000","37.97955","1.73773","1.18686","0.28962","1.73773","37.97955"
"38.20000","38.17956","1.71993","1.19311","0.28665","1.71993","38.17956"
"38.40000","38.37952","1.74458","1.19936","0.29076","1.74458","38.37952"
"38.60000","38.57964","1.80109","1.20561","0.30018","1.80109","38.57964"
"38.80000","38.77957","1.70582","1.21186","0.28430","1.70582","38.77957"
"39.00000","38.97948","1.73803","1.21811","0.28967","1.73803","38.97948"
"39.20000","39.17952","1.80299","1.22436","0.30050","1.80299","39.17952"
"39.40000","39.37959","1.76756","1.23061","0.29459","1.76756","39.37959"
"39.60000","39.57958","1.81205","1.23686","0.30201","1.81205","39.57958"
"39.80000","39.77954","1.82450","1.24311","0.30408","1.82450","39.77954"
"40.00000","39.97960","1.78236","1.24936","0.29706","1.78236","39.97960"
"40.20000","40.17955","1.81162","1.25561","0.30194","1.81162","40.17955"
"40.40000","40.37959","1.88068","1.26186","0.31345","1.88068","40.37959"
"40.60000","40.57954","1.87694","1.26811","0.31282","1.87694","40.57954"
"40.80000","40.77947","1.84021","1.27436","0.30670","1.84021","40.77947"
"41.00000","40.97957","1.79713","1.28061","0.29952","1.79713","40.97957"
"41.20000","41.17957","1.84808","1.28686","0.30801","1.84808","41.17957"
"41.40000","41.37955","1.88946","1.29311","0.31491","1.88946","41.37955"
"41.60000","41.57955","1.95094","1.29936","0.32516","1.95094","41.57955"
"41.80000","41.77953","1.87153","1.30561","0.31192","1.87153","41.77953"
"42.00000","41.97958","1.90864","1.31186","0.31811","1.90864","41.97958"
"42.20000","42.17955","1.98842","1.31811","0.33140","1.98842","42.17955"
"42.40000","42.37957","1.95746","1.32436","0.32624","1.95746","42.37957"
"42.60000","42.57951","1.99287","1.33061","0.33214","1.99287","42.57951"
"42.80000","42.77953","1.99350","1.33686","0.33225","1.99350","42.77953"
"43.00000","42.97955","1.94537","1.34311","0.32423","1.94537","42.97955"
"43.20000","43.17952","1.94577","1.34936","0.32430","1.94577","43.17952"
"43.40000","43.37955","2.06554","1.35561","0.34426","2.06554","43.37955"
"43.60000","43.57954","2.07317","1.36186","0.34553","2.07317","43.57954"
"43.80000","43.77949","2.01293","1.36811","0.33549","2.01293","43.77949"
"44.00000","43.97957","2.10683","1.37436","0.35114","2.10683","43.97957"
"44.20000","44.17951","2.05569","1.38061","0.34261","2.05569","44.17951"
"44.40000","44.37956","2.00487","1.38686","0.33414","2.00487","44.37956"
"44.60000","44.57944","2.03012","1.39311","0.33835","2.03012","44.57944"
"44.80000","44.77954","2.08445","1.39936","0.34741","2.08445","44.77954"
"45.00000","44.97953","2.11915","1.40561","0.35319","2.11915","44.97953"
"45.20000","45.17949","2.03889","1.41186","0.33981","2.03889","45.17949"
"45.40000","45.37949","2.06574","1.41811","0.34429","2.06574","45.37949"
"45.60000","45.57951","2.11673","1.42436","0.35279","2.11673","45.57951"
"45.80000","45.77948","2.13794","1.43061","0.35632","2.13794","45.77948"
"46.00000","45.97953","2.20585","1.43686","0.36764","2.20585","45.97953"
"46.20000","46.17945","2.16722","1.44311","0.36120","2.16722","46.17945"
"46.40000","46.37958","2.16810","1.44936","0.36135","2.16810","46.37958"
"46.60000","46.57945","2.19169","1.45561","0.36528","2.19169","46.57945"
"46.80000","46.77956","2.22559","1.46186","0.37093","2.22559","46.77956"
"47.00000","46.97945","2.21044","1.46811","0.36841","2.21044","46.97945"
"47.20000","47.17949","2.27346","1.47436","0.37891","2.27346","47.17949"
"47.40000","47.37942","2.22785","1.48061","0.37131","2.22785","47.37942"
"47.60000","47.57948","2.29985","1.48686","0.38331","2.29985","47.57948"
"47.80000","47.77947","2.26450","1.49311","0.37742","2.26450","47.77947"
"48.00000","47.97949","2.28259","1.49936","0.38043","2.28259","47.97949"
"48.20000","48.17940","2.21352","1.50561","0.36892","2.21352","48.17940"
"48.40000","48.37952","2.25548","1.51186","0.37591","2.25548","48.37952"
"48.60000","48.57940","2.36258","1.51811","0.39376","2.36258","48.57940"
"48.80000","48.77955","2.25085","1.52436","0.37514","2.25085","48.77955"
"49.00000","48.97937","2.35348","1.53061","0.39225","2.35348","48.97937"
"49.20000","49.17957","2.41407","1.53686","0.40235","2.41407","49.17957"
"49.40000","49.37943","2.35880","1.54311","0.39313","2.35880","49.37943"
"49.60000","49.57947","2.35987","1.54936","0.39331","2.35987","49.57947"
"49.80000","49.77942","2.32453","1.55561","0.38742","2.32453","49.77942"
"50.00000","49.97947","2.42450","1.56186","0.40408","2.42450","49.97947"
"50.20000","50.17941","2.38888","1.56811","0.39815","2.38888","50.17941"
"50.40000","50.37950","2.37388","1.57436","0.39565","2.37388","50.37950"
"50.60000","50.57941","2.49178","1.58061","0.41530","2.49178","50.57941"
"50.80000","50.77946","2.46187","1.58686","0.41031","2.46187","50.77946"
"51.00000","50.97932","2.43499","1.59310","0.40583","2.43499","50.97932"
"51.20000","51.17955","2.53817","1.59936","0.42303","2.53817","51.17955"
"51.40000","51.37942","2.42806","1.60561","0.40468","2.42806","51.37942"
"51.60000","51.57953","2.47228","1.61186","0.41205","2.47228","51.57953"
"51.80000","51.77941","2.57592","1.61811","0.42932","2.57592","51.77941"
"52.00000","51.97950","2.47087","1.62436","0.41181","2.47087","51.97950"
"52.20000","52.17942","2.47806","1.63061","0.41301","2.47806","52.17942"
"52.40000","52.37946","2.55626","1.63686","0.42604","2.55626","52.37946"
"52.60000","52.57941","2.53024","1.64311","0.42171","2.53024","52.57941"
"52.80000","52.77950","2.52695","1.64936","0.42116","2.52695","52.77950"
"53.00000","52.97937","2.59625","1.65561","0.43271","2.59625","52.97937"
"53.20000","53.17951","2.60888","1.66186","0.43481","2.60888","53.17951"
"53.40000","53.37936","2.64359","1.66811","0.44060","2.64359","53.37936"
"53.60000","53.57954","2.67808","1.67436","0.44635","2.67808","53.57954"
"53.80000","53.77936","2.72890","1.68060","0.45482","2.72890","53.77936"
"54.00000","53.97955","2.61881","1.68686","0.43647","2.61881","53.97955"
"54.20000","54.17938","2.58519","1.69311","0.43086","2.58519","54.17938"
"54.40000","54.37954","2.76137","1.69936","0.46023","2.76137","54.37954"
"54.60000","54.57944","2.73058","1.70561","0.45510","2.73058","54.57944"
"54.80000","54.77952","2.72413","1.71186","0.45402","2.72413","54.77952"
"55.00000","54.97939","2.73000","1.71811","0.45500","2.73000","54.97939"
"55.20000","55.17960","2.74501","1.72436","0.45750","2.74501","55.17960"
"55.40000","55.37943","2.69573","1.73061","0.44929","2.69573","55.37943"
"55.60000","55.57961","2.70163","1.73686","0.45027","2.70163","55.57961"
"55.80000","55.77938","2.77553","1.74311","0.46259","2.77553","55.77938"
"56.00000","55.97955","2.76631","1.74936","0.46105","2.76631","55.97955"
"56.20000","56.17944","2.82934","1.75561","0.47156","2.82934","56.17944"
"56.40000","56.37960","2.83906","1.76186","0.47318","2.83906","56.37960"
"56.60000","56.57943","2.84259","1.76811","0.47377","2.84259","56.57943"
"56.80000","56.77954","2.82831","1.77436","0.47139","2.82831","56.77954"
"57.00000","56.97949","2.84791","1.78061","0.47465","2.84791","56.97949"
"57.20000","57.17953","2.89587","1.78686","0.48265","2.89587","57.17953"
"57.40000","57.37943","2.90463","1.79311","0.48411","2.90463","57.37943"
"57.60000","57.57966","2.97707","1.79936","0.49618","2.97707","57.57966"
"57.80000","57.77940","2.95304","1.80561","0.49217","2.95304","57.77940"
"58.00000","57.97963","2.93554","1.81186","0.48926","2.93554","57.97963"
"58.20000","58.17943","2.99888","1.81811","0.49981","2.99888","58.17943"
"58.40000","58.37963","2.97807","1.82436","0.49635","2.97807","58.37963"
"58.60000","58.57946","2.99470","1.83061","0.49912","2.99470","58.57946"
"58.80000","58.77962","2.96670","1.83686","0.49445","2.96670","58.77962"
"59.00000","58.97947","3.07255","1.84311","0.51209","3.07255","58.97947"
"59.20000","59.17958","3.01425","1.84936","0.50238","3.01425","59.17958"
"59.40000","59.37951","3.03330","1.85561","0.50555","3.03330","59.37951"
"59.60000","59.57959","3.04672","1.86186","0.50779","3.04672","59.57959"
"59.80000","59.77944","3.08911","1.86811","0.51485","3.08911","59.77944"
"60.00000","59.97968","3.09186","1.87436","0.51531","3.09186","59.97968"
"60.20000","60.17945","3.22411","1.88061","0.53735","3.22411","60.17945"
"60.40000","60.37965","3.11357","1.88686","0.51893","3.11357","60.37965"
"60.60000","60.57943","3.08799","1.89311","0.51467","3.08799","60.57943"
"60.80000","60.77961","3.18922","1.89936","0.53154","3.18922","60.77961"
"61.00000","60.97950","3.20021","1.90561","0.53337","3.20021","60.97950"
"61.20000","61.17967","3.09201","1.91186","0.51533","3.09201","61.17967"
"61.40000","61.37950","3.19375","1.91811","0.53229","3.19375","61.37950"
"61.60000","61.57962","3.19984","1.92436","0.53331","3.19984","61.57962"
"61.80000","61.77953","3.23266","1.93061","0.53878","3.23266","61.77953"
"62.00000","61.97961","3.23902","1.93686","0.53984","3.23902","61.97961"
"62.20000","62.17943","3.28844","1.94311","0.54807","3.28844","62.17943"
"62.40000","62.37967","3.21990","1.94936","0.53665","3.21990","62.37967"
"62.60000","62.57948","3.31368","1.95561","0.55228","3.31368","62.57948"
"62.80000","62.77968","3.25543","1.96186","0.54257","3.25543","62.77968"
"63.00000","62.97946","3.28893","1.96811","0.54815","3.28893","62.97946"
"63.20000","63.17963","3.32928","1.97436","0.55488","3.32928","63.17963"
"63.40000","63.37950","3.37078","1.98061","0.56180","3.37078","63.37950"
"63.60000","63.57965","3.29468","1.98686","0.54911","3.29468","63.57965"
"63.80000","63.77950","3.42293","1.99311","0.57049","3.42293","63.77950"
"64.00000","63.97963","3.43287","1.99936","0.57214","3.43287","63.97963"
"64.20000","64.17949","3.38657","2.00561","0.56443","3.38657","64.17949"
"64.40000","64.37956","3.37886","2.01186","0.56314","3.37886","64.37956"
"64.60000","64.57944","3.50348","2.01811","0.58391","3.50348","64.57944"
"64.80000","64.77972","3.45803","2.02437","0.57634","3.45803","64.77972"
"65.00000","64.97948","3.46986","2.03061","0.57831","3.46986","64.97948"
"65.20000","65.17960","3.48539","2.03686","0.58090","3.48539","65.17960"
"65.40000","65.37949","3.50767","2.04311","0.58461","3.50767","65.37949"
"65.60000","65.57960","3.44636","2.04936","0.57439","3.44636","65.57960"
"65.80000","65.77948","3.55214","2.05561","0.59202","3.55214","65.77948"
"66.00000","65.97958","3.58763","2.06186","0.59794","3.58763","65.97958"
"66.20000","66.17947","3.51667","2.06811","0.58611","3.51667","66.17947"
"66.40000","66.37958","3.56008","2.07436","0.59335","3.56008","66.37958"
"66.60000","66.57944","3.60350","2.08061","0.60058","3.60350","66.57944"
"66.80000","66.77963","3.62127","2.08686","0.60354","3.62127","66.77963"
"67.00000","66.97942","3.52747","2.09311","0.58791","3.52747","66.97942"
"67.20000","67.17963","3.73996","2.09936","0.62333","3.73996","67.17963"
"67.40000","67.37943","3.66029","2.10561","0.61005","3.66029","67.37943"
"67.60000","67.57957","3.65649","2.11186","0.60941","3.65649","67.57957"
"67.80000","67.77944","3.70557","2.11811","0.61760","3.70557","67.77944"
"68.00000","67.97956","3.73204","2.12436","0.62201","3.73204","67.97956"
"68.20000","68.17945","3.72567","2.13061","0.62094","3.72567","68.17945"
"68.40000","68.37958","3.72735","2.13686","0.62122","3.72735","68.37958"
"68.60000","68.57941","3.72752","2.14311","0.62125","3.72752","68.57941"
"68.80000","68.77959","3.70720","2.14936","0.61787","3.70720","68.77959"
"69.00000","68.97936","3.75918","2.15561","0.62653","3.75918","68.97936"
"69.20000","69.17957","3.77465","2.16186","0.62911","3.77465","69.17957"
"69.40000","69.37940","3.81882","2.16811","0.63647","3.81882","69.37940"
"69.60000","69.57958","3.81947","2.17436","0.63658","3.81947","69.57958"
"69.80000","69.77942","3.81693","2.18061","0.63616","3.81693","69.77942"
"70.00000","69.97952","3.81852","2.18686","0.63642","3.81852","69.97952"
"70.20000","70.17945","3.84739","2.19311","0.64123","3.84739","70.17945"
"70.40000","70.37955","3.89947","2.19936","0.64991","3.89947","70.37955"
"70.60000","70.57939","3.88186","2.20561","0.64698","3.88186","70.57939"
"70.80000","70.77952","3.94764","2.21186","0.65794","3.94764","70.77952"
"71.00000","70.97939","3.96196","2.21811","0.66033","3.96196","70.97939"
"71.20000","71.17954","3.89974","2.22436","0.64996","3.89974","71.17954"
"71.40000","71.37934","3.96818","2.23060","0.66136","3.96818","71.37934"
"71.60000","71.57957","3.97871","2.23686","0.66312","3.97871","71.57957"
"71.80000","71.77941","3.90069","2.24311","0.65011","3.90069","71.77941"
"72.00000","71.97948","3.96685","2.24936","0.66114","3.96685","71.97948"
"72.20000","72.17937","4.06040","2.25561","0.67673","4.06040","72.17937"
"72.40000","72.37949","4.01983","2.26186","0.66997","4.01983","72.37949"
"72.60000","72.57943","4.08407","2.26811","0.68068","4.08407","72.57943"
"72.80000","72.77949","4.06275","2.27436","0.67712","4.06275","72.77949"
"73.00000","72.97937","4.09111","2.28061","0.68185","4.09111","72.97937"
"73.20000","73.17952","4.09220","2.28686","0.68203","4.09220","73.17952"
"73.40000","73.37936","4.19470","2.29310","0.69912","4.19470","73.37936"
"73.60000","73.57952","4.12916","2.29936","0.68819","4.12916","73.57952"
"73.80000","73.77934","4.10233","2.30560","0.68372","4.10233","73.77934"
"74.00000","73.97952","4.23813","2.31186","0.70636","4.23813","73.97952"
"74.20000","74.17937","4.15306","2.31811","0.69218","4.15306","74.17937"
"74.40000","74.37949","4.14397","2.32436","0.69066","4.14397","74.37949"
"74.60000","74.57940","4.19924","2.33061","0.69987","4.19924","74.57940"
"74.80000","74.77946","4.25395","2.33686","0.70899","4.25395","74.77946"
"75.00000","74.97941","4.18092","2.34311","0.69682","4.18092","74.97941"
"75.20000","75.17948","4.25614","2.34936","0.70936","4.25614","75.17948"
"75.40000","75.37939","4.27125","2.35561","0.71187","4.27125","75.37939"
"75.60000","75.57948","4.26311","2.36186","0.71052","4.26311","75.57948"
"75.80000","75.77937","4.34827","2.36811","0.72471","4.34827","75.77937"
"76.00000","75.97955","4.37135","2.37436","0.72856","4.37135","75.97955"
"76.20000","76.17940","4.34177","2.38061","0.72363","4.34177","76.17940"
"76.40000","76.37950","4.34710","2.38686","0.72452","4.34710","76.37950"
"76.60000","76.57941","4.37424","2.39311","0.72904","4.37424","76.57941"
"76.80000","76.77952","4.34702","2.39936","0.72450","4.34702","76.77952"
"77.00000","76.97945","4.38729","2.40561","0.73121","4.38729","76.97945"
"77.20000","77.17947","4.45829","2.41186","0.74305","4.45829","77.17947"
"77.40000","77.37943","4.45171","2.41811","0.74195","4.45171","77.37943"
"77.60000","77.57950","4.43535","2.42436","0.73923","4.43535","77.57950"
"77.80000","77.77943","4.52734","2.43061","0.75456","4.52734","77.77943"
"78.00000","77.97952","4.50142","2.43686","0.75024","4.50142","77.97952"
"78.20000","78.17944","4.48530","2.44311","0.74755","4.48530","78.17944"
"78.40000","78.37957","4.50078","2.44936","0.75013","4.50078","78.37957"
"78.60000","78.57941","4.53036","2.45561","0.75506","4.53036","78.57941"
"78.80000","78.77956","4.53013","2.46186","0.75502","4.53013","78.77956"
"79.00000","78.97950","4.56319","2.46811","0.76053","4.56319","78.97950"
"79.20000","79.17950","4.55060","2.47436","0.75843","4.55060","79.17950"
"79.40000","79.37947","4.59896","2.48061","0.76649","4.59896","79.37947"
"79.60000","79.57951","4.59735","2.48686","0.76623","4.59735","79.57951"
"79.80000","79.77950","4.59926","2.49311","0.76654","4.59926","79.77950"
"80.00000","79.97954","4.61936","2.49936","0.76989","4.61936","79.97954"
"80.20000","80.17947","4.66316","2.50561","0.77719","4.66316","80.17947"
"80.40000","80.37955","4.71032","2.51186","0.78505","4.71032","80.37955"
"80.60000","80.57948","4.67361","2.51811","0.77893","4.67361","80.57948"
"80.80000","80.77960","4.70518","2.52436","0.78420","4.70518","80.77960"
"81.00000","80.97951","4.74319","2.53061","0.79053","4.74319","80.97951"
"81.20000","81.17953","4.76712","2.53686","0.79452","4.76712","81.17953"
"81.40000","81.37946","4.81295","2.54311","0.80216","4.81295","81.37946"
"81.60000","81.57958","4.79007","2.54936","0.79835","4.79007","81.57958"
"81.80000","81.77956","4.79059","2.55561","0.79843","4.79059","81.77956"
"82.00000","81.97948","4.86226","2.56186","0.81038","4.86226","81.97948"
"82.20000","82.17954","4.72922","2.56811","0.78820","4.72922","82.17954"
"82.40000","82.37958","4.77138","2.57436","0.79523","4.77138","82.37958"
"82.60000","82.57954","4.79023","2.58061","0.79837","4.79023","82.57954"
"82.80000","82.77956","4.77042","2.58686","0.79507","4.77042","82.77956"
"83.00000","82.97945","4.83283","2.59311","0.80547","4.83283","82.97945"
"83.20000","83.17962","4.81742","2.59936","0.80290","4.81742","83.17962"
"83.40000","83.37949","4.90525","2.60561","0.81754","4.90525","83.37949"
"83.60000","83.57954","4.88633","2.61186","0.81439","4.88633","83.57954"
"83.80000","83.77958","4.89459","2.61811","0.81577","4.89459","83.77958"
"84.00000","83.97957","4.93730","2.62436","0.82288","4.93730","83.97957"
"84.20000","84.17957","4.95060","2.63061","0.82510","4.95060","84.17957"
"84.40000","84.37952","4.93065","2.63686","0.82177","4.93065","84.37952"
"84.60000","84.57962","5.00435","2.64311","0.83406","5.00435","84.57962"
"84.80000","84.77958","5.01703","2.64936","0.83617","5.01703","84.77958"
"85.00000","84.97954","4.95811","2.65561","0.82635","4.95811","84.97954"
"85.20000","85.17957","5.03925","2.66186","0.83988","5.03925","85.17957"
"85.40000","85.37951","5.03976","2.66811","0.83996","5.03976","85.37951"
"85.60000","85.57961","5.12534","2.67436","0.85422","5.12534","85.57961"
"85.80000","85.77953","5.04770","2.68061","0.84128","5.04770","85.77953"
"86.00000","85.97948","5.12468","2.68686","0.85411","5.12468","85.97948"
"86.20000","86.17957","5.14672","2.69311","0.85779","5.14672","86.17957"
"86.40000","86.37955","5.07391","2.69936","0.84565","5.07391","86.37955"
"86.60000","86.57958","5.14705","2.70561","0.85784","5.14705","86.57958"
"86.80000","86.77951","5.14151","2.71186","0.85692","5.14151","86.77951"
"87.00000","86.97956","5.12868","2.71811","0.85478","5.12868","86.97956"
"87.20000","87.17953","5.19960","2.72436","0.86660","5.19960","87.17953"
"87.40000","87.37955","5.24044","2.73061","0.87341","5.24044","87.37955"
"87.60000","87.57956","5.18170","2.73686","0.86362","5.18170","87.57956"
"87.80000","87.77952","5.31582","2.74311","0.88597","5.31582","87.77952"
"88.00000","87.97957","5.26253","2.74936","0.87709","5.26253","87.97957"
"88.20000","88.17955","5.22617","2.75561","0.87103","5.22617","88.17955"
"88.40000","88.37946","5.29233","2.76186","0.88206","5.29233","88.37946"
"88.60000","88.57960","5.31578","2.76811","0.88596","5.31578","88.57960"
"88.80000","88.77952","5.29130","2.77436","0.88188","5.29130","88.77952"
"89.00000","88.97952","5.33964","2.78061","0.88994","5.33964","88.97952"
"89.20000","89.17944","5.38591","2.78686","0.89765","5.38591","89.17944"
"89.40000","89.37956","5.39555","2.79311","0.89926","5.39555","89.37956"
"89.60000","89.57954","5.48736","2.79936","0.91456","5.48736","89.57954"
"89.80000","89.77950","5.40065","2.80561","0.90011","5.40065","89.77950"
"90.00000","89.97952","5.42499","2.81186","0.90416","5.42499","89.97952"
"90.20000","90.17954","5.40999","2.81811","0.90166","5.40999","90.17954"
"90.40000","90.37949","5.44304","2.82436","0.90717","5.44304","90.37949"
"90.60000","90.57956","5.39798","2.83061","0.89966","5.39798","90.57956"
"90.80000","90.77943","5.50143","2.83686","0.91691","5.50143","90.77943"
"91.00000","90.97957","5.47904","2.84311","0.91317","5.47904","90.97957"
"91.20000","91.17946","5.52147","2.84936","0.92024","5.52147","91.17946"
"91.40000","91.37950","5.51944","2.85561","0.91991","5.51944","91.37950"
"91.60000","91.57944","5.60939","2.86186","0.93490","5.60939","91.57944"
"91.80000","91.77954","5.50260","2.86811","0.91710","5.50260","91.77954"
"92.00000","91.97946","5.61339","2.87436","0.93556","5.61339","91.97946"
"92.20000","92.17949","5.59416","2.88061","0.93236","5.59416","92.17949"
"92.40000","92.37945","5.60796","2.88686","0.93466","5.60796","92.37945"
"92.60000","92.57951","5.65230","2.89311","0.94205","5.65230","92.57951"
"92.80000","92.77942","5.68572","2.89936","0.94762","5.68572","92.77942"
"93.00000","92.97958","5.59376","2.90561","0.93229","5.59376","92.97958"
"93.20000","93.17938","5.58834","2.91186","0.93139","5.58834","93.17938"
"93.40000","93.37952","5.68165","2.91811","0.94694","5.68165","93.37952"
"93.60000","93.57938","5.67975","2.92436","0.94662","5.67975","93.57938"
"93.80000","93.77949","5.66382","2.93061","0.94397","5.66382","93.77949"
"94.00000","93.97942","5.72993","2.93686","0.95499","5.72993","93.97942"
"94.20000","94.17948","5.68516","2.94311","0.94753","5.68516","94.17948"
"94.40000","94.37943","5.74849","2.94936","0.95808","5.74849","94.37943"
"94.60000","94.57951","5.74314","2.95561","0.95719","5.74314","94.57951"
"94.80000","94.77940","5.75683","2.96186","0.95947","5.75683","94.77940"
"95.00000","94.97948","5.81556","2.96811","0.96926","5.81556","94.97948"
"95.20000","95.17937","5.87659","2.97436","0.97943","5.87659","95.17937"
"95.40000","95.37950","5.80605","2.98061","0.96767","5.80605","95.37950"
"95.60000","95.57935","5.82871","2.98685","0.97145","5.82871","95.57935"
"95.80000","95.77953","5.93037","2.99311","0.98839","5.93037","95.77953"
"96.00000","95.97937","5.88857","2.99936","0.98143","5.88857","95.97937"
"96.20000","96.17947","5.93767","3.00561","0.98961","5.93767","96.17947"
"96.40000","96.37942","5.89318","3.01186","0.98220","5.89318","96.37942"
"96.60000","96.57952","5.93838","3.01811","0.98973","5.93838","96.57952"
"96.80000","96.77940","5.92266","3.02436","0.98711","5.92266","96.77940"
"97.00000","96.97955","5.97325","3.03061","0.99554","5.97325","96.97955"
"97.20000","97.17933","6.00546","3.03685","1.00091","6.00546","97.17933"
"97.40000","97.37952","5.98231","3.04311","0.99705","5.98231","97.37952"
"97.60000","97.57935","6.00123","3.04935","1.00020","6.00123","97.57935"
"97.80000","97.77953","6.04798","3.05561","1.00800","6.04798","97.77953"
"98.00000","97.97938","6.02155","3.06186","1.00359","6.02155","97.97938"
"98.20000","98.17950","6.04705","3.06811","1.00784","6.04705","98.17950"
"98.40000","98.37937","6.09858","3.07436","1.01643","6.09858","98.37937"
"98.60000","98.57952","6.10111","3.08061","1.01685","6.10111","98.57952"
"98.80000","98.77943","6.13225","3.08686","1.02204","6.13225","98.77943"
"99.00000","98.97952","6.10878","3.09311","1.01813","6.10878","98.97952"
"99.20000","99.17943","6.13508","3.09936","1.02251","6.13508","99.17943"
"99.40000","99.37959","6.22333","3.10561","1.03722","6.22333","99.37959"
"99.60000","99.57938","6.14724","3.11186","1.02454","6.14724","99.57938"
"99.80000","99.77956","6.18235","3.11811","1.03039","6.18235","99.77956"
"100.00000","99.97935","6.26691","3.12435","1.04449","6.26691","99.97935"
"100.20000","100.17955","6.22183","3.13061","1.03697","6.22183","100.17955"
"100.40000","100.37939","6.20331","3.13686","1.03389","6.20331","100.37939"
"100.60000","100.57955","6.32030","3.14311","1.05338","6.32030","100.57955"
"100.80000","100.77943","6.21857","3.14936","1.03643","6.21857","100.77943"
"101.00000","100.97955","6.31227","3.15561","1.05204","6.31227","100.97955"
"101.20000","101.17947","6.31604","3.16186","1.05267","6.31604","101.17947"
"101.40000","101.37955","6.36154","3.16811","1.06026","6.36154","101.37955"
"101.60000","101.57948","6.32474","3.17436","1.05412","6.32474","101.57948"
"101.80000","101.77961","6.41853","3.18061","1.06976","6.41853","101.77961"
"102.00000","101.97942","6.35564","3.18686","1.05927","6.35564","101.97942"
"102.20000","102.17962","6.34814","3.19311","1.05802","6.34814","102.17962"
"102.40000","102.37940","6.42068","3.19936","1.07011","6.42068","102.37940"
"102.60000","102.57960","6.42041","3.20561","1.07007","6.42041","102.57960"
"102.80000","102.77949","6.41399","3.21186","1.06900","6.41399","102.77949"
"103.00000","102.97963","6.48651","3.21811","1.08109","6.48651","102.97963"
"103.20000","103.17943","6.46273","3.22436","1.07712","6.46273","103.17943"
"103.40000","103.37956","6.47538","3.23061","1.07923","6.47538","103.37956"
"103.60000","103.57947","6.51693","3.23686","1.08616","6.51693","103.57947"
"103.80000","103.77961","6.56023","3.24311","1.09337","6.56023","103.77961"
"104.00000","103.97947","6.50204","3.24936","1.08367","6.50204","103.97947"
"104.20000","104.17963","6.59467","3.25561","1.09911","6.59467","104.17963"
"104.40000","104.37946","6.57626","3.26186","1.09604","6.57626","104.37946"
"104.60000","104.57967","6.62100","3.26811","1.10350","6.62100","104.57967"
"104.80000","104.77943","6.56592","3.27436","1.09432","6.56592","104.77943"
"105.00000","104.97964","6.56191","3.28061","1.09365","6.56191","104.97964"
"105.20000","105.17952","6.61674","3.28686","1.10279","6.61674","105.17952"
"105.40000","105.37964","6.65904","3.29311","1.10984","6.65904","105.37964"
"105.60000","105.57950","6.71398","3.29936","1.11900","6.71398","105.57950"
"105.80000","105.77962","6.62941","3.30561","1.10490","6.62941","105.77962"
"106.00000","105.97948","6.71083","3.31186","1.11847","6.71083","105.97948"
"106.20000","106.17966","6.71483","3.31811","1.11914","6.71483","106.17966"
"106.40000","106.37952","6.71913","3.32436","1.11985","6.71913","106.37952"
"106.60000","106.57969","6.73032","3.33062","1.12172","6.73032","106.57969"
"106.80000","106.77935","6.68474","3.33685","1.11412","6.68474","106.77935"
"107.00000","106.97969","6.63278","3.34312","1.10546","6.63278","106.97969"
"107.20000","107.17948","6.69540","3.34936","1.11590","6.69540","107.17948"
"107.40000","107.37961","6.70411","3.35561","1.11735","6.70411","107.37961"
"107.60000","107.57951","0.24528","3.36186","0.04088","0.24528","107.57951"
"107.80000","107.77964","0.21908","3.36811","0.03651","0.21908","107.77964"
"108.00000","107.97951","0.23819","3.37436","0.03970","0.23819","107.97951"
"108.20000","108.17961","0.19505","3.38061","0.03251","0.19505","108.17961"
"108.40000","108.37950","0.15058","3.38686","0.02510","0.15058","108.37950"
"108.60000","108.57964","0.27323","3.39311","0.04554","0.27323","108.57964"
"108.80000","108.77950","0.26129","3.39936","0.04355","0.26129","108.77950"
"108.97000","108.94954","0.25506","3.40467","0.04251","0.25506","108.94954"